[32mINFO    [0m pytest_operator.plugin:plugin.py:734 Connecting to existing model microk8s-localhost:test on unspecified cloud
[32mINFO    [0m juju.model:model.py:2098 Deploying local:jammy/postgresql-k8s-0
[32mINFO    [0m juju.model:model.py:2098 Deploying ch:amd64/jammy/postgresql-test-app-244
[32mINFO    [0m juju.model:model.py:2972 Waiting for model:
  postgresql-k8s/0 [allocating] waiting: installing agent
  postgresql-k8s/1 [allocating] waiting: installing agent
  postgresql-k8s/2 [allocating] waiting: installing agent
  postgresql-test-app/0 [allocating] waiting: installing agent
[32mINFO    [0m juju.model:model.py:2972 Waiting for model:
  postgresql-k8s/0 [executing] maintenance: installing charm software
  postgresql-k8s/1 [executing] maintenance: installing charm software
  postgresql-k8s/2 [executing] maintenance: installing charm software
  postgresql-test-app/0 [idle] active: 
[32mINFO    [0m juju.model:model.py:2972 Waiting for model:
  postgresql-k8s/0 [executing] waiting: awaiting for cluster to start
  postgresql-k8s/1 [executing] unknown: 
  postgresql-k8s/2 [executing] unknown: 
[32mINFO    [0m juju.model:model.py:2972 Waiting for model:
  postgresql-k8s/0 [executing] waiting: awaiting for cluster to start
  postgresql-k8s/1 [executing] unknown: 
  postgresql-k8s/2 [executing] unknown: 
[32mINFO    [0m juju.model:model.py:2972 Waiting for model:
  postgresql-k8s/0 [executing] waiting: awaiting for cluster to start
  postgresql-k8s/1 [idle] unknown: 
  postgresql-k8s/2 [idle] unknown: 
[32mINFO    [0m juju.model:model.py:2972 Waiting for model:
  postgresql-k8s/0 [executing] waiting: awaiting for cluster to start
  postgresql-k8s/1 [idle] unknown: 
  postgresql-k8s/2 [idle] unknown: 
[32mINFO    [0m juju.model:model.py:2972 Waiting for model:
  postgresql-k8s/0 [executing] waiting: awaiting for cluster to start
  postgresql-k8s/1 [idle] unknown: 
  postgresql-k8s/2 [idle] unknown: 
[32mINFO    [0m juju.model:model.py:2972 Waiting for model:
  postgresql-k8s/0 [executing] waiting: awaiting for cluster to start
  postgresql-k8s/1 [idle] unknown: 
  postgresql-k8s/2 [idle] unknown: 
[32mINFO    [0m juju.model:model.py:2972 Waiting for model:
  postgresql-k8s/0 [executing] waiting: awaiting for primary endpoint to be ready
  postgresql-k8s/1 [idle] unknown: 
  postgresql-k8s/2 [idle] unknown: 
[32mINFO    [0m juju.model:model.py:2972 Waiting for model:
  postgresql-k8s/0 [executing] waiting: awaiting for primary endpoint to be ready
  postgresql-k8s/1 [idle] unknown: 
  postgresql-k8s/2 [idle] unknown: 
[32mINFO    [0m juju.model:model.py:2972 Waiting for model:
  postgresql-k8s/0 [executing] waiting: awaiting for primary endpoint to be ready
  postgresql-k8s/1 [idle] unknown: 
  postgresql-k8s/2 [idle] unknown: 
[32mINFO    [0m juju.model:model.py:2972 Waiting for model:
  postgresql-k8s/0 [executing] waiting: awaiting for primary endpoint to be ready
  postgresql-k8s/1 [idle] unknown: 
  postgresql-k8s/2 [idle] unknown: 
[32mINFO    [0m juju.model:model.py:2972 Waiting for model:
  postgresql-k8s/0 [executing] waiting: awaiting for primary endpoint to be ready
  postgresql-k8s/1 [idle] unknown: 
  postgresql-k8s/2 [idle] unknown: 
[32mINFO    [0m juju.model:model.py:2972 Waiting for model:
  postgresql-k8s/0 [executing] waiting: awaiting for primary endpoint to be ready
  postgresql-k8s/1 [idle] unknown: 
  postgresql-k8s/2 [idle] unknown: 
[32mINFO    [0m juju.model:model.py:2972 Waiting for model:
  postgresql-k8s/0 [executing] waiting: awaiting for primary endpoint to be ready
  postgresql-k8s/1 [idle] unknown: 
  postgresql-k8s/2 [idle] unknown: 
[32mINFO    [0m juju.model:model.py:2972 Waiting for model:
  postgresql-k8s/0 [idle] waiting: awaiting for primary endpoint to be ready
  postgresql-k8s/1 [idle] unknown: 
  postgresql-k8s/2 [idle] unknown: 
[32mINFO    [0m juju.model:model.py:2972 Waiting for model:
  postgresql-k8s/0 [executing] active: Primary
  postgresql-k8s/1 [executing] unknown: 
  postgresql-k8s/2 [executing] unknown: 
[32mINFO    [0m juju.model:model.py:2972 Waiting for model:
  postgresql-k8s/0 [executing] active: Primary
  postgresql-k8s/1 [idle] waiting: awaiting for cluster to start
  postgresql-k8s/2 [idle] waiting: awaiting for cluster to start
[32mINFO    [0m juju.model:model.py:2972 Waiting for model:
  postgresql-k8s/0 [idle] active: Primary
  postgresql-k8s/1 [idle] waiting: awaiting for cluster to start
  postgresql-k8s/2 [idle] waiting: awaiting for cluster to start
[32mINFO    [0m juju.model:model.py:2972 Waiting for model:
  postgresql-k8s/0 [executing] active: Primary
  postgresql-k8s/1 [idle] active: 
  postgresql-k8s/2 [idle] waiting: awaiting for cluster to start
[33mWARNING [0m juju.model:model.py:1564 relate is deprecated and will be removed. Use integrate instead.
[32mINFO    [0m pytest_operator.plugin:plugin.py:862 Model status:

Model  Controller          Cloud/Region        Version  SLA          Timestamp
test   microk8s-localhost  microk8s/localhost  3.4.4    unsupported  01:48:32Z

App                  Version  Status  Scale  Charm                Channel      Rev  Address         Exposed  Message
postgresql-k8s       14.12    active      3  postgresql-k8s                      0  10.152.183.106  no       
postgresql-test-app           active      1  postgresql-test-app  latest/edge  244  10.152.183.243  no       

Unit                    Workload  Agent  Address      Ports  Message
postgresql-k8s/0*       active    idle   10.1.144.11         Primary
postgresql-k8s/1        active    idle   10.1.144.12         
postgresql-k8s/2        active    idle   10.1.144.13         
postgresql-test-app/0*  active    idle   10.1.144.14         

[32mINFO    [0m pytest_operator.plugin:plugin.py:868 Juju error logs:

unit-postgresql-test-app-0: 01:43:29 ERROR unit.postgresql-test-app/0.juju-log Uncaught exception while in charm code:
Traceback (most recent call last):
  File "/var/lib/juju/agents/unit-postgresql-test-app-0/charm/./src/charm.py", line 538, in <module>
    main(ApplicationCharm)
  File "/var/lib/juju/agents/unit-postgresql-test-app-0/charm/venv/ops/main.py", line 553, in main
    manager.run()
  File "/var/lib/juju/agents/unit-postgresql-test-app-0/charm/venv/ops/main.py", line 529, in run
    self._emit()
  File "/var/lib/juju/agents/unit-postgresql-test-app-0/charm/venv/ops/main.py", line 518, in _emit
    _emit_charm_event(self.charm, self.dispatcher.event_name, self._juju_context)
  File "/var/lib/juju/agents/unit-postgresql-test-app-0/charm/venv/ops/main.py", line 139, in _emit_charm_event
    event_to_emit.emit(*args, **kwargs)
  File "/var/lib/juju/agents/unit-postgresql-test-app-0/charm/venv/ops/framework.py", line 347, in emit
    framework._emit(event)
  File "/var/lib/juju/agents/unit-postgresql-test-app-0/charm/venv/ops/framework.py", line 853, in _emit
    self._reemit(event_path)
  File "/var/lib/juju/agents/unit-postgresql-test-app-0/charm/venv/ops/framework.py", line 943, in _reemit
    custom_handler(event)
  File "/var/lib/juju/agents/unit-postgresql-test-app-0/charm/./src/charm.py", line 289, in _on_clear_continuous_writes_action
    if self._connection_string is None:
  File "/var/lib/juju/agents/unit-postgresql-test-app-0/charm/./src/charm.py", line 259, in _connection_string
    data = list(self.first_database.fetch_relation_data().values())[0]
AttributeError: 'ApplicationCharm' object has no attribute 'first_database'
unit-postgresql-test-app-0: 01:43:33 ERROR unit.postgresql-test-app/0.juju-log Uncaught exception while in charm code:
Traceback (most recent call last):
  File "/var/lib/juju/agents/unit-postgresql-test-app-0/charm/./src/charm.py", line 538, in <module>
    main(ApplicationCharm)
  File "/var/lib/juju/agents/unit-postgresql-test-app-0/charm/venv/ops/main.py", line 553, in main
    manager.run()
  File "/var/lib/juju/agents/unit-postgresql-test-app-0/charm/venv/ops/main.py", line 529, in run
    self._emit()
  File "/var/lib/juju/agents/unit-postgresql-test-app-0/charm/venv/ops/main.py", line 518, in _emit
    _emit_charm_event(self.charm, self.dispatcher.event_name, self._juju_context)
  File "/var/lib/juju/agents/unit-postgresql-test-app-0/charm/venv/ops/main.py", line 139, in _emit_charm_event
    event_to_emit.emit(*args, **kwargs)
  File "/var/lib/juju/agents/unit-postgresql-test-app-0/charm/venv/ops/framework.py", line 347, in emit
    framework._emit(event)
  File "/var/lib/juju/agents/unit-postgresql-test-app-0/charm/venv/ops/framework.py", line 853, in _emit
    self._reemit(event_path)
  File "/var/lib/juju/agents/unit-postgresql-test-app-0/charm/venv/ops/framework.py", line 943, in _reemit
    custom_handler(event)
  File "/var/lib/juju/agents/unit-postgresql-test-app-0/charm/./src/charm.py", line 289, in _on_clear_continuous_writes_action
    if self._connection_string is None:
  File "/var/lib/juju/agents/unit-postgresql-test-app-0/charm/./src/charm.py", line 259, in _connection_string
    data = list(self.first_database.fetch_relation_data().values())[0]
AttributeError: 'ApplicationCharm' object has no attribute 'first_database'
unit-postgresql-test-app-0: 01:43:37 ERROR unit.postgresql-test-app/0.juju-log Uncaught exception while in charm code:
Traceback (most recent call last):
  File "/var/lib/juju/agents/unit-postgresql-test-app-0/charm/./src/charm.py", line 538, in <module>
    main(ApplicationCharm)
  File "/var/lib/juju/agents/unit-postgresql-test-app-0/charm/venv/ops/main.py", line 553, in main
    manager.run()
  File "/var/lib/juju/agents/unit-postgresql-test-app-0/charm/venv/ops/main.py", line 529, in run
    self._emit()
  File "/var/lib/juju/agents/unit-postgresql-test-app-0/charm/venv/ops/main.py", line 518, in _emit
    _emit_charm_event(self.charm, self.dispatcher.event_name, self._juju_context)
  File "/var/lib/juju/agents/unit-postgresql-test-app-0/charm/venv/ops/main.py", line 139, in _emit_charm_event
    event_to_emit.emit(*args, **kwargs)
  File "/var/lib/juju/agents/unit-postgresql-test-app-0/charm/venv/ops/framework.py", line 347, in emit
    framework._emit(event)
  File "/var/lib/juju/agents/unit-postgresql-test-app-0/charm/venv/ops/framework.py", line 853, in _emit
    self._reemit(event_path)
  File "/var/lib/juju/agents/unit-postgresql-test-app-0/charm/venv/ops/framework.py", line 943, in _reemit
    custom_handler(event)
  File "/var/lib/juju/agents/unit-postgresql-test-app-0/charm/./src/charm.py", line 289, in _on_clear_continuous_writes_action
    if self._connection_string is None:
  File "/var/lib/juju/agents/unit-postgresql-test-app-0/charm/./src/charm.py", line 259, in _connection_string
    data = list(self.first_database.fetch_relation_data().values())[0]
AttributeError: 'ApplicationCharm' object has no attribute 'first_database'
unit-postgresql-test-app-0: 01:43:41 ERROR unit.postgresql-test-app/0.juju-log Uncaught exception while in charm code:
Traceback (most recent call last):
  File "/var/lib/juju/agents/unit-postgresql-test-app-0/charm/./src/charm.py", line 538, in <module>
    main(ApplicationCharm)
  File "/var/lib/juju/agents/unit-postgresql-test-app-0/charm/venv/ops/main.py", line 553, in main
    manager.run()
  File "/var/lib/juju/agents/unit-postgresql-test-app-0/charm/venv/ops/main.py", line 529, in run
    self._emit()
  File "/var/lib/juju/agents/unit-postgresql-test-app-0/charm/venv/ops/main.py", line 518, in _emit
    _emit_charm_event(self.charm, self.dispatcher.event_name, self._juju_context)
  File "/var/lib/juju/agents/unit-postgresql-test-app-0/charm/venv/ops/main.py", line 139, in _emit_charm_event
    event_to_emit.emit(*args, **kwargs)
  File "/var/lib/juju/agents/unit-postgresql-test-app-0/charm/venv/ops/framework.py", line 347, in emit
    framework._emit(event)
  File "/var/lib/juju/agents/unit-postgresql-test-app-0/charm/venv/ops/framework.py", line 853, in _emit
    self._reemit(event_path)
  File "/var/lib/juju/agents/unit-postgresql-test-app-0/charm/venv/ops/framework.py", line 943, in _reemit
    custom_handler(event)
  File "/var/lib/juju/agents/unit-postgresql-test-app-0/charm/./src/charm.py", line 289, in _on_clear_continuous_writes_action
    if self._connection_string is None:
  File "/var/lib/juju/agents/unit-postgresql-test-app-0/charm/./src/charm.py", line 259, in _connection_string
    data = list(self.first_database.fetch_relation_data().values())[0]
AttributeError: 'ApplicationCharm' object has no attribute 'first_database'
unit-postgresql-test-app-0: 01:43:45 ERROR unit.postgresql-test-app/0.juju-log Uncaught exception while in charm code:
Traceback (most recent call last):
  File "/var/lib/juju/agents/unit-postgresql-test-app-0/charm/./src/charm.py", line 538, in <module>
    main(ApplicationCharm)
  File "/var/lib/juju/agents/unit-postgresql-test-app-0/charm/venv/ops/main.py", line 553, in main
    manager.run()
  File "/var/lib/juju/agents/unit-postgresql-test-app-0/charm/venv/ops/main.py", line 529, in run
    self._emit()
  File "/var/lib/juju/agents/unit-postgresql-test-app-0/charm/venv/ops/main.py", line 518, in _emit
    _emit_charm_event(self.charm, self.dispatcher.event_name, self._juju_context)
  File "/var/lib/juju/agents/unit-postgresql-test-app-0/charm/venv/ops/main.py", line 139, in _emit_charm_event
    event_to_emit.emit(*args, **kwargs)
  File "/var/lib/juju/agents/unit-postgresql-test-app-0/charm/venv/ops/framework.py", line 347, in emit
    framework._emit(event)
  File "/var/lib/juju/agents/unit-postgresql-test-app-0/charm/venv/ops/framework.py", line 853, in _emit
    self._reemit(event_path)
  File "/var/lib/juju/agents/unit-postgresql-test-app-0/charm/venv/ops/framework.py", line 943, in _reemit
    custom_handler(event)
  File "/var/lib/juju/agents/unit-postgresql-test-app-0/charm/./src/charm.py", line 289, in _on_clear_continuous_writes_action
    if self._connection_string is None:
  File "/var/lib/juju/agents/unit-postgresql-test-app-0/charm/./src/charm.py", line 259, in _connection_string
    data = list(self.first_database.fetch_relation_data().values())[0]
AttributeError: 'ApplicationCharm' object has no attribute 'first_database'
unit-postgresql-test-app-0: 01:43:49 ERROR unit.postgresql-test-app/0.juju-log Uncaught exception while in charm code:
Traceback (most recent call last):
  File "/var/lib/juju/agents/unit-postgresql-test-app-0/charm/./src/charm.py", line 538, in <module>
    main(ApplicationCharm)
  File "/var/lib/juju/agents/unit-postgresql-test-app-0/charm/venv/ops/main.py", line 553, in main
    manager.run()
  File "/var/lib/juju/agents/unit-postgresql-test-app-0/charm/venv/ops/main.py", line 529, in run
    self._emit()
  File "/var/lib/juju/agents/unit-postgresql-test-app-0/charm/venv/ops/main.py", line 518, in _emit
    _emit_charm_event(self.charm, self.dispatcher.event_name, self._juju_context)
  File "/var/lib/juju/agents/unit-postgresql-test-app-0/charm/venv/ops/main.py", line 139, in _emit_charm_event
    event_to_emit.emit(*args, **kwargs)
  File "/var/lib/juju/agents/unit-postgresql-test-app-0/charm/venv/ops/framework.py", line 347, in emit
    framework._emit(event)
  File "/var/lib/juju/agents/unit-postgresql-test-app-0/charm/venv/ops/framework.py", line 853, in _emit
    self._reemit(event_path)
  File "/var/lib/juju/agents/unit-postgresql-test-app-0/charm/venv/ops/framework.py", line 943, in _reemit
    custom_handler(event)
  File "/var/lib/juju/agents/unit-postgresql-test-app-0/charm/./src/charm.py", line 289, in _on_clear_continuous_writes_action
    if self._connection_string is None:
  File "/var/lib/juju/agents/unit-postgresql-test-app-0/charm/./src/charm.py", line 259, in _connection_string
    data = list(self.first_database.fetch_relation_data().values())[0]
AttributeError: 'ApplicationCharm' object has no attribute 'first_database'
unit-postgresql-test-app-0: 01:43:53 ERROR unit.postgresql-test-app/0.juju-log Uncaught exception while in charm code:
Traceback (most recent call last):
  File "/var/lib/juju/agents/unit-postgresql-test-app-0/charm/./src/charm.py", line 538, in <module>
    main(ApplicationCharm)
  File "/var/lib/juju/agents/unit-postgresql-test-app-0/charm/venv/ops/main.py", line 553, in main
    manager.run()
  File "/var/lib/juju/agents/unit-postgresql-test-app-0/charm/venv/ops/main.py", line 529, in run
    self._emit()
  File "/var/lib/juju/agents/unit-postgresql-test-app-0/charm/venv/ops/main.py", line 518, in _emit
    _emit_charm_event(self.charm, self.dispatcher.event_name, self._juju_context)
  File "/var/lib/juju/agents/unit-postgresql-test-app-0/charm/venv/ops/main.py", line 139, in _emit_charm_event
    event_to_emit.emit(*args, **kwargs)
  File "/var/lib/juju/agents/unit-postgresql-test-app-0/charm/venv/ops/framework.py", line 347, in emit
    framework._emit(event)
  File "/var/lib/juju/agents/unit-postgresql-test-app-0/charm/venv/ops/framework.py", line 853, in _emit
    self._reemit(event_path)
  File "/var/lib/juju/agents/unit-postgresql-test-app-0/charm/venv/ops/framework.py", line 943, in _reemit
    custom_handler(event)
  File "/var/lib/juju/agents/unit-postgresql-test-app-0/charm/./src/charm.py", line 289, in _on_clear_continuous_writes_action
    if self._connection_string is None:
  File "/var/lib/juju/agents/unit-postgresql-test-app-0/charm/./src/charm.py", line 259, in _connection_string
    data = list(self.first_database.fetch_relation_data().values())[0]
AttributeError: 'ApplicationCharm' object has no attribute 'first_database'
unit-postgresql-test-app-0: 01:43:57 ERROR unit.postgresql-test-app/0.juju-log Uncaught exception while in charm code:
Traceback (most recent call last):
  File "/var/lib/juju/agents/unit-postgresql-test-app-0/charm/./src/charm.py", line 538, in <module>
    main(ApplicationCharm)
  File "/var/lib/juju/agents/unit-postgresql-test-app-0/charm/venv/ops/main.py", line 553, in main
    manager.run()
  File "/var/lib/juju/agents/unit-postgresql-test-app-0/charm/venv/ops/main.py", line 529, in run
    self._emit()
  File "/var/lib/juju/agents/unit-postgresql-test-app-0/charm/venv/ops/main.py", line 518, in _emit
    _emit_charm_event(self.charm, self.dispatcher.event_name, self._juju_context)
  File "/var/lib/juju/agents/unit-postgresql-test-app-0/charm/venv/ops/main.py", line 139, in _emit_charm_event
    event_to_emit.emit(*args, **kwargs)
  File "/var/lib/juju/agents/unit-postgresql-test-app-0/charm/venv/ops/framework.py", line 347, in emit
    framework._emit(event)
  File "/var/lib/juju/agents/unit-postgresql-test-app-0/charm/venv/ops/framework.py", line 853, in _emit
    self._reemit(event_path)
  File "/var/lib/juju/agents/unit-postgresql-test-app-0/charm/venv/ops/framework.py", line 943, in _reemit
    custom_handler(event)
  File "/var/lib/juju/agents/unit-postgresql-test-app-0/charm/./src/charm.py", line 289, in _on_clear_continuous_writes_action
    if self._connection_string is None:
  File "/var/lib/juju/agents/unit-postgresql-test-app-0/charm/./src/charm.py", line 259, in _connection_string
    data = list(self.first_database.fetch_relation_data().values())[0]
AttributeError: 'ApplicationCharm' object has no attribute 'first_database'
unit-postgresql-test-app-0: 01:44:01 ERROR unit.postgresql-test-app/0.juju-log Uncaught exception while in charm code:
Traceback (most recent call last):
  File "/var/lib/juju/agents/unit-postgresql-test-app-0/charm/./src/charm.py", line 538, in <module>
    main(ApplicationCharm)
  File "/var/lib/juju/agents/unit-postgresql-test-app-0/charm/venv/ops/main.py", line 553, in main
    manager.run()
  File "/var/lib/juju/agents/unit-postgresql-test-app-0/charm/venv/ops/main.py", line 529, in run
    self._emit()
  File "/var/lib/juju/agents/unit-postgresql-test-app-0/charm/venv/ops/main.py", line 518, in _emit
    _emit_charm_event(self.charm, self.dispatcher.event_name, self._juju_context)
  File "/var/lib/juju/agents/unit-postgresql-test-app-0/charm/venv/ops/main.py", line 139, in _emit_charm_event
    event_to_emit.emit(*args, **kwargs)
  File "/var/lib/juju/agents/unit-postgresql-test-app-0/charm/venv/ops/framework.py", line 347, in emit
    framework._emit(event)
  File "/var/lib/juju/agents/unit-postgresql-test-app-0/charm/venv/ops/framework.py", line 853, in _emit
    self._reemit(event_path)
  File "/var/lib/juju/agents/unit-postgresql-test-app-0/charm/venv/ops/framework.py", line 943, in _reemit
    custom_handler(event)
  File "/var/lib/juju/agents/unit-postgresql-test-app-0/charm/./src/charm.py", line 289, in _on_clear_continuous_writes_action
    if self._connection_string is None:
  File "/var/lib/juju/agents/unit-postgresql-test-app-0/charm/./src/charm.py", line 259, in _connection_string
    data = list(self.first_database.fetch_relation_data().values())[0]
AttributeError: 'ApplicationCharm' object has no attribute 'first_database'
unit-postgresql-test-app-0: 01:44:05 ERROR unit.postgresql-test-app/0.juju-log Uncaught exception while in charm code:
Traceback (most recent call last):
  File "/var/lib/juju/agents/unit-postgresql-test-app-0/charm/./src/charm.py", line 538, in <module>
    main(ApplicationCharm)
  File "/var/lib/juju/agents/unit-postgresql-test-app-0/charm/venv/ops/main.py", line 553, in main
    manager.run()
  File "/var/lib/juju/agents/unit-postgresql-test-app-0/charm/venv/ops/main.py", line 529, in run
    self._emit()
  File "/var/lib/juju/agents/unit-postgresql-test-app-0/charm/venv/ops/main.py", line 518, in _emit
    _emit_charm_event(self.charm, self.dispatcher.event_name, self._juju_context)
  File "/var/lib/juju/agents/unit-postgresql-test-app-0/charm/venv/ops/main.py", line 139, in _emit_charm_event
    event_to_emit.emit(*args, **kwargs)
  File "/var/lib/juju/agents/unit-postgresql-test-app-0/charm/venv/ops/framework.py", line 347, in emit
    framework._emit(event)
  File "/var/lib/juju/agents/unit-postgresql-test-app-0/charm/venv/ops/framework.py", line 853, in _emit
    self._reemit(event_path)
  File "/var/lib/juju/agents/unit-postgresql-test-app-0/charm/venv/ops/framework.py", line 943, in _reemit
    custom_handler(event)
  File "/var/lib/juju/agents/unit-postgresql-test-app-0/charm/./src/charm.py", line 289, in _on_clear_continuous_writes_action
    if self._connection_string is None:
  File "/var/lib/juju/agents/unit-postgresql-test-app-0/charm/./src/charm.py", line 259, in _connection_string
    data = list(self.first_database.fetch_relation_data().values())[0]
AttributeError: 'ApplicationCharm' object has no attribute 'first_database'
unit-postgresql-test-app-0: 01:44:09 ERROR unit.postgresql-test-app/0.juju-log Uncaught exception while in charm code:
Traceback (most recent call last):
  File "/var/lib/juju/agents/unit-postgresql-test-app-0/charm/./src/charm.py", line 538, in <module>
    main(ApplicationCharm)
  File "/var/lib/juju/agents/unit-postgresql-test-app-0/charm/venv/ops/main.py", line 553, in main
    manager.run()
  File "/var/lib/juju/agents/unit-postgresql-test-app-0/charm/venv/ops/main.py", line 529, in run
    self._emit()
  File "/var/lib/juju/agents/unit-postgresql-test-app-0/charm/venv/ops/main.py", line 518, in _emit
    _emit_charm_event(self.charm, self.dispatcher.event_name, self._juju_context)
  File "/var/lib/juju/agents/unit-postgresql-test-app-0/charm/venv/ops/main.py", line 139, in _emit_charm_event
    event_to_emit.emit(*args, **kwargs)
  File "/var/lib/juju/agents/unit-postgresql-test-app-0/charm/venv/ops/framework.py", line 347, in emit
    framework._emit(event)
  File "/var/lib/juju/agents/unit-postgresql-test-app-0/charm/venv/ops/framework.py", line 853, in _emit
    self._reemit(event_path)
  File "/var/lib/juju/agents/unit-postgresql-test-app-0/charm/venv/ops/framework.py", line 943, in _reemit
    custom_handler(event)
  File "/var/lib/juju/agents/unit-postgresql-test-app-0/charm/./src/charm.py", line 289, in _on_clear_continuous_writes_action
    if self._connection_string is None:
  File "/var/lib/juju/agents/unit-postgresql-test-app-0/charm/./src/charm.py", line 259, in _connection_string
    data = list(self.first_database.fetch_relation_data().values())[0]
AttributeError: 'ApplicationCharm' object has no attribute 'first_database'
unit-postgresql-test-app-0: 01:44:13 ERROR unit.postgresql-test-app/0.juju-log Uncaught exception while in charm code:
Traceback (most recent call last):
  File "/var/lib/juju/agents/unit-postgresql-test-app-0/charm/./src/charm.py", line 538, in <module>
    main(ApplicationCharm)
  File "/var/lib/juju/agents/unit-postgresql-test-app-0/charm/venv/ops/main.py", line 553, in main
    manager.run()
  File "/var/lib/juju/agents/unit-postgresql-test-app-0/charm/venv/ops/main.py", line 529, in run
    self._emit()
  File "/var/lib/juju/agents/unit-postgresql-test-app-0/charm/venv/ops/main.py", line 518, in _emit
    _emit_charm_event(self.charm, self.dispatcher.event_name, self._juju_context)
  File "/var/lib/juju/agents/unit-postgresql-test-app-0/charm/venv/ops/main.py", line 139, in _emit_charm_event
    event_to_emit.emit(*args, **kwargs)
  File "/var/lib/juju/agents/unit-postgresql-test-app-0/charm/venv/ops/framework.py", line 347, in emit
    framework._emit(event)
  File "/var/lib/juju/agents/unit-postgresql-test-app-0/charm/venv/ops/framework.py", line 853, in _emit
    self._reemit(event_path)
  File "/var/lib/juju/agents/unit-postgresql-test-app-0/charm/venv/ops/framework.py", line 943, in _reemit
    custom_handler(event)
  File "/var/lib/juju/agents/unit-postgresql-test-app-0/charm/./src/charm.py", line 289, in _on_clear_continuous_writes_action
    if self._connection_string is None:
  File "/var/lib/juju/agents/unit-postgresql-test-app-0/charm/./src/charm.py", line 259, in _connection_string
    data = list(self.first_database.fetch_relation_data().values())[0]
AttributeError: 'ApplicationCharm' object has no attribute 'first_database'
unit-postgresql-test-app-0: 01:44:17 ERROR unit.postgresql-test-app/0.juju-log Uncaught exception while in charm code:
Traceback (most recent call last):
  File "/var/lib/juju/agents/unit-postgresql-test-app-0/charm/./src/charm.py", line 538, in <module>
    main(ApplicationCharm)
  File "/var/lib/juju/agents/unit-postgresql-test-app-0/charm/venv/ops/main.py", line 553, in main
    manager.run()
  File "/var/lib/juju/agents/unit-postgresql-test-app-0/charm/venv/ops/main.py", line 529, in run
    self._emit()
  File "/var/lib/juju/agents/unit-postgresql-test-app-0/charm/venv/ops/main.py", line 518, in _emit
    _emit_charm_event(self.charm, self.dispatcher.event_name, self._juju_context)
  File "/var/lib/juju/agents/unit-postgresql-test-app-0/charm/venv/ops/main.py", line 139, in _emit_charm_event
    event_to_emit.emit(*args, **kwargs)
  File "/var/lib/juju/agents/unit-postgresql-test-app-0/charm/venv/ops/framework.py", line 347, in emit
    framework._emit(event)
  File "/var/lib/juju/agents/unit-postgresql-test-app-0/charm/venv/ops/framework.py", line 853, in _emit
    self._reemit(event_path)
  File "/var/lib/juju/agents/unit-postgresql-test-app-0/charm/venv/ops/framework.py", line 943, in _reemit
    custom_handler(event)
  File "/var/lib/juju/agents/unit-postgresql-test-app-0/charm/./src/charm.py", line 289, in _on_clear_continuous_writes_action
    if self._connection_string is None:
  File "/var/lib/juju/agents/unit-postgresql-test-app-0/charm/./src/charm.py", line 259, in _connection_string
    data = list(self.first_database.fetch_relation_data().values())[0]
AttributeError: 'ApplicationCharm' object has no attribute 'first_database'
unit-postgresql-test-app-0: 01:44:21 ERROR unit.postgresql-test-app/0.juju-log Uncaught exception while in charm code:
Traceback (most recent call last):
  File "/var/lib/juju/agents/unit-postgresql-test-app-0/charm/./src/charm.py", line 538, in <module>
    main(ApplicationCharm)
  File "/var/lib/juju/agents/unit-postgresql-test-app-0/charm/venv/ops/main.py", line 553, in main
    manager.run()
  File "/var/lib/juju/agents/unit-postgresql-test-app-0/charm/venv/ops/main.py", line 529, in run
    self._emit()
  File "/var/lib/juju/agents/unit-postgresql-test-app-0/charm/venv/ops/main.py", line 518, in _emit
    _emit_charm_event(self.charm, self.dispatcher.event_name, self._juju_context)
  File "/var/lib/juju/agents/unit-postgresql-test-app-0/charm/venv/ops/main.py", line 139, in _emit_charm_event
    event_to_emit.emit(*args, **kwargs)
  File "/var/lib/juju/agents/unit-postgresql-test-app-0/charm/venv/ops/framework.py", line 347, in emit
    framework._emit(event)
  File "/var/lib/juju/agents/unit-postgresql-test-app-0/charm/venv/ops/framework.py", line 853, in _emit
    self._reemit(event_path)
  File "/var/lib/juju/agents/unit-postgresql-test-app-0/charm/venv/ops/framework.py", line 943, in _reemit
    custom_handler(event)
  File "/var/lib/juju/agents/unit-postgresql-test-app-0/charm/./src/charm.py", line 289, in _on_clear_continuous_writes_action
    if self._connection_string is None:
  File "/var/lib/juju/agents/unit-postgresql-test-app-0/charm/./src/charm.py", line 259, in _connection_string
    data = list(self.first_database.fetch_relation_data().values())[0]
AttributeError: 'ApplicationCharm' object has no attribute 'first_database'
unit-postgresql-test-app-0: 01:44:25 ERROR unit.postgresql-test-app/0.juju-log Uncaught exception while in charm code:
Traceback (most recent call last):
  File "/var/lib/juju/agents/unit-postgresql-test-app-0/charm/./src/charm.py", line 538, in <module>
    main(ApplicationCharm)
  File "/var/lib/juju/agents/unit-postgresql-test-app-0/charm/venv/ops/main.py", line 553, in main
    manager.run()
  File "/var/lib/juju/agents/unit-postgresql-test-app-0/charm/venv/ops/main.py", line 529, in run
    self._emit()
  File "/var/lib/juju/agents/unit-postgresql-test-app-0/charm/venv/ops/main.py", line 518, in _emit
    _emit_charm_event(self.charm, self.dispatcher.event_name, self._juju_context)
  File "/var/lib/juju/agents/unit-postgresql-test-app-0/charm/venv/ops/main.py", line 139, in _emit_charm_event
    event_to_emit.emit(*args, **kwargs)
  File "/var/lib/juju/agents/unit-postgresql-test-app-0/charm/venv/ops/framework.py", line 347, in emit
    framework._emit(event)
  File "/var/lib/juju/agents/unit-postgresql-test-app-0/charm/venv/ops/framework.py", line 853, in _emit
    self._reemit(event_path)
  File "/var/lib/juju/agents/unit-postgresql-test-app-0/charm/venv/ops/framework.py", line 943, in _reemit
    custom_handler(event)
  File "/var/lib/juju/agents/unit-postgresql-test-app-0/charm/./src/charm.py", line 289, in _on_clear_continuous_writes_action
    if self._connection_string is None:
  File "/var/lib/juju/agents/unit-postgresql-test-app-0/charm/./src/charm.py", line 259, in _connection_string
    data = list(self.first_database.fetch_relation_data().values())[0]
AttributeError: 'ApplicationCharm' object has no attribute 'first_database'
unit-postgresql-test-app-0: 01:44:29 ERROR unit.postgresql-test-app/0.juju-log Uncaught exception while in charm code:
Traceback (most recent call last):
  File "/var/lib/juju/agents/unit-postgresql-test-app-0/charm/./src/charm.py", line 538, in <module>
    main(ApplicationCharm)
  File "/var/lib/juju/agents/unit-postgresql-test-app-0/charm/venv/ops/main.py", line 553, in main
    manager.run()
  File "/var/lib/juju/agents/unit-postgresql-test-app-0/charm/venv/ops/main.py", line 529, in run
    self._emit()
  File "/var/lib/juju/agents/unit-postgresql-test-app-0/charm/venv/ops/main.py", line 518, in _emit
    _emit_charm_event(self.charm, self.dispatcher.event_name, self._juju_context)
  File "/var/lib/juju/agents/unit-postgresql-test-app-0/charm/venv/ops/main.py", line 139, in _emit_charm_event
    event_to_emit.emit(*args, **kwargs)
  File "/var/lib/juju/agents/unit-postgresql-test-app-0/charm/venv/ops/framework.py", line 347, in emit
    framework._emit(event)
  File "/var/lib/juju/agents/unit-postgresql-test-app-0/charm/venv/ops/framework.py", line 853, in _emit
    self._reemit(event_path)
  File "/var/lib/juju/agents/unit-postgresql-test-app-0/charm/venv/ops/framework.py", line 943, in _reemit
    custom_handler(event)
  File "/var/lib/juju/agents/unit-postgresql-test-app-0/charm/./src/charm.py", line 289, in _on_clear_continuous_writes_action
    if self._connection_string is None:
  File "/var/lib/juju/agents/unit-postgresql-test-app-0/charm/./src/charm.py", line 259, in _connection_string
    data = list(self.first_database.fetch_relation_data().values())[0]
AttributeError: 'ApplicationCharm' object has no attribute 'first_database'
unit-postgresql-test-app-0: 01:44:33 ERROR unit.postgresql-test-app/0.juju-log Uncaught exception while in charm code:
Traceback (most recent call last):
  File "/var/lib/juju/agents/unit-postgresql-test-app-0/charm/./src/charm.py", line 538, in <module>
    main(ApplicationCharm)
  File "/var/lib/juju/agents/unit-postgresql-test-app-0/charm/venv/ops/main.py", line 553, in main
    manager.run()
  File "/var/lib/juju/agents/unit-postgresql-test-app-0/charm/venv/ops/main.py", line 529, in run
    self._emit()
  File "/var/lib/juju/agents/unit-postgresql-test-app-0/charm/venv/ops/main.py", line 518, in _emit
    _emit_charm_event(self.charm, self.dispatcher.event_name, self._juju_context)
  File "/var/lib/juju/agents/unit-postgresql-test-app-0/charm/venv/ops/main.py", line 139, in _emit_charm_event
    event_to_emit.emit(*args, **kwargs)
  File "/var/lib/juju/agents/unit-postgresql-test-app-0/charm/venv/ops/framework.py", line 347, in emit
    framework._emit(event)
  File "/var/lib/juju/agents/unit-postgresql-test-app-0/charm/venv/ops/framework.py", line 853, in _emit
    self._reemit(event_path)
  File "/var/lib/juju/agents/unit-postgresql-test-app-0/charm/venv/ops/framework.py", line 943, in _reemit
    custom_handler(event)
  File "/var/lib/juju/agents/unit-postgresql-test-app-0/charm/./src/charm.py", line 289, in _on_clear_continuous_writes_action
    if self._connection_string is None:
  File "/var/lib/juju/agents/unit-postgresql-test-app-0/charm/./src/charm.py", line 259, in _connection_string
    data = list(self.first_database.fetch_relation_data().values())[0]
AttributeError: 'ApplicationCharm' object has no attribute 'first_database'
unit-postgresql-test-app-0: 01:44:37 ERROR unit.postgresql-test-app/0.juju-log Uncaught exception while in charm code:
Traceback (most recent call last):
  File "/var/lib/juju/agents/unit-postgresql-test-app-0/charm/./src/charm.py", line 538, in <module>
    main(ApplicationCharm)
  File "/var/lib/juju/agents/unit-postgresql-test-app-0/charm/venv/ops/main.py", line 553, in main
    manager.run()
  File "/var/lib/juju/agents/unit-postgresql-test-app-0/charm/venv/ops/main.py", line 529, in run
    self._emit()
  File "/var/lib/juju/agents/unit-postgresql-test-app-0/charm/venv/ops/main.py", line 518, in _emit
    _emit_charm_event(self.charm, self.dispatcher.event_name, self._juju_context)
  File "/var/lib/juju/agents/unit-postgresql-test-app-0/charm/venv/ops/main.py", line 139, in _emit_charm_event
    event_to_emit.emit(*args, **kwargs)
  File "/var/lib/juju/agents/unit-postgresql-test-app-0/charm/venv/ops/framework.py", line 347, in emit
    framework._emit(event)
  File "/var/lib/juju/agents/unit-postgresql-test-app-0/charm/venv/ops/framework.py", line 853, in _emit
    self._reemit(event_path)
  File "/var/lib/juju/agents/unit-postgresql-test-app-0/charm/venv/ops/framework.py", line 943, in _reemit
    custom_handler(event)
  File "/var/lib/juju/agents/unit-postgresql-test-app-0/charm/./src/charm.py", line 289, in _on_clear_continuous_writes_action
    if self._connection_string is None:
  File "/var/lib/juju/agents/unit-postgresql-test-app-0/charm/./src/charm.py", line 259, in _connection_string
    data = list(self.first_database.fetch_relation_data().values())[0]
AttributeError: 'ApplicationCharm' object has no attribute 'first_database'
unit-postgresql-test-app-0: 01:44:41 ERROR unit.postgresql-test-app/0.juju-log Uncaught exception while in charm code:
Traceback (most recent call last):
  File "/var/lib/juju/agents/unit-postgresql-test-app-0/charm/./src/charm.py", line 538, in <module>
    main(ApplicationCharm)
  File "/var/lib/juju/agents/unit-postgresql-test-app-0/charm/venv/ops/main.py", line 553, in main
    manager.run()
  File "/var/lib/juju/agents/unit-postgresql-test-app-0/charm/venv/ops/main.py", line 529, in run
    self._emit()
  File "/var/lib/juju/agents/unit-postgresql-test-app-0/charm/venv/ops/main.py", line 518, in _emit
    _emit_charm_event(self.charm, self.dispatcher.event_name, self._juju_context)
  File "/var/lib/juju/agents/unit-postgresql-test-app-0/charm/venv/ops/main.py", line 139, in _emit_charm_event
    event_to_emit.emit(*args, **kwargs)
  File "/var/lib/juju/agents/unit-postgresql-test-app-0/charm/venv/ops/framework.py", line 347, in emit
    framework._emit(event)
  File "/var/lib/juju/agents/unit-postgresql-test-app-0/charm/venv/ops/framework.py", line 853, in _emit
    self._reemit(event_path)
  File "/var/lib/juju/agents/unit-postgresql-test-app-0/charm/venv/ops/framework.py", line 943, in _reemit
    custom_handler(event)
  File "/var/lib/juju/agents/unit-postgresql-test-app-0/charm/./src/charm.py", line 289, in _on_clear_continuous_writes_action
    if self._connection_string is None:
  File "/var/lib/juju/agents/unit-postgresql-test-app-0/charm/./src/charm.py", line 259, in _connection_string
    data = list(self.first_database.fetch_relation_data().values())[0]
AttributeError: 'ApplicationCharm' object has no attribute 'first_database'
unit-postgresql-test-app-0: 01:44:45 ERROR unit.postgresql-test-app/0.juju-log Uncaught exception while in charm code:
Traceback (most recent call last):
  File "/var/lib/juju/agents/unit-postgresql-test-app-0/charm/./src/charm.py", line 538, in <module>
    main(ApplicationCharm)
  File "/var/lib/juju/agents/unit-postgresql-test-app-0/charm/venv/ops/main.py", line 553, in main
    manager.run()
  File "/var/lib/juju/agents/unit-postgresql-test-app-0/charm/venv/ops/main.py", line 529, in run
    self._emit()
  File "/var/lib/juju/agents/unit-postgresql-test-app-0/charm/venv/ops/main.py", line 518, in _emit
    _emit_charm_event(self.charm, self.dispatcher.event_name, self._juju_context)
  File "/var/lib/juju/agents/unit-postgresql-test-app-0/charm/venv/ops/main.py", line 139, in _emit_charm_event
    event_to_emit.emit(*args, **kwargs)
  File "/var/lib/juju/agents/unit-postgresql-test-app-0/charm/venv/ops/framework.py", line 347, in emit
    framework._emit(event)
  File "/var/lib/juju/agents/unit-postgresql-test-app-0/charm/venv/ops/framework.py", line 853, in _emit
    self._reemit(event_path)
  File "/var/lib/juju/agents/unit-postgresql-test-app-0/charm/venv/ops/framework.py", line 943, in _reemit
    custom_handler(event)
  File "/var/lib/juju/agents/unit-postgresql-test-app-0/charm/./src/charm.py", line 289, in _on_clear_continuous_writes_action
    if self._connection_string is None:
  File "/var/lib/juju/agents/unit-postgresql-test-app-0/charm/./src/charm.py", line 259, in _connection_string
    data = list(self.first_database.fetch_relation_data().values())[0]
AttributeError: 'ApplicationCharm' object has no attribute 'first_database'
unit-postgresql-test-app-0: 01:44:49 ERROR unit.postgresql-test-app/0.juju-log Uncaught exception while in charm code:
Traceback (most recent call last):
  File "/var/lib/juju/agents/unit-postgresql-test-app-0/charm/./src/charm.py", line 538, in <module>
    main(ApplicationCharm)
  File "/var/lib/juju/agents/unit-postgresql-test-app-0/charm/venv/ops/main.py", line 553, in main
    manager.run()
  File "/var/lib/juju/agents/unit-postgresql-test-app-0/charm/venv/ops/main.py", line 529, in run
    self._emit()
  File "/var/lib/juju/agents/unit-postgresql-test-app-0/charm/venv/ops/main.py", line 518, in _emit
    _emit_charm_event(self.charm, self.dispatcher.event_name, self._juju_context)
  File "/var/lib/juju/agents/unit-postgresql-test-app-0/charm/venv/ops/main.py", line 139, in _emit_charm_event
    event_to_emit.emit(*args, **kwargs)
  File "/var/lib/juju/agents/unit-postgresql-test-app-0/charm/venv/ops/framework.py", line 347, in emit
    framework._emit(event)
  File "/var/lib/juju/agents/unit-postgresql-test-app-0/charm/venv/ops/framework.py", line 853, in _emit
    self._reemit(event_path)
  File "/var/lib/juju/agents/unit-postgresql-test-app-0/charm/venv/ops/framework.py", line 943, in _reemit
    custom_handler(event)
  File "/var/lib/juju/agents/unit-postgresql-test-app-0/charm/./src/charm.py", line 289, in _on_clear_continuous_writes_action
    if self._connection_string is None:
  File "/var/lib/juju/agents/unit-postgresql-test-app-0/charm/./src/charm.py", line 259, in _connection_string
    data = list(self.first_database.fetch_relation_data().values())[0]
AttributeError: 'ApplicationCharm' object has no attribute 'first_database'
unit-postgresql-test-app-0: 01:44:53 ERROR unit.postgresql-test-app/0.juju-log Uncaught exception while in charm code:
Traceback (most recent call last):
  File "/var/lib/juju/agents/unit-postgresql-test-app-0/charm/./src/charm.py", line 538, in <module>
    main(ApplicationCharm)
  File "/var/lib/juju/agents/unit-postgresql-test-app-0/charm/venv/ops/main.py", line 553, in main
    manager.run()
  File "/var/lib/juju/agents/unit-postgresql-test-app-0/charm/venv/ops/main.py", line 529, in run
    self._emit()
  File "/var/lib/juju/agents/unit-postgresql-test-app-0/charm/venv/ops/main.py", line 518, in _emit
    _emit_charm_event(self.charm, self.dispatcher.event_name, self._juju_context)
  File "/var/lib/juju/agents/unit-postgresql-test-app-0/charm/venv/ops/main.py", line 139, in _emit_charm_event
    event_to_emit.emit(*args, **kwargs)
  File "/var/lib/juju/agents/unit-postgresql-test-app-0/charm/venv/ops/framework.py", line 347, in emit
    framework._emit(event)
  File "/var/lib/juju/agents/unit-postgresql-test-app-0/charm/venv/ops/framework.py", line 853, in _emit
    self._reemit(event_path)
  File "/var/lib/juju/agents/unit-postgresql-test-app-0/charm/venv/ops/framework.py", line 943, in _reemit
    custom_handler(event)
  File "/var/lib/juju/agents/unit-postgresql-test-app-0/charm/./src/charm.py", line 289, in _on_clear_continuous_writes_action
    if self._connection_string is None:
  File "/var/lib/juju/agents/unit-postgresql-test-app-0/charm/./src/charm.py", line 259, in _connection_string
    data = list(self.first_database.fetch_relation_data().values())[0]
AttributeError: 'ApplicationCharm' object has no attribute 'first_database'
unit-postgresql-test-app-0: 01:44:57 ERROR unit.postgresql-test-app/0.juju-log Uncaught exception while in charm code:
Traceback (most recent call last):
  File "/var/lib/juju/agents/unit-postgresql-test-app-0/charm/./src/charm.py", line 538, in <module>
    main(ApplicationCharm)
  File "/var/lib/juju/agents/unit-postgresql-test-app-0/charm/venv/ops/main.py", line 553, in main
    manager.run()
  File "/var/lib/juju/agents/unit-postgresql-test-app-0/charm/venv/ops/main.py", line 529, in run
    self._emit()
  File "/var/lib/juju/agents/unit-postgresql-test-app-0/charm/venv/ops/main.py", line 518, in _emit
    _emit_charm_event(self.charm, self.dispatcher.event_name, self._juju_context)
  File "/var/lib/juju/agents/unit-postgresql-test-app-0/charm/venv/ops/main.py", line 139, in _emit_charm_event
    event_to_emit.emit(*args, **kwargs)
  File "/var/lib/juju/agents/unit-postgresql-test-app-0/charm/venv/ops/framework.py", line 347, in emit
    framework._emit(event)
  File "/var/lib/juju/agents/unit-postgresql-test-app-0/charm/venv/ops/framework.py", line 853, in _emit
    self._reemit(event_path)
  File "/var/lib/juju/agents/unit-postgresql-test-app-0/charm/venv/ops/framework.py", line 943, in _reemit
    custom_handler(event)
  File "/var/lib/juju/agents/unit-postgresql-test-app-0/charm/./src/charm.py", line 289, in _on_clear_continuous_writes_action
    if self._connection_string is None:
  File "/var/lib/juju/agents/unit-postgresql-test-app-0/charm/./src/charm.py", line 259, in _connection_string
    data = list(self.first_database.fetch_relation_data().values())[0]
AttributeError: 'ApplicationCharm' object has no attribute 'first_database'
unit-postgresql-test-app-0: 01:45:01 ERROR unit.postgresql-test-app/0.juju-log Uncaught exception while in charm code:
Traceback (most recent call last):
  File "/var/lib/juju/agents/unit-postgresql-test-app-0/charm/./src/charm.py", line 538, in <module>
    main(ApplicationCharm)
  File "/var/lib/juju/agents/unit-postgresql-test-app-0/charm/venv/ops/main.py", line 553, in main
    manager.run()
  File "/var/lib/juju/agents/unit-postgresql-test-app-0/charm/venv/ops/main.py", line 529, in run
    self._emit()
  File "/var/lib/juju/agents/unit-postgresql-test-app-0/charm/venv/ops/main.py", line 518, in _emit
    _emit_charm_event(self.charm, self.dispatcher.event_name, self._juju_context)
  File "/var/lib/juju/agents/unit-postgresql-test-app-0/charm/venv/ops/main.py", line 139, in _emit_charm_event
    event_to_emit.emit(*args, **kwargs)
  File "/var/lib/juju/agents/unit-postgresql-test-app-0/charm/venv/ops/framework.py", line 347, in emit
    framework._emit(event)
  File "/var/lib/juju/agents/unit-postgresql-test-app-0/charm/venv/ops/framework.py", line 853, in _emit
    self._reemit(event_path)
  File "/var/lib/juju/agents/unit-postgresql-test-app-0/charm/venv/ops/framework.py", line 943, in _reemit
    custom_handler(event)
  File "/var/lib/juju/agents/unit-postgresql-test-app-0/charm/./src/charm.py", line 289, in _on_clear_continuous_writes_action
    if self._connection_string is None:
  File "/var/lib/juju/agents/unit-postgresql-test-app-0/charm/./src/charm.py", line 259, in _connection_string
    data = list(self.first_database.fetch_relation_data().values())[0]
AttributeError: 'ApplicationCharm' object has no attribute 'first_database'
unit-postgresql-test-app-0: 01:45:05 ERROR unit.postgresql-test-app/0.juju-log Uncaught exception while in charm code:
Traceback (most recent call last):
  File "/var/lib/juju/agents/unit-postgresql-test-app-0/charm/./src/charm.py", line 538, in <module>
    main(ApplicationCharm)
  File "/var/lib/juju/agents/unit-postgresql-test-app-0/charm/venv/ops/main.py", line 553, in main
    manager.run()
  File "/var/lib/juju/agents/unit-postgresql-test-app-0/charm/venv/ops/main.py", line 529, in run
    self._emit()
  File "/var/lib/juju/agents/unit-postgresql-test-app-0/charm/venv/ops/main.py", line 518, in _emit
    _emit_charm_event(self.charm, self.dispatcher.event_name, self._juju_context)
  File "/var/lib/juju/agents/unit-postgresql-test-app-0/charm/venv/ops/main.py", line 139, in _emit_charm_event
    event_to_emit.emit(*args, **kwargs)
  File "/var/lib/juju/agents/unit-postgresql-test-app-0/charm/venv/ops/framework.py", line 347, in emit
    framework._emit(event)
  File "/var/lib/juju/agents/unit-postgresql-test-app-0/charm/venv/ops/framework.py", line 853, in _emit
    self._reemit(event_path)
  File "/var/lib/juju/agents/unit-postgresql-test-app-0/charm/venv/ops/framework.py", line 943, in _reemit
    custom_handler(event)
  File "/var/lib/juju/agents/unit-postgresql-test-app-0/charm/./src/charm.py", line 289, in _on_clear_continuous_writes_action
    if self._connection_string is None:
  File "/var/lib/juju/agents/unit-postgresql-test-app-0/charm/./src/charm.py", line 259, in _connection_string
    data = list(self.first_database.fetch_relation_data().values())[0]
AttributeError: 'ApplicationCharm' object has no attribute 'first_database'
unit-postgresql-test-app-0: 01:45:10 ERROR unit.postgresql-test-app/0.juju-log Uncaught exception while in charm code:
Traceback (most recent call last):
  File "/var/lib/juju/agents/unit-postgresql-test-app-0/charm/./src/charm.py", line 538, in <module>
    main(ApplicationCharm)
  File "/var/lib/juju/agents/unit-postgresql-test-app-0/charm/venv/ops/main.py", line 553, in main
    manager.run()
  File "/var/lib/juju/agents/unit-postgresql-test-app-0/charm/venv/ops/main.py", line 529, in run
    self._emit()
  File "/var/lib/juju/agents/unit-postgresql-test-app-0/charm/venv/ops/main.py", line 518, in _emit
    _emit_charm_event(self.charm, self.dispatcher.event_name, self._juju_context)
  File "/var/lib/juju/agents/unit-postgresql-test-app-0/charm/venv/ops/main.py", line 139, in _emit_charm_event
    event_to_emit.emit(*args, **kwargs)
  File "/var/lib/juju/agents/unit-postgresql-test-app-0/charm/venv/ops/framework.py", line 347, in emit
    framework._emit(event)
  File "/var/lib/juju/agents/unit-postgresql-test-app-0/charm/venv/ops/framework.py", line 853, in _emit
    self._reemit(event_path)
  File "/var/lib/juju/agents/unit-postgresql-test-app-0/charm/venv/ops/framework.py", line 943, in _reemit
    custom_handler(event)
  File "/var/lib/juju/agents/unit-postgresql-test-app-0/charm/./src/charm.py", line 289, in _on_clear_continuous_writes_action
    if self._connection_string is None:
  File "/var/lib/juju/agents/unit-postgresql-test-app-0/charm/./src/charm.py", line 259, in _connection_string
    data = list(self.first_database.fetch_relation_data().values())[0]
AttributeError: 'ApplicationCharm' object has no attribute 'first_database'
unit-postgresql-test-app-0: 01:45:14 ERROR unit.postgresql-test-app/0.juju-log Uncaught exception while in charm code:
Traceback (most recent call last):
  File "/var/lib/juju/agents/unit-postgresql-test-app-0/charm/./src/charm.py", line 538, in <module>
    main(ApplicationCharm)
  File "/var/lib/juju/agents/unit-postgresql-test-app-0/charm/venv/ops/main.py", line 553, in main
    manager.run()
  File "/var/lib/juju/agents/unit-postgresql-test-app-0/charm/venv/ops/main.py", line 529, in run
    self._emit()
  File "/var/lib/juju/agents/unit-postgresql-test-app-0/charm/venv/ops/main.py", line 518, in _emit
    _emit_charm_event(self.charm, self.dispatcher.event_name, self._juju_context)
  File "/var/lib/juju/agents/unit-postgresql-test-app-0/charm/venv/ops/main.py", line 139, in _emit_charm_event
    event_to_emit.emit(*args, **kwargs)
  File "/var/lib/juju/agents/unit-postgresql-test-app-0/charm/venv/ops/framework.py", line 347, in emit
    framework._emit(event)
  File "/var/lib/juju/agents/unit-postgresql-test-app-0/charm/venv/ops/framework.py", line 853, in _emit
    self._reemit(event_path)
  File "/var/lib/juju/agents/unit-postgresql-test-app-0/charm/venv/ops/framework.py", line 943, in _reemit
    custom_handler(event)
  File "/var/lib/juju/agents/unit-postgresql-test-app-0/charm/./src/charm.py", line 289, in _on_clear_continuous_writes_action
    if self._connection_string is None:
  File "/var/lib/juju/agents/unit-postgresql-test-app-0/charm/./src/charm.py", line 259, in _connection_string
    data = list(self.first_database.fetch_relation_data().values())[0]
AttributeError: 'ApplicationCharm' object has no attribute 'first_database'
unit-postgresql-test-app-0: 01:45:18 ERROR unit.postgresql-test-app/0.juju-log Uncaught exception while in charm code:
Traceback (most recent call last):
  File "/var/lib/juju/agents/unit-postgresql-test-app-0/charm/./src/charm.py", line 538, in <module>
    main(ApplicationCharm)
  File "/var/lib/juju/agents/unit-postgresql-test-app-0/charm/venv/ops/main.py", line 553, in main
    manager.run()
  File "/var/lib/juju/agents/unit-postgresql-test-app-0/charm/venv/ops/main.py", line 529, in run
    self._emit()
  File "/var/lib/juju/agents/unit-postgresql-test-app-0/charm/venv/ops/main.py", line 518, in _emit
    _emit_charm_event(self.charm, self.dispatcher.event_name, self._juju_context)
  File "/var/lib/juju/agents/unit-postgresql-test-app-0/charm/venv/ops/main.py", line 139, in _emit_charm_event
    event_to_emit.emit(*args, **kwargs)
  File "/var/lib/juju/agents/unit-postgresql-test-app-0/charm/venv/ops/framework.py", line 347, in emit
    framework._emit(event)
  File "/var/lib/juju/agents/unit-postgresql-test-app-0/charm/venv/ops/framework.py", line 853, in _emit
    self._reemit(event_path)
  File "/var/lib/juju/agents/unit-postgresql-test-app-0/charm/venv/ops/framework.py", line 943, in _reemit
    custom_handler(event)
  File "/var/lib/juju/agents/unit-postgresql-test-app-0/charm/./src/charm.py", line 289, in _on_clear_continuous_writes_action
    if self._connection_string is None:
  File "/var/lib/juju/agents/unit-postgresql-test-app-0/charm/./src/charm.py", line 259, in _connection_string
    data = list(self.first_database.fetch_relation_data().values())[0]
AttributeError: 'ApplicationCharm' object has no attribute 'first_database'
unit-postgresql-test-app-0: 01:45:22 ERROR unit.postgresql-test-app/0.juju-log Uncaught exception while in charm code:
Traceback (most recent call last):
  File "/var/lib/juju/agents/unit-postgresql-test-app-0/charm/./src/charm.py", line 538, in <module>
    main(ApplicationCharm)
  File "/var/lib/juju/agents/unit-postgresql-test-app-0/charm/venv/ops/main.py", line 553, in main
    manager.run()
  File "/var/lib/juju/agents/unit-postgresql-test-app-0/charm/venv/ops/main.py", line 529, in run
    self._emit()
  File "/var/lib/juju/agents/unit-postgresql-test-app-0/charm/venv/ops/main.py", line 518, in _emit
    _emit_charm_event(self.charm, self.dispatcher.event_name, self._juju_context)
  File "/var/lib/juju/agents/unit-postgresql-test-app-0/charm/venv/ops/main.py", line 139, in _emit_charm_event
    event_to_emit.emit(*args, **kwargs)
  File "/var/lib/juju/agents/unit-postgresql-test-app-0/charm/venv/ops/framework.py", line 347, in emit
    framework._emit(event)
  File "/var/lib/juju/agents/unit-postgresql-test-app-0/charm/venv/ops/framework.py", line 853, in _emit
    self._reemit(event_path)
  File "/var/lib/juju/agents/unit-postgresql-test-app-0/charm/venv/ops/framework.py", line 943, in _reemit
    custom_handler(event)
  File "/var/lib/juju/agents/unit-postgresql-test-app-0/charm/./src/charm.py", line 289, in _on_clear_continuous_writes_action
    if self._connection_string is None:
  File "/var/lib/juju/agents/unit-postgresql-test-app-0/charm/./src/charm.py", line 259, in _connection_string
    data = list(self.first_database.fetch_relation_data().values())[0]
AttributeError: 'ApplicationCharm' object has no attribute 'first_database'
unit-postgresql-test-app-0: 01:45:26 ERROR unit.postgresql-test-app/0.juju-log Uncaught exception while in charm code:
Traceback (most recent call last):
  File "/var/lib/juju/agents/unit-postgresql-test-app-0/charm/./src/charm.py", line 538, in <module>
    main(ApplicationCharm)
  File "/var/lib/juju/agents/unit-postgresql-test-app-0/charm/venv/ops/main.py", line 553, in main
    manager.run()
  File "/var/lib/juju/agents/unit-postgresql-test-app-0/charm/venv/ops/main.py", line 529, in run
    self._emit()
  File "/var/lib/juju/agents/unit-postgresql-test-app-0/charm/venv/ops/main.py", line 518, in _emit
    _emit_charm_event(self.charm, self.dispatcher.event_name, self._juju_context)
  File "/var/lib/juju/agents/unit-postgresql-test-app-0/charm/venv/ops/main.py", line 139, in _emit_charm_event
    event_to_emit.emit(*args, **kwargs)
  File "/var/lib/juju/agents/unit-postgresql-test-app-0/charm/venv/ops/framework.py", line 347, in emit
    framework._emit(event)
  File "/var/lib/juju/agents/unit-postgresql-test-app-0/charm/venv/ops/framework.py", line 853, in _emit
    self._reemit(event_path)
  File "/var/lib/juju/agents/unit-postgresql-test-app-0/charm/venv/ops/framework.py", line 943, in _reemit
    custom_handler(event)
  File "/var/lib/juju/agents/unit-postgresql-test-app-0/charm/./src/charm.py", line 289, in _on_clear_continuous_writes_action
    if self._connection_string is None:
  File "/var/lib/juju/agents/unit-postgresql-test-app-0/charm/./src/charm.py", line 259, in _connection_string
    data = list(self.first_database.fetch_relation_data().values())[0]
AttributeError: 'ApplicationCharm' object has no attribute 'first_database'
unit-postgresql-test-app-0: 01:45:30 ERROR unit.postgresql-test-app/0.juju-log Uncaught exception while in charm code:
Traceback (most recent call last):
  File "/var/lib/juju/agents/unit-postgresql-test-app-0/charm/./src/charm.py", line 538, in <module>
    main(ApplicationCharm)
  File "/var/lib/juju/agents/unit-postgresql-test-app-0/charm/venv/ops/main.py", line 553, in main
    manager.run()
  File "/var/lib/juju/agents/unit-postgresql-test-app-0/charm/venv/ops/main.py", line 529, in run
    self._emit()
  File "/var/lib/juju/agents/unit-postgresql-test-app-0/charm/venv/ops/main.py", line 518, in _emit
    _emit_charm_event(self.charm, self.dispatcher.event_name, self._juju_context)
  File "/var/lib/juju/agents/unit-postgresql-test-app-0/charm/venv/ops/main.py", line 139, in _emit_charm_event
    event_to_emit.emit(*args, **kwargs)
  File "/var/lib/juju/agents/unit-postgresql-test-app-0/charm/venv/ops/framework.py", line 347, in emit
    framework._emit(event)
  File "/var/lib/juju/agents/unit-postgresql-test-app-0/charm/venv/ops/framework.py", line 853, in _emit
    self._reemit(event_path)
  File "/var/lib/juju/agents/unit-postgresql-test-app-0/charm/venv/ops/framework.py", line 943, in _reemit
    custom_handler(event)
  File "/var/lib/juju/agents/unit-postgresql-test-app-0/charm/./src/charm.py", line 289, in _on_clear_continuous_writes_action
    if self._connection_string is None:
  File "/var/lib/juju/agents/unit-postgresql-test-app-0/charm/./src/charm.py", line 259, in _connection_string
    data = list(self.first_database.fetch_relation_data().values())[0]
AttributeError: 'ApplicationCharm' object has no attribute 'first_database'
unit-postgresql-test-app-0: 01:45:34 ERROR unit.postgresql-test-app/0.juju-log Uncaught exception while in charm code:
Traceback (most recent call last):
  File "/var/lib/juju/agents/unit-postgresql-test-app-0/charm/./src/charm.py", line 538, in <module>
    main(ApplicationCharm)
  File "/var/lib/juju/agents/unit-postgresql-test-app-0/charm/venv/ops/main.py", line 553, in main
    manager.run()
  File "/var/lib/juju/agents/unit-postgresql-test-app-0/charm/venv/ops/main.py", line 529, in run
    self._emit()
  File "/var/lib/juju/agents/unit-postgresql-test-app-0/charm/venv/ops/main.py", line 518, in _emit
    _emit_charm_event(self.charm, self.dispatcher.event_name, self._juju_context)
  File "/var/lib/juju/agents/unit-postgresql-test-app-0/charm/venv/ops/main.py", line 139, in _emit_charm_event
    event_to_emit.emit(*args, **kwargs)
  File "/var/lib/juju/agents/unit-postgresql-test-app-0/charm/venv/ops/framework.py", line 347, in emit
    framework._emit(event)
  File "/var/lib/juju/agents/unit-postgresql-test-app-0/charm/venv/ops/framework.py", line 853, in _emit
    self._reemit(event_path)
  File "/var/lib/juju/agents/unit-postgresql-test-app-0/charm/venv/ops/framework.py", line 943, in _reemit
    custom_handler(event)
  File "/var/lib/juju/agents/unit-postgresql-test-app-0/charm/./src/charm.py", line 289, in _on_clear_continuous_writes_action
    if self._connection_string is None:
  File "/var/lib/juju/agents/unit-postgresql-test-app-0/charm/./src/charm.py", line 259, in _connection_string
    data = list(self.first_database.fetch_relation_data().values())[0]
AttributeError: 'ApplicationCharm' object has no attribute 'first_database'
unit-postgresql-test-app-0: 01:45:38 ERROR unit.postgresql-test-app/0.juju-log Uncaught exception while in charm code:
Traceback (most recent call last):
  File "/var/lib/juju/agents/unit-postgresql-test-app-0/charm/./src/charm.py", line 538, in <module>
    main(ApplicationCharm)
  File "/var/lib/juju/agents/unit-postgresql-test-app-0/charm/venv/ops/main.py", line 553, in main
    manager.run()
  File "/var/lib/juju/agents/unit-postgresql-test-app-0/charm/venv/ops/main.py", line 529, in run
    self._emit()
  File "/var/lib/juju/agents/unit-postgresql-test-app-0/charm/venv/ops/main.py", line 518, in _emit
    _emit_charm_event(self.charm, self.dispatcher.event_name, self._juju_context)
  File "/var/lib/juju/agents/unit-postgresql-test-app-0/charm/venv/ops/main.py", line 139, in _emit_charm_event
    event_to_emit.emit(*args, **kwargs)
  File "/var/lib/juju/agents/unit-postgresql-test-app-0/charm/venv/ops/framework.py", line 347, in emit
    framework._emit(event)
  File "/var/lib/juju/agents/unit-postgresql-test-app-0/charm/venv/ops/framework.py", line 853, in _emit
    self._reemit(event_path)
  File "/var/lib/juju/agents/unit-postgresql-test-app-0/charm/venv/ops/framework.py", line 943, in _reemit
    custom_handler(event)
  File "/var/lib/juju/agents/unit-postgresql-test-app-0/charm/./src/charm.py", line 289, in _on_clear_continuous_writes_action
    if self._connection_string is None:
  File "/var/lib/juju/agents/unit-postgresql-test-app-0/charm/./src/charm.py", line 259, in _connection_string
    data = list(self.first_database.fetch_relation_data().values())[0]
AttributeError: 'ApplicationCharm' object has no attribute 'first_database'
unit-postgresql-test-app-0: 01:45:42 ERROR unit.postgresql-test-app/0.juju-log Uncaught exception while in charm code:
Traceback (most recent call last):
  File "/var/lib/juju/agents/unit-postgresql-test-app-0/charm/./src/charm.py", line 538, in <module>
    main(ApplicationCharm)
  File "/var/lib/juju/agents/unit-postgresql-test-app-0/charm/venv/ops/main.py", line 553, in main
    manager.run()
  File "/var/lib/juju/agents/unit-postgresql-test-app-0/charm/venv/ops/main.py", line 529, in run
    self._emit()
  File "/var/lib/juju/agents/unit-postgresql-test-app-0/charm/venv/ops/main.py", line 518, in _emit
    _emit_charm_event(self.charm, self.dispatcher.event_name, self._juju_context)
  File "/var/lib/juju/agents/unit-postgresql-test-app-0/charm/venv/ops/main.py", line 139, in _emit_charm_event
    event_to_emit.emit(*args, **kwargs)
  File "/var/lib/juju/agents/unit-postgresql-test-app-0/charm/venv/ops/framework.py", line 347, in emit
    framework._emit(event)
  File "/var/lib/juju/agents/unit-postgresql-test-app-0/charm/venv/ops/framework.py", line 853, in _emit
    self._reemit(event_path)
  File "/var/lib/juju/agents/unit-postgresql-test-app-0/charm/venv/ops/framework.py", line 943, in _reemit
    custom_handler(event)
  File "/var/lib/juju/agents/unit-postgresql-test-app-0/charm/./src/charm.py", line 289, in _on_clear_continuous_writes_action
    if self._connection_string is None:
  File "/var/lib/juju/agents/unit-postgresql-test-app-0/charm/./src/charm.py", line 259, in _connection_string
    data = list(self.first_database.fetch_relation_data().values())[0]
AttributeError: 'ApplicationCharm' object has no attribute 'first_database'
unit-postgresql-test-app-0: 01:45:46 ERROR unit.postgresql-test-app/0.juju-log Uncaught exception while in charm code:
Traceback (most recent call last):
  File "/var/lib/juju/agents/unit-postgresql-test-app-0/charm/./src/charm.py", line 538, in <module>
    main(ApplicationCharm)
  File "/var/lib/juju/agents/unit-postgresql-test-app-0/charm/venv/ops/main.py", line 553, in main
    manager.run()
  File "/var/lib/juju/agents/unit-postgresql-test-app-0/charm/venv/ops/main.py", line 529, in run
    self._emit()
  File "/var/lib/juju/agents/unit-postgresql-test-app-0/charm/venv/ops/main.py", line 518, in _emit
    _emit_charm_event(self.charm, self.dispatcher.event_name, self._juju_context)
  File "/var/lib/juju/agents/unit-postgresql-test-app-0/charm/venv/ops/main.py", line 139, in _emit_charm_event
    event_to_emit.emit(*args, **kwargs)
  File "/var/lib/juju/agents/unit-postgresql-test-app-0/charm/venv/ops/framework.py", line 347, in emit
    framework._emit(event)
  File "/var/lib/juju/agents/unit-postgresql-test-app-0/charm/venv/ops/framework.py", line 853, in _emit
    self._reemit(event_path)
  File "/var/lib/juju/agents/unit-postgresql-test-app-0/charm/venv/ops/framework.py", line 943, in _reemit
    custom_handler(event)
  File "/var/lib/juju/agents/unit-postgresql-test-app-0/charm/./src/charm.py", line 289, in _on_clear_continuous_writes_action
    if self._connection_string is None:
  File "/var/lib/juju/agents/unit-postgresql-test-app-0/charm/./src/charm.py", line 259, in _connection_string
    data = list(self.first_database.fetch_relation_data().values())[0]
AttributeError: 'ApplicationCharm' object has no attribute 'first_database'
unit-postgresql-test-app-0: 01:45:50 ERROR unit.postgresql-test-app/0.juju-log Uncaught exception while in charm code:
Traceback (most recent call last):
  File "/var/lib/juju/agents/unit-postgresql-test-app-0/charm/./src/charm.py", line 538, in <module>
    main(ApplicationCharm)
  File "/var/lib/juju/agents/unit-postgresql-test-app-0/charm/venv/ops/main.py", line 553, in main
    manager.run()
  File "/var/lib/juju/agents/unit-postgresql-test-app-0/charm/venv/ops/main.py", line 529, in run
    self._emit()
  File "/var/lib/juju/agents/unit-postgresql-test-app-0/charm/venv/ops/main.py", line 518, in _emit
    _emit_charm_event(self.charm, self.dispatcher.event_name, self._juju_context)
  File "/var/lib/juju/agents/unit-postgresql-test-app-0/charm/venv/ops/main.py", line 139, in _emit_charm_event
    event_to_emit.emit(*args, **kwargs)
  File "/var/lib/juju/agents/unit-postgresql-test-app-0/charm/venv/ops/framework.py", line 347, in emit
    framework._emit(event)
  File "/var/lib/juju/agents/unit-postgresql-test-app-0/charm/venv/ops/framework.py", line 853, in _emit
    self._reemit(event_path)
  File "/var/lib/juju/agents/unit-postgresql-test-app-0/charm/venv/ops/framework.py", line 943, in _reemit
    custom_handler(event)
  File "/var/lib/juju/agents/unit-postgresql-test-app-0/charm/./src/charm.py", line 289, in _on_clear_continuous_writes_action
    if self._connection_string is None:
  File "/var/lib/juju/agents/unit-postgresql-test-app-0/charm/./src/charm.py", line 259, in _connection_string
    data = list(self.first_database.fetch_relation_data().values())[0]
AttributeError: 'ApplicationCharm' object has no attribute 'first_database'
unit-postgresql-test-app-0: 01:45:54 ERROR unit.postgresql-test-app/0.juju-log Uncaught exception while in charm code:
Traceback (most recent call last):
  File "/var/lib/juju/agents/unit-postgresql-test-app-0/charm/./src/charm.py", line 538, in <module>
    main(ApplicationCharm)
  File "/var/lib/juju/agents/unit-postgresql-test-app-0/charm/venv/ops/main.py", line 553, in main
    manager.run()
  File "/var/lib/juju/agents/unit-postgresql-test-app-0/charm/venv/ops/main.py", line 529, in run
    self._emit()
  File "/var/lib/juju/agents/unit-postgresql-test-app-0/charm/venv/ops/main.py", line 518, in _emit
    _emit_charm_event(self.charm, self.dispatcher.event_name, self._juju_context)
  File "/var/lib/juju/agents/unit-postgresql-test-app-0/charm/venv/ops/main.py", line 139, in _emit_charm_event
    event_to_emit.emit(*args, **kwargs)
  File "/var/lib/juju/agents/unit-postgresql-test-app-0/charm/venv/ops/framework.py", line 347, in emit
    framework._emit(event)
  File "/var/lib/juju/agents/unit-postgresql-test-app-0/charm/venv/ops/framework.py", line 853, in _emit
    self._reemit(event_path)
  File "/var/lib/juju/agents/unit-postgresql-test-app-0/charm/venv/ops/framework.py", line 943, in _reemit
    custom_handler(event)
  File "/var/lib/juju/agents/unit-postgresql-test-app-0/charm/./src/charm.py", line 289, in _on_clear_continuous_writes_action
    if self._connection_string is None:
  File "/var/lib/juju/agents/unit-postgresql-test-app-0/charm/./src/charm.py", line 259, in _connection_string
    data = list(self.first_database.fetch_relation_data().values())[0]
AttributeError: 'ApplicationCharm' object has no attribute 'first_database'
unit-postgresql-test-app-0: 01:45:58 ERROR unit.postgresql-test-app/0.juju-log Uncaught exception while in charm code:
Traceback (most recent call last):
  File "/var/lib/juju/agents/unit-postgresql-test-app-0/charm/./src/charm.py", line 538, in <module>
    main(ApplicationCharm)
  File "/var/lib/juju/agents/unit-postgresql-test-app-0/charm/venv/ops/main.py", line 553, in main
    manager.run()
  File "/var/lib/juju/agents/unit-postgresql-test-app-0/charm/venv/ops/main.py", line 529, in run
    self._emit()
  File "/var/lib/juju/agents/unit-postgresql-test-app-0/charm/venv/ops/main.py", line 518, in _emit
    _emit_charm_event(self.charm, self.dispatcher.event_name, self._juju_context)
  File "/var/lib/juju/agents/unit-postgresql-test-app-0/charm/venv/ops/main.py", line 139, in _emit_charm_event
    event_to_emit.emit(*args, **kwargs)
  File "/var/lib/juju/agents/unit-postgresql-test-app-0/charm/venv/ops/framework.py", line 347, in emit
    framework._emit(event)
  File "/var/lib/juju/agents/unit-postgresql-test-app-0/charm/venv/ops/framework.py", line 853, in _emit
    self._reemit(event_path)
  File "/var/lib/juju/agents/unit-postgresql-test-app-0/charm/venv/ops/framework.py", line 943, in _reemit
    custom_handler(event)
  File "/var/lib/juju/agents/unit-postgresql-test-app-0/charm/./src/charm.py", line 289, in _on_clear_continuous_writes_action
    if self._connection_string is None:
  File "/var/lib/juju/agents/unit-postgresql-test-app-0/charm/./src/charm.py", line 259, in _connection_string
    data = list(self.first_database.fetch_relation_data().values())[0]
AttributeError: 'ApplicationCharm' object has no attribute 'first_database'
unit-postgresql-test-app-0: 01:46:02 ERROR unit.postgresql-test-app/0.juju-log Uncaught exception while in charm code:
Traceback (most recent call last):
  File "/var/lib/juju/agents/unit-postgresql-test-app-0/charm/./src/charm.py", line 538, in <module>
    main(ApplicationCharm)
  File "/var/lib/juju/agents/unit-postgresql-test-app-0/charm/venv/ops/main.py", line 553, in main
    manager.run()
  File "/var/lib/juju/agents/unit-postgresql-test-app-0/charm/venv/ops/main.py", line 529, in run
    self._emit()
  File "/var/lib/juju/agents/unit-postgresql-test-app-0/charm/venv/ops/main.py", line 518, in _emit
    _emit_charm_event(self.charm, self.dispatcher.event_name, self._juju_context)
  File "/var/lib/juju/agents/unit-postgresql-test-app-0/charm/venv/ops/main.py", line 139, in _emit_charm_event
    event_to_emit.emit(*args, **kwargs)
  File "/var/lib/juju/agents/unit-postgresql-test-app-0/charm/venv/ops/framework.py", line 347, in emit
    framework._emit(event)
  File "/var/lib/juju/agents/unit-postgresql-test-app-0/charm/venv/ops/framework.py", line 853, in _emit
    self._reemit(event_path)
  File "/var/lib/juju/agents/unit-postgresql-test-app-0/charm/venv/ops/framework.py", line 943, in _reemit
    custom_handler(event)
  File "/var/lib/juju/agents/unit-postgresql-test-app-0/charm/./src/charm.py", line 289, in _on_clear_continuous_writes_action
    if self._connection_string is None:
  File "/var/lib/juju/agents/unit-postgresql-test-app-0/charm/./src/charm.py", line 259, in _connection_string
    data = list(self.first_database.fetch_relation_data().values())[0]
AttributeError: 'ApplicationCharm' object has no attribute 'first_database'
unit-postgresql-test-app-0: 01:46:06 ERROR unit.postgresql-test-app/0.juju-log Uncaught exception while in charm code:
Traceback (most recent call last):
  File "/var/lib/juju/agents/unit-postgresql-test-app-0/charm/./src/charm.py", line 538, in <module>
    main(ApplicationCharm)
  File "/var/lib/juju/agents/unit-postgresql-test-app-0/charm/venv/ops/main.py", line 553, in main
    manager.run()
  File "/var/lib/juju/agents/unit-postgresql-test-app-0/charm/venv/ops/main.py", line 529, in run
    self._emit()
  File "/var/lib/juju/agents/unit-postgresql-test-app-0/charm/venv/ops/main.py", line 518, in _emit
    _emit_charm_event(self.charm, self.dispatcher.event_name, self._juju_context)
  File "/var/lib/juju/agents/unit-postgresql-test-app-0/charm/venv/ops/main.py", line 139, in _emit_charm_event
    event_to_emit.emit(*args, **kwargs)
  File "/var/lib/juju/agents/unit-postgresql-test-app-0/charm/venv/ops/framework.py", line 347, in emit
    framework._emit(event)
  File "/var/lib/juju/agents/unit-postgresql-test-app-0/charm/venv/ops/framework.py", line 853, in _emit
    self._reemit(event_path)
  File "/var/lib/juju/agents/unit-postgresql-test-app-0/charm/venv/ops/framework.py", line 943, in _reemit
    custom_handler(event)
  File "/var/lib/juju/agents/unit-postgresql-test-app-0/charm/./src/charm.py", line 289, in _on_clear_continuous_writes_action
    if self._connection_string is None:
  File "/var/lib/juju/agents/unit-postgresql-test-app-0/charm/./src/charm.py", line 259, in _connection_string
    data = list(self.first_database.fetch_relation_data().values())[0]
AttributeError: 'ApplicationCharm' object has no attribute 'first_database'
unit-postgresql-test-app-0: 01:46:10 ERROR unit.postgresql-test-app/0.juju-log Uncaught exception while in charm code:
Traceback (most recent call last):
  File "/var/lib/juju/agents/unit-postgresql-test-app-0/charm/./src/charm.py", line 538, in <module>
    main(ApplicationCharm)
  File "/var/lib/juju/agents/unit-postgresql-test-app-0/charm/venv/ops/main.py", line 553, in main
    manager.run()
  File "/var/lib/juju/agents/unit-postgresql-test-app-0/charm/venv/ops/main.py", line 529, in run
    self._emit()
  File "/var/lib/juju/agents/unit-postgresql-test-app-0/charm/venv/ops/main.py", line 518, in _emit
    _emit_charm_event(self.charm, self.dispatcher.event_name, self._juju_context)
  File "/var/lib/juju/agents/unit-postgresql-test-app-0/charm/venv/ops/main.py", line 139, in _emit_charm_event
    event_to_emit.emit(*args, **kwargs)
  File "/var/lib/juju/agents/unit-postgresql-test-app-0/charm/venv/ops/framework.py", line 347, in emit
    framework._emit(event)
  File "/var/lib/juju/agents/unit-postgresql-test-app-0/charm/venv/ops/framework.py", line 853, in _emit
    self._reemit(event_path)
  File "/var/lib/juju/agents/unit-postgresql-test-app-0/charm/venv/ops/framework.py", line 943, in _reemit
    custom_handler(event)
  File "/var/lib/juju/agents/unit-postgresql-test-app-0/charm/./src/charm.py", line 289, in _on_clear_continuous_writes_action
    if self._connection_string is None:
  File "/var/lib/juju/agents/unit-postgresql-test-app-0/charm/./src/charm.py", line 259, in _connection_string
    data = list(self.first_database.fetch_relation_data().values())[0]
AttributeError: 'ApplicationCharm' object has no attribute 'first_database'
unit-postgresql-test-app-0: 01:46:14 ERROR unit.postgresql-test-app/0.juju-log Uncaught exception while in charm code:
Traceback (most recent call last):
  File "/var/lib/juju/agents/unit-postgresql-test-app-0/charm/./src/charm.py", line 538, in <module>
    main(ApplicationCharm)
  File "/var/lib/juju/agents/unit-postgresql-test-app-0/charm/venv/ops/main.py", line 553, in main
    manager.run()
  File "/var/lib/juju/agents/unit-postgresql-test-app-0/charm/venv/ops/main.py", line 529, in run
    self._emit()
  File "/var/lib/juju/agents/unit-postgresql-test-app-0/charm/venv/ops/main.py", line 518, in _emit
    _emit_charm_event(self.charm, self.dispatcher.event_name, self._juju_context)
  File "/var/lib/juju/agents/unit-postgresql-test-app-0/charm/venv/ops/main.py", line 139, in _emit_charm_event
    event_to_emit.emit(*args, **kwargs)
  File "/var/lib/juju/agents/unit-postgresql-test-app-0/charm/venv/ops/framework.py", line 347, in emit
    framework._emit(event)
  File "/var/lib/juju/agents/unit-postgresql-test-app-0/charm/venv/ops/framework.py", line 853, in _emit
    self._reemit(event_path)
  File "/var/lib/juju/agents/unit-postgresql-test-app-0/charm/venv/ops/framework.py", line 943, in _reemit
    custom_handler(event)
  File "/var/lib/juju/agents/unit-postgresql-test-app-0/charm/./src/charm.py", line 289, in _on_clear_continuous_writes_action
    if self._connection_string is None:
  File "/var/lib/juju/agents/unit-postgresql-test-app-0/charm/./src/charm.py", line 259, in _connection_string
    data = list(self.first_database.fetch_relation_data().values())[0]
AttributeError: 'ApplicationCharm' object has no attribute 'first_database'
unit-postgresql-test-app-0: 01:46:18 ERROR unit.postgresql-test-app/0.juju-log Uncaught exception while in charm code:
Traceback (most recent call last):
  File "/var/lib/juju/agents/unit-postgresql-test-app-0/charm/./src/charm.py", line 538, in <module>
    main(ApplicationCharm)
  File "/var/lib/juju/agents/unit-postgresql-test-app-0/charm/venv/ops/main.py", line 553, in main
    manager.run()
  File "/var/lib/juju/agents/unit-postgresql-test-app-0/charm/venv/ops/main.py", line 529, in run
    self._emit()
  File "/var/lib/juju/agents/unit-postgresql-test-app-0/charm/venv/ops/main.py", line 518, in _emit
    _emit_charm_event(self.charm, self.dispatcher.event_name, self._juju_context)
  File "/var/lib/juju/agents/unit-postgresql-test-app-0/charm/venv/ops/main.py", line 139, in _emit_charm_event
    event_to_emit.emit(*args, **kwargs)
  File "/var/lib/juju/agents/unit-postgresql-test-app-0/charm/venv/ops/framework.py", line 347, in emit
    framework._emit(event)
  File "/var/lib/juju/agents/unit-postgresql-test-app-0/charm/venv/ops/framework.py", line 853, in _emit
    self._reemit(event_path)
  File "/var/lib/juju/agents/unit-postgresql-test-app-0/charm/venv/ops/framework.py", line 943, in _reemit
    custom_handler(event)
  File "/var/lib/juju/agents/unit-postgresql-test-app-0/charm/./src/charm.py", line 289, in _on_clear_continuous_writes_action
    if self._connection_string is None:
  File "/var/lib/juju/agents/unit-postgresql-test-app-0/charm/./src/charm.py", line 259, in _connection_string
    data = list(self.first_database.fetch_relation_data().values())[0]
AttributeError: 'ApplicationCharm' object has no attribute 'first_database'
unit-postgresql-test-app-0: 01:46:22 ERROR unit.postgresql-test-app/0.juju-log Uncaught exception while in charm code:
Traceback (most recent call last):
  File "/var/lib/juju/agents/unit-postgresql-test-app-0/charm/./src/charm.py", line 538, in <module>
    main(ApplicationCharm)
  File "/var/lib/juju/agents/unit-postgresql-test-app-0/charm/venv/ops/main.py", line 553, in main
    manager.run()
  File "/var/lib/juju/agents/unit-postgresql-test-app-0/charm/venv/ops/main.py", line 529, in run
    self._emit()
  File "/var/lib/juju/agents/unit-postgresql-test-app-0/charm/venv/ops/main.py", line 518, in _emit
    _emit_charm_event(self.charm, self.dispatcher.event_name, self._juju_context)
  File "/var/lib/juju/agents/unit-postgresql-test-app-0/charm/venv/ops/main.py", line 139, in _emit_charm_event
    event_to_emit.emit(*args, **kwargs)
  File "/var/lib/juju/agents/unit-postgresql-test-app-0/charm/venv/ops/framework.py", line 347, in emit
    framework._emit(event)
  File "/var/lib/juju/agents/unit-postgresql-test-app-0/charm/venv/ops/framework.py", line 853, in _emit
    self._reemit(event_path)
  File "/var/lib/juju/agents/unit-postgresql-test-app-0/charm/venv/ops/framework.py", line 943, in _reemit
    custom_handler(event)
  File "/var/lib/juju/agents/unit-postgresql-test-app-0/charm/./src/charm.py", line 289, in _on_clear_continuous_writes_action
    if self._connection_string is None:
  File "/var/lib/juju/agents/unit-postgresql-test-app-0/charm/./src/charm.py", line 259, in _connection_string
    data = list(self.first_database.fetch_relation_data().values())[0]
AttributeError: 'ApplicationCharm' object has no attribute 'first_database'
unit-postgresql-test-app-0: 01:46:26 ERROR unit.postgresql-test-app/0.juju-log Uncaught exception while in charm code:
Traceback (most recent call last):
  File "/var/lib/juju/agents/unit-postgresql-test-app-0/charm/./src/charm.py", line 538, in <module>
    main(ApplicationCharm)
  File "/var/lib/juju/agents/unit-postgresql-test-app-0/charm/venv/ops/main.py", line 553, in main
    manager.run()
  File "/var/lib/juju/agents/unit-postgresql-test-app-0/charm/venv/ops/main.py", line 529, in run
    self._emit()
  File "/var/lib/juju/agents/unit-postgresql-test-app-0/charm/venv/ops/main.py", line 518, in _emit
    _emit_charm_event(self.charm, self.dispatcher.event_name, self._juju_context)
  File "/var/lib/juju/agents/unit-postgresql-test-app-0/charm/venv/ops/main.py", line 139, in _emit_charm_event
    event_to_emit.emit(*args, **kwargs)
  File "/var/lib/juju/agents/unit-postgresql-test-app-0/charm/venv/ops/framework.py", line 347, in emit
    framework._emit(event)
  File "/var/lib/juju/agents/unit-postgresql-test-app-0/charm/venv/ops/framework.py", line 853, in _emit
    self._reemit(event_path)
  File "/var/lib/juju/agents/unit-postgresql-test-app-0/charm/venv/ops/framework.py", line 943, in _reemit
    custom_handler(event)
  File "/var/lib/juju/agents/unit-postgresql-test-app-0/charm/./src/charm.py", line 289, in _on_clear_continuous_writes_action
    if self._connection_string is None:
  File "/var/lib/juju/agents/unit-postgresql-test-app-0/charm/./src/charm.py", line 259, in _connection_string
    data = list(self.first_database.fetch_relation_data().values())[0]
AttributeError: 'ApplicationCharm' object has no attribute 'first_database'
unit-postgresql-test-app-0: 01:46:30 ERROR unit.postgresql-test-app/0.juju-log Uncaught exception while in charm code:
Traceback (most recent call last):
  File "/var/lib/juju/agents/unit-postgresql-test-app-0/charm/./src/charm.py", line 538, in <module>
    main(ApplicationCharm)
  File "/var/lib/juju/agents/unit-postgresql-test-app-0/charm/venv/ops/main.py", line 553, in main
    manager.run()
  File "/var/lib/juju/agents/unit-postgresql-test-app-0/charm/venv/ops/main.py", line 529, in run
    self._emit()
  File "/var/lib/juju/agents/unit-postgresql-test-app-0/charm/venv/ops/main.py", line 518, in _emit
    _emit_charm_event(self.charm, self.dispatcher.event_name, self._juju_context)
  File "/var/lib/juju/agents/unit-postgresql-test-app-0/charm/venv/ops/main.py", line 139, in _emit_charm_event
    event_to_emit.emit(*args, **kwargs)
  File "/var/lib/juju/agents/unit-postgresql-test-app-0/charm/venv/ops/framework.py", line 347, in emit
    framework._emit(event)
  File "/var/lib/juju/agents/unit-postgresql-test-app-0/charm/venv/ops/framework.py", line 853, in _emit
    self._reemit(event_path)
  File "/var/lib/juju/agents/unit-postgresql-test-app-0/charm/venv/ops/framework.py", line 943, in _reemit
    custom_handler(event)
  File "/var/lib/juju/agents/unit-postgresql-test-app-0/charm/./src/charm.py", line 289, in _on_clear_continuous_writes_action
    if self._connection_string is None:
  File "/var/lib/juju/agents/unit-postgresql-test-app-0/charm/./src/charm.py", line 259, in _connection_string
    data = list(self.first_database.fetch_relation_data().values())[0]
AttributeError: 'ApplicationCharm' object has no attribute 'first_database'
unit-postgresql-test-app-0: 01:46:34 ERROR unit.postgresql-test-app/0.juju-log Uncaught exception while in charm code:
Traceback (most recent call last):
  File "/var/lib/juju/agents/unit-postgresql-test-app-0/charm/./src/charm.py", line 538, in <module>
    main(ApplicationCharm)
  File "/var/lib/juju/agents/unit-postgresql-test-app-0/charm/venv/ops/main.py", line 553, in main
    manager.run()
  File "/var/lib/juju/agents/unit-postgresql-test-app-0/charm/venv/ops/main.py", line 529, in run
    self._emit()
  File "/var/lib/juju/agents/unit-postgresql-test-app-0/charm/venv/ops/main.py", line 518, in _emit
    _emit_charm_event(self.charm, self.dispatcher.event_name, self._juju_context)
  File "/var/lib/juju/agents/unit-postgresql-test-app-0/charm/venv/ops/main.py", line 139, in _emit_charm_event
    event_to_emit.emit(*args, **kwargs)
  File "/var/lib/juju/agents/unit-postgresql-test-app-0/charm/venv/ops/framework.py", line 347, in emit
    framework._emit(event)
  File "/var/lib/juju/agents/unit-postgresql-test-app-0/charm/venv/ops/framework.py", line 853, in _emit
    self._reemit(event_path)
  File "/var/lib/juju/agents/unit-postgresql-test-app-0/charm/venv/ops/framework.py", line 943, in _reemit
    custom_handler(event)
  File "/var/lib/juju/agents/unit-postgresql-test-app-0/charm/./src/charm.py", line 289, in _on_clear_continuous_writes_action
    if self._connection_string is None:
  File "/var/lib/juju/agents/unit-postgresql-test-app-0/charm/./src/charm.py", line 259, in _connection_string
    data = list(self.first_database.fetch_relation_data().values())[0]
AttributeError: 'ApplicationCharm' object has no attribute 'first_database'
unit-postgresql-test-app-0: 01:46:38 ERROR unit.postgresql-test-app/0.juju-log Uncaught exception while in charm code:
Traceback (most recent call last):
  File "/var/lib/juju/agents/unit-postgresql-test-app-0/charm/./src/charm.py", line 538, in <module>
    main(ApplicationCharm)
  File "/var/lib/juju/agents/unit-postgresql-test-app-0/charm/venv/ops/main.py", line 553, in main
    manager.run()
  File "/var/lib/juju/agents/unit-postgresql-test-app-0/charm/venv/ops/main.py", line 529, in run
    self._emit()
  File "/var/lib/juju/agents/unit-postgresql-test-app-0/charm/venv/ops/main.py", line 518, in _emit
    _emit_charm_event(self.charm, self.dispatcher.event_name, self._juju_context)
  File "/var/lib/juju/agents/unit-postgresql-test-app-0/charm/venv/ops/main.py", line 139, in _emit_charm_event
    event_to_emit.emit(*args, **kwargs)
  File "/var/lib/juju/agents/unit-postgresql-test-app-0/charm/venv/ops/framework.py", line 347, in emit
    framework._emit(event)
  File "/var/lib/juju/agents/unit-postgresql-test-app-0/charm/venv/ops/framework.py", line 853, in _emit
    self._reemit(event_path)
  File "/var/lib/juju/agents/unit-postgresql-test-app-0/charm/venv/ops/framework.py", line 943, in _reemit
    custom_handler(event)
  File "/var/lib/juju/agents/unit-postgresql-test-app-0/charm/./src/charm.py", line 289, in _on_clear_continuous_writes_action
    if self._connection_string is None:
  File "/var/lib/juju/agents/unit-postgresql-test-app-0/charm/./src/charm.py", line 259, in _connection_string
    data = list(self.first_database.fetch_relation_data().values())[0]
AttributeError: 'ApplicationCharm' object has no attribute 'first_database'
unit-postgresql-test-app-0: 01:46:42 ERROR unit.postgresql-test-app/0.juju-log Uncaught exception while in charm code:
Traceback (most recent call last):
  File "/var/lib/juju/agents/unit-postgresql-test-app-0/charm/./src/charm.py", line 538, in <module>
    main(ApplicationCharm)
  File "/var/lib/juju/agents/unit-postgresql-test-app-0/charm/venv/ops/main.py", line 553, in main
    manager.run()
  File "/var/lib/juju/agents/unit-postgresql-test-app-0/charm/venv/ops/main.py", line 529, in run
    self._emit()
  File "/var/lib/juju/agents/unit-postgresql-test-app-0/charm/venv/ops/main.py", line 518, in _emit
    _emit_charm_event(self.charm, self.dispatcher.event_name, self._juju_context)
  File "/var/lib/juju/agents/unit-postgresql-test-app-0/charm/venv/ops/main.py", line 139, in _emit_charm_event
    event_to_emit.emit(*args, **kwargs)
  File "/var/lib/juju/agents/unit-postgresql-test-app-0/charm/venv/ops/framework.py", line 347, in emit
    framework._emit(event)
  File "/var/lib/juju/agents/unit-postgresql-test-app-0/charm/venv/ops/framework.py", line 853, in _emit
    self._reemit(event_path)
  File "/var/lib/juju/agents/unit-postgresql-test-app-0/charm/venv/ops/framework.py", line 943, in _reemit
    custom_handler(event)
  File "/var/lib/juju/agents/unit-postgresql-test-app-0/charm/./src/charm.py", line 289, in _on_clear_continuous_writes_action
    if self._connection_string is None:
  File "/var/lib/juju/agents/unit-postgresql-test-app-0/charm/./src/charm.py", line 259, in _connection_string
    data = list(self.first_database.fetch_relation_data().values())[0]
AttributeError: 'ApplicationCharm' object has no attribute 'first_database'
unit-postgresql-test-app-0: 01:46:46 ERROR unit.postgresql-test-app/0.juju-log Uncaught exception while in charm code:
Traceback (most recent call last):
  File "/var/lib/juju/agents/unit-postgresql-test-app-0/charm/./src/charm.py", line 538, in <module>
    main(ApplicationCharm)
  File "/var/lib/juju/agents/unit-postgresql-test-app-0/charm/venv/ops/main.py", line 553, in main
    manager.run()
  File "/var/lib/juju/agents/unit-postgresql-test-app-0/charm/venv/ops/main.py", line 529, in run
    self._emit()
  File "/var/lib/juju/agents/unit-postgresql-test-app-0/charm/venv/ops/main.py", line 518, in _emit
    _emit_charm_event(self.charm, self.dispatcher.event_name, self._juju_context)
  File "/var/lib/juju/agents/unit-postgresql-test-app-0/charm/venv/ops/main.py", line 139, in _emit_charm_event
    event_to_emit.emit(*args, **kwargs)
  File "/var/lib/juju/agents/unit-postgresql-test-app-0/charm/venv/ops/framework.py", line 347, in emit
    framework._emit(event)
  File "/var/lib/juju/agents/unit-postgresql-test-app-0/charm/venv/ops/framework.py", line 853, in _emit
    self._reemit(event_path)
  File "/var/lib/juju/agents/unit-postgresql-test-app-0/charm/venv/ops/framework.py", line 943, in _reemit
    custom_handler(event)
  File "/var/lib/juju/agents/unit-postgresql-test-app-0/charm/./src/charm.py", line 289, in _on_clear_continuous_writes_action
    if self._connection_string is None:
  File "/var/lib/juju/agents/unit-postgresql-test-app-0/charm/./src/charm.py", line 259, in _connection_string
    data = list(self.first_database.fetch_relation_data().values())[0]
AttributeError: 'ApplicationCharm' object has no attribute 'first_database'
unit-postgresql-test-app-0: 01:46:50 ERROR unit.postgresql-test-app/0.juju-log Uncaught exception while in charm code:
Traceback (most recent call last):
  File "/var/lib/juju/agents/unit-postgresql-test-app-0/charm/./src/charm.py", line 538, in <module>
    main(ApplicationCharm)
  File "/var/lib/juju/agents/unit-postgresql-test-app-0/charm/venv/ops/main.py", line 553, in main
    manager.run()
  File "/var/lib/juju/agents/unit-postgresql-test-app-0/charm/venv/ops/main.py", line 529, in run
    self._emit()
  File "/var/lib/juju/agents/unit-postgresql-test-app-0/charm/venv/ops/main.py", line 518, in _emit
    _emit_charm_event(self.charm, self.dispatcher.event_name, self._juju_context)
  File "/var/lib/juju/agents/unit-postgresql-test-app-0/charm/venv/ops/main.py", line 139, in _emit_charm_event
    event_to_emit.emit(*args, **kwargs)
  File "/var/lib/juju/agents/unit-postgresql-test-app-0/charm/venv/ops/framework.py", line 347, in emit
    framework._emit(event)
  File "/var/lib/juju/agents/unit-postgresql-test-app-0/charm/venv/ops/framework.py", line 853, in _emit
    self._reemit(event_path)
  File "/var/lib/juju/agents/unit-postgresql-test-app-0/charm/venv/ops/framework.py", line 943, in _reemit
    custom_handler(event)
  File "/var/lib/juju/agents/unit-postgresql-test-app-0/charm/./src/charm.py", line 289, in _on_clear_continuous_writes_action
    if self._connection_string is None:
  File "/var/lib/juju/agents/unit-postgresql-test-app-0/charm/./src/charm.py", line 259, in _connection_string
    data = list(self.first_database.fetch_relation_data().values())[0]
AttributeError: 'ApplicationCharm' object has no attribute 'first_database'
unit-postgresql-test-app-0: 01:46:54 ERROR unit.postgresql-test-app/0.juju-log Uncaught exception while in charm code:
Traceback (most recent call last):
  File "/var/lib/juju/agents/unit-postgresql-test-app-0/charm/./src/charm.py", line 538, in <module>
    main(ApplicationCharm)
  File "/var/lib/juju/agents/unit-postgresql-test-app-0/charm/venv/ops/main.py", line 553, in main
    manager.run()
  File "/var/lib/juju/agents/unit-postgresql-test-app-0/charm/venv/ops/main.py", line 529, in run
    self._emit()
  File "/var/lib/juju/agents/unit-postgresql-test-app-0/charm/venv/ops/main.py", line 518, in _emit
    _emit_charm_event(self.charm, self.dispatcher.event_name, self._juju_context)
  File "/var/lib/juju/agents/unit-postgresql-test-app-0/charm/venv/ops/main.py", line 139, in _emit_charm_event
    event_to_emit.emit(*args, **kwargs)
  File "/var/lib/juju/agents/unit-postgresql-test-app-0/charm/venv/ops/framework.py", line 347, in emit
    framework._emit(event)
  File "/var/lib/juju/agents/unit-postgresql-test-app-0/charm/venv/ops/framework.py", line 853, in _emit
    self._reemit(event_path)
  File "/var/lib/juju/agents/unit-postgresql-test-app-0/charm/venv/ops/framework.py", line 943, in _reemit
    custom_handler(event)
  File "/var/lib/juju/agents/unit-postgresql-test-app-0/charm/./src/charm.py", line 289, in _on_clear_continuous_writes_action
    if self._connection_string is None:
  File "/var/lib/juju/agents/unit-postgresql-test-app-0/charm/./src/charm.py", line 259, in _connection_string
    data = list(self.first_database.fetch_relation_data().values())[0]
AttributeError: 'ApplicationCharm' object has no attribute 'first_database'
unit-postgresql-test-app-0: 01:46:58 ERROR unit.postgresql-test-app/0.juju-log Uncaught exception while in charm code:
Traceback (most recent call last):
  File "/var/lib/juju/agents/unit-postgresql-test-app-0/charm/./src/charm.py", line 538, in <module>
    main(ApplicationCharm)
  File "/var/lib/juju/agents/unit-postgresql-test-app-0/charm/venv/ops/main.py", line 553, in main
    manager.run()
  File "/var/lib/juju/agents/unit-postgresql-test-app-0/charm/venv/ops/main.py", line 529, in run
    self._emit()
  File "/var/lib/juju/agents/unit-postgresql-test-app-0/charm/venv/ops/main.py", line 518, in _emit
    _emit_charm_event(self.charm, self.dispatcher.event_name, self._juju_context)
  File "/var/lib/juju/agents/unit-postgresql-test-app-0/charm/venv/ops/main.py", line 139, in _emit_charm_event
    event_to_emit.emit(*args, **kwargs)
  File "/var/lib/juju/agents/unit-postgresql-test-app-0/charm/venv/ops/framework.py", line 347, in emit
    framework._emit(event)
  File "/var/lib/juju/agents/unit-postgresql-test-app-0/charm/venv/ops/framework.py", line 853, in _emit
    self._reemit(event_path)
  File "/var/lib/juju/agents/unit-postgresql-test-app-0/charm/venv/ops/framework.py", line 943, in _reemit
    custom_handler(event)
  File "/var/lib/juju/agents/unit-postgresql-test-app-0/charm/./src/charm.py", line 289, in _on_clear_continuous_writes_action
    if self._connection_string is None:
  File "/var/lib/juju/agents/unit-postgresql-test-app-0/charm/./src/charm.py", line 259, in _connection_string
    data = list(self.first_database.fetch_relation_data().values())[0]
AttributeError: 'ApplicationCharm' object has no attribute 'first_database'
unit-postgresql-test-app-0: 01:47:02 ERROR unit.postgresql-test-app/0.juju-log Uncaught exception while in charm code:
Traceback (most recent call last):
  File "/var/lib/juju/agents/unit-postgresql-test-app-0/charm/./src/charm.py", line 538, in <module>
    main(ApplicationCharm)
  File "/var/lib/juju/agents/unit-postgresql-test-app-0/charm/venv/ops/main.py", line 553, in main
    manager.run()
  File "/var/lib/juju/agents/unit-postgresql-test-app-0/charm/venv/ops/main.py", line 529, in run
    self._emit()
  File "/var/lib/juju/agents/unit-postgresql-test-app-0/charm/venv/ops/main.py", line 518, in _emit
    _emit_charm_event(self.charm, self.dispatcher.event_name, self._juju_context)
  File "/var/lib/juju/agents/unit-postgresql-test-app-0/charm/venv/ops/main.py", line 139, in _emit_charm_event
    event_to_emit.emit(*args, **kwargs)
  File "/var/lib/juju/agents/unit-postgresql-test-app-0/charm/venv/ops/framework.py", line 347, in emit
    framework._emit(event)
  File "/var/lib/juju/agents/unit-postgresql-test-app-0/charm/venv/ops/framework.py", line 853, in _emit
    self._reemit(event_path)
  File "/var/lib/juju/agents/unit-postgresql-test-app-0/charm/venv/ops/framework.py", line 943, in _reemit
    custom_handler(event)
  File "/var/lib/juju/agents/unit-postgresql-test-app-0/charm/./src/charm.py", line 289, in _on_clear_continuous_writes_action
    if self._connection_string is None:
  File "/var/lib/juju/agents/unit-postgresql-test-app-0/charm/./src/charm.py", line 259, in _connection_string
    data = list(self.first_database.fetch_relation_data().values())[0]
AttributeError: 'ApplicationCharm' object has no attribute 'first_database'
unit-postgresql-test-app-0: 01:47:06 ERROR unit.postgresql-test-app/0.juju-log Uncaught exception while in charm code:
Traceback (most recent call last):
  File "/var/lib/juju/agents/unit-postgresql-test-app-0/charm/./src/charm.py", line 538, in <module>
    main(ApplicationCharm)
  File "/var/lib/juju/agents/unit-postgresql-test-app-0/charm/venv/ops/main.py", line 553, in main
    manager.run()
  File "/var/lib/juju/agents/unit-postgresql-test-app-0/charm/venv/ops/main.py", line 529, in run
    self._emit()
  File "/var/lib/juju/agents/unit-postgresql-test-app-0/charm/venv/ops/main.py", line 518, in _emit
    _emit_charm_event(self.charm, self.dispatcher.event_name, self._juju_context)
  File "/var/lib/juju/agents/unit-postgresql-test-app-0/charm/venv/ops/main.py", line 139, in _emit_charm_event
    event_to_emit.emit(*args, **kwargs)
  File "/var/lib/juju/agents/unit-postgresql-test-app-0/charm/venv/ops/framework.py", line 347, in emit
    framework._emit(event)
  File "/var/lib/juju/agents/unit-postgresql-test-app-0/charm/venv/ops/framework.py", line 853, in _emit
    self._reemit(event_path)
  File "/var/lib/juju/agents/unit-postgresql-test-app-0/charm/venv/ops/framework.py", line 943, in _reemit
    custom_handler(event)
  File "/var/lib/juju/agents/unit-postgresql-test-app-0/charm/./src/charm.py", line 289, in _on_clear_continuous_writes_action
    if self._connection_string is None:
  File "/var/lib/juju/agents/unit-postgresql-test-app-0/charm/./src/charm.py", line 259, in _connection_string
    data = list(self.first_database.fetch_relation_data().values())[0]
AttributeError: 'ApplicationCharm' object has no attribute 'first_database'
unit-postgresql-test-app-0: 01:47:10 ERROR unit.postgresql-test-app/0.juju-log Uncaught exception while in charm code:
Traceback (most recent call last):
  File "/var/lib/juju/agents/unit-postgresql-test-app-0/charm/./src/charm.py", line 538, in <module>
    main(ApplicationCharm)
  File "/var/lib/juju/agents/unit-postgresql-test-app-0/charm/venv/ops/main.py", line 553, in main
    manager.run()
  File "/var/lib/juju/agents/unit-postgresql-test-app-0/charm/venv/ops/main.py", line 529, in run
    self._emit()
  File "/var/lib/juju/agents/unit-postgresql-test-app-0/charm/venv/ops/main.py", line 518, in _emit
    _emit_charm_event(self.charm, self.dispatcher.event_name, self._juju_context)
  File "/var/lib/juju/agents/unit-postgresql-test-app-0/charm/venv/ops/main.py", line 139, in _emit_charm_event
    event_to_emit.emit(*args, **kwargs)
  File "/var/lib/juju/agents/unit-postgresql-test-app-0/charm/venv/ops/framework.py", line 347, in emit
    framework._emit(event)
  File "/var/lib/juju/agents/unit-postgresql-test-app-0/charm/venv/ops/framework.py", line 853, in _emit
    self._reemit(event_path)
  File "/var/lib/juju/agents/unit-postgresql-test-app-0/charm/venv/ops/framework.py", line 943, in _reemit
    custom_handler(event)
  File "/var/lib/juju/agents/unit-postgresql-test-app-0/charm/./src/charm.py", line 289, in _on_clear_continuous_writes_action
    if self._connection_string is None:
  File "/var/lib/juju/agents/unit-postgresql-test-app-0/charm/./src/charm.py", line 259, in _connection_string
    data = list(self.first_database.fetch_relation_data().values())[0]
AttributeError: 'ApplicationCharm' object has no attribute 'first_database'
unit-postgresql-test-app-0: 01:47:14 ERROR unit.postgresql-test-app/0.juju-log Uncaught exception while in charm code:
Traceback (most recent call last):
  File "/var/lib/juju/agents/unit-postgresql-test-app-0/charm/./src/charm.py", line 538, in <module>
    main(ApplicationCharm)
  File "/var/lib/juju/agents/unit-postgresql-test-app-0/charm/venv/ops/main.py", line 553, in main
    manager.run()
  File "/var/lib/juju/agents/unit-postgresql-test-app-0/charm/venv/ops/main.py", line 529, in run
    self._emit()
  File "/var/lib/juju/agents/unit-postgresql-test-app-0/charm/venv/ops/main.py", line 518, in _emit
    _emit_charm_event(self.charm, self.dispatcher.event_name, self._juju_context)
  File "/var/lib/juju/agents/unit-postgresql-test-app-0/charm/venv/ops/main.py", line 139, in _emit_charm_event
    event_to_emit.emit(*args, **kwargs)
  File "/var/lib/juju/agents/unit-postgresql-test-app-0/charm/venv/ops/framework.py", line 347, in emit
    framework._emit(event)
  File "/var/lib/juju/agents/unit-postgresql-test-app-0/charm/venv/ops/framework.py", line 853, in _emit
    self._reemit(event_path)
  File "/var/lib/juju/agents/unit-postgresql-test-app-0/charm/venv/ops/framework.py", line 943, in _reemit
    custom_handler(event)
  File "/var/lib/juju/agents/unit-postgresql-test-app-0/charm/./src/charm.py", line 289, in _on_clear_continuous_writes_action
    if self._connection_string is None:
  File "/var/lib/juju/agents/unit-postgresql-test-app-0/charm/./src/charm.py", line 259, in _connection_string
    data = list(self.first_database.fetch_relation_data().values())[0]
AttributeError: 'ApplicationCharm' object has no attribute 'first_database'
unit-postgresql-test-app-0: 01:47:18 ERROR unit.postgresql-test-app/0.juju-log Uncaught exception while in charm code:
Traceback (most recent call last):
  File "/var/lib/juju/agents/unit-postgresql-test-app-0/charm/./src/charm.py", line 538, in <module>
    main(ApplicationCharm)
  File "/var/lib/juju/agents/unit-postgresql-test-app-0/charm/venv/ops/main.py", line 553, in main
    manager.run()
  File "/var/lib/juju/agents/unit-postgresql-test-app-0/charm/venv/ops/main.py", line 529, in run
    self._emit()
  File "/var/lib/juju/agents/unit-postgresql-test-app-0/charm/venv/ops/main.py", line 518, in _emit
    _emit_charm_event(self.charm, self.dispatcher.event_name, self._juju_context)
  File "/var/lib/juju/agents/unit-postgresql-test-app-0/charm/venv/ops/main.py", line 139, in _emit_charm_event
    event_to_emit.emit(*args, **kwargs)
  File "/var/lib/juju/agents/unit-postgresql-test-app-0/charm/venv/ops/framework.py", line 347, in emit
    framework._emit(event)
  File "/var/lib/juju/agents/unit-postgresql-test-app-0/charm/venv/ops/framework.py", line 853, in _emit
    self._reemit(event_path)
  File "/var/lib/juju/agents/unit-postgresql-test-app-0/charm/venv/ops/framework.py", line 943, in _reemit
    custom_handler(event)
  File "/var/lib/juju/agents/unit-postgresql-test-app-0/charm/./src/charm.py", line 289, in _on_clear_continuous_writes_action
    if self._connection_string is None:
  File "/var/lib/juju/agents/unit-postgresql-test-app-0/charm/./src/charm.py", line 259, in _connection_string
    data = list(self.first_database.fetch_relation_data().values())[0]
AttributeError: 'ApplicationCharm' object has no attribute 'first_database'
unit-postgresql-test-app-0: 01:47:22 ERROR unit.postgresql-test-app/0.juju-log Uncaught exception while in charm code:
Traceback (most recent call last):
  File "/var/lib/juju/agents/unit-postgresql-test-app-0/charm/./src/charm.py", line 538, in <module>
    main(ApplicationCharm)
  File "/var/lib/juju/agents/unit-postgresql-test-app-0/charm/venv/ops/main.py", line 553, in main
    manager.run()
  File "/var/lib/juju/agents/unit-postgresql-test-app-0/charm/venv/ops/main.py", line 529, in run
    self._emit()
  File "/var/lib/juju/agents/unit-postgresql-test-app-0/charm/venv/ops/main.py", line 518, in _emit
    _emit_charm_event(self.charm, self.dispatcher.event_name, self._juju_context)
  File "/var/lib/juju/agents/unit-postgresql-test-app-0/charm/venv/ops/main.py", line 139, in _emit_charm_event
    event_to_emit.emit(*args, **kwargs)
  File "/var/lib/juju/agents/unit-postgresql-test-app-0/charm/venv/ops/framework.py", line 347, in emit
    framework._emit(event)
  File "/var/lib/juju/agents/unit-postgresql-test-app-0/charm/venv/ops/framework.py", line 853, in _emit
    self._reemit(event_path)
  File "/var/lib/juju/agents/unit-postgresql-test-app-0/charm/venv/ops/framework.py", line 943, in _reemit
    custom_handler(event)
  File "/var/lib/juju/agents/unit-postgresql-test-app-0/charm/./src/charm.py", line 289, in _on_clear_continuous_writes_action
    if self._connection_string is None:
  File "/var/lib/juju/agents/unit-postgresql-test-app-0/charm/./src/charm.py", line 259, in _connection_string
    data = list(self.first_database.fetch_relation_data().values())[0]
AttributeError: 'ApplicationCharm' object has no attribute 'first_database'
unit-postgresql-test-app-0: 01:47:26 ERROR unit.postgresql-test-app/0.juju-log Uncaught exception while in charm code:
Traceback (most recent call last):
  File "/var/lib/juju/agents/unit-postgresql-test-app-0/charm/./src/charm.py", line 538, in <module>
    main(ApplicationCharm)
  File "/var/lib/juju/agents/unit-postgresql-test-app-0/charm/venv/ops/main.py", line 553, in main
    manager.run()
  File "/var/lib/juju/agents/unit-postgresql-test-app-0/charm/venv/ops/main.py", line 529, in run
    self._emit()
  File "/var/lib/juju/agents/unit-postgresql-test-app-0/charm/venv/ops/main.py", line 518, in _emit
    _emit_charm_event(self.charm, self.dispatcher.event_name, self._juju_context)
  File "/var/lib/juju/agents/unit-postgresql-test-app-0/charm/venv/ops/main.py", line 139, in _emit_charm_event
    event_to_emit.emit(*args, **kwargs)
  File "/var/lib/juju/agents/unit-postgresql-test-app-0/charm/venv/ops/framework.py", line 347, in emit
    framework._emit(event)
  File "/var/lib/juju/agents/unit-postgresql-test-app-0/charm/venv/ops/framework.py", line 853, in _emit
    self._reemit(event_path)
  File "/var/lib/juju/agents/unit-postgresql-test-app-0/charm/venv/ops/framework.py", line 943, in _reemit
    custom_handler(event)
  File "/var/lib/juju/agents/unit-postgresql-test-app-0/charm/./src/charm.py", line 289, in _on_clear_continuous_writes_action
    if self._connection_string is None:
  File "/var/lib/juju/agents/unit-postgresql-test-app-0/charm/./src/charm.py", line 259, in _connection_string
    data = list(self.first_database.fetch_relation_data().values())[0]
AttributeError: 'ApplicationCharm' object has no attribute 'first_database'
unit-postgresql-test-app-0: 01:47:30 ERROR unit.postgresql-test-app/0.juju-log Uncaught exception while in charm code:
Traceback (most recent call last):
  File "/var/lib/juju/agents/unit-postgresql-test-app-0/charm/./src/charm.py", line 538, in <module>
    main(ApplicationCharm)
  File "/var/lib/juju/agents/unit-postgresql-test-app-0/charm/venv/ops/main.py", line 553, in main
    manager.run()
  File "/var/lib/juju/agents/unit-postgresql-test-app-0/charm/venv/ops/main.py", line 529, in run
    self._emit()
  File "/var/lib/juju/agents/unit-postgresql-test-app-0/charm/venv/ops/main.py", line 518, in _emit
    _emit_charm_event(self.charm, self.dispatcher.event_name, self._juju_context)
  File "/var/lib/juju/agents/unit-postgresql-test-app-0/charm/venv/ops/main.py", line 139, in _emit_charm_event
    event_to_emit.emit(*args, **kwargs)
  File "/var/lib/juju/agents/unit-postgresql-test-app-0/charm/venv/ops/framework.py", line 347, in emit
    framework._emit(event)
  File "/var/lib/juju/agents/unit-postgresql-test-app-0/charm/venv/ops/framework.py", line 853, in _emit
    self._reemit(event_path)
  File "/var/lib/juju/agents/unit-postgresql-test-app-0/charm/venv/ops/framework.py", line 943, in _reemit
    custom_handler(event)
  File "/var/lib/juju/agents/unit-postgresql-test-app-0/charm/./src/charm.py", line 289, in _on_clear_continuous_writes_action
    if self._connection_string is None:
  File "/var/lib/juju/agents/unit-postgresql-test-app-0/charm/./src/charm.py", line 259, in _connection_string
    data = list(self.first_database.fetch_relation_data().values())[0]
AttributeError: 'ApplicationCharm' object has no attribute 'first_database'
unit-postgresql-test-app-0: 01:47:34 ERROR unit.postgresql-test-app/0.juju-log Uncaught exception while in charm code:
Traceback (most recent call last):
  File "/var/lib/juju/agents/unit-postgresql-test-app-0/charm/./src/charm.py", line 538, in <module>
    main(ApplicationCharm)
  File "/var/lib/juju/agents/unit-postgresql-test-app-0/charm/venv/ops/main.py", line 553, in main
    manager.run()
  File "/var/lib/juju/agents/unit-postgresql-test-app-0/charm/venv/ops/main.py", line 529, in run
    self._emit()
  File "/var/lib/juju/agents/unit-postgresql-test-app-0/charm/venv/ops/main.py", line 518, in _emit
    _emit_charm_event(self.charm, self.dispatcher.event_name, self._juju_context)
  File "/var/lib/juju/agents/unit-postgresql-test-app-0/charm/venv/ops/main.py", line 139, in _emit_charm_event
    event_to_emit.emit(*args, **kwargs)
  File "/var/lib/juju/agents/unit-postgresql-test-app-0/charm/venv/ops/framework.py", line 347, in emit
    framework._emit(event)
  File "/var/lib/juju/agents/unit-postgresql-test-app-0/charm/venv/ops/framework.py", line 853, in _emit
    self._reemit(event_path)
  File "/var/lib/juju/agents/unit-postgresql-test-app-0/charm/venv/ops/framework.py", line 943, in _reemit
    custom_handler(event)
  File "/var/lib/juju/agents/unit-postgresql-test-app-0/charm/./src/charm.py", line 289, in _on_clear_continuous_writes_action
    if self._connection_string is None:
  File "/var/lib/juju/agents/unit-postgresql-test-app-0/charm/./src/charm.py", line 259, in _connection_string
    data = list(self.first_database.fetch_relation_data().values())[0]
AttributeError: 'ApplicationCharm' object has no attribute 'first_database'
unit-postgresql-test-app-0: 01:47:38 ERROR unit.postgresql-test-app/0.juju-log Uncaught exception while in charm code:
Traceback (most recent call last):
  File "/var/lib/juju/agents/unit-postgresql-test-app-0/charm/./src/charm.py", line 538, in <module>
    main(ApplicationCharm)
  File "/var/lib/juju/agents/unit-postgresql-test-app-0/charm/venv/ops/main.py", line 553, in main
    manager.run()
  File "/var/lib/juju/agents/unit-postgresql-test-app-0/charm/venv/ops/main.py", line 529, in run
    self._emit()
  File "/var/lib/juju/agents/unit-postgresql-test-app-0/charm/venv/ops/main.py", line 518, in _emit
    _emit_charm_event(self.charm, self.dispatcher.event_name, self._juju_context)
  File "/var/lib/juju/agents/unit-postgresql-test-app-0/charm/venv/ops/main.py", line 139, in _emit_charm_event
    event_to_emit.emit(*args, **kwargs)
  File "/var/lib/juju/agents/unit-postgresql-test-app-0/charm/venv/ops/framework.py", line 347, in emit
    framework._emit(event)
  File "/var/lib/juju/agents/unit-postgresql-test-app-0/charm/venv/ops/framework.py", line 853, in _emit
    self._reemit(event_path)
  File "/var/lib/juju/agents/unit-postgresql-test-app-0/charm/venv/ops/framework.py", line 943, in _reemit
    custom_handler(event)
  File "/var/lib/juju/agents/unit-postgresql-test-app-0/charm/./src/charm.py", line 289, in _on_clear_continuous_writes_action
    if self._connection_string is None:
  File "/var/lib/juju/agents/unit-postgresql-test-app-0/charm/./src/charm.py", line 259, in _connection_string
    data = list(self.first_database.fetch_relation_data().values())[0]
AttributeError: 'ApplicationCharm' object has no attribute 'first_database'
unit-postgresql-test-app-0: 01:47:42 ERROR unit.postgresql-test-app/0.juju-log Uncaught exception while in charm code:
Traceback (most recent call last):
  File "/var/lib/juju/agents/unit-postgresql-test-app-0/charm/./src/charm.py", line 538, in <module>
    main(ApplicationCharm)
  File "/var/lib/juju/agents/unit-postgresql-test-app-0/charm/venv/ops/main.py", line 553, in main
    manager.run()
  File "/var/lib/juju/agents/unit-postgresql-test-app-0/charm/venv/ops/main.py", line 529, in run
    self._emit()
  File "/var/lib/juju/agents/unit-postgresql-test-app-0/charm/venv/ops/main.py", line 518, in _emit
    _emit_charm_event(self.charm, self.dispatcher.event_name, self._juju_context)
  File "/var/lib/juju/agents/unit-postgresql-test-app-0/charm/venv/ops/main.py", line 139, in _emit_charm_event
    event_to_emit.emit(*args, **kwargs)
  File "/var/lib/juju/agents/unit-postgresql-test-app-0/charm/venv/ops/framework.py", line 347, in emit
    framework._emit(event)
  File "/var/lib/juju/agents/unit-postgresql-test-app-0/charm/venv/ops/framework.py", line 853, in _emit
    self._reemit(event_path)
  File "/var/lib/juju/agents/unit-postgresql-test-app-0/charm/venv/ops/framework.py", line 943, in _reemit
    custom_handler(event)
  File "/var/lib/juju/agents/unit-postgresql-test-app-0/charm/./src/charm.py", line 289, in _on_clear_continuous_writes_action
    if self._connection_string is None:
  File "/var/lib/juju/agents/unit-postgresql-test-app-0/charm/./src/charm.py", line 259, in _connection_string
    data = list(self.first_database.fetch_relation_data().values())[0]
AttributeError: 'ApplicationCharm' object has no attribute 'first_database'
unit-postgresql-test-app-0: 01:47:46 ERROR unit.postgresql-test-app/0.juju-log Uncaught exception while in charm code:
Traceback (most recent call last):
  File "/var/lib/juju/agents/unit-postgresql-test-app-0/charm/./src/charm.py", line 538, in <module>
    main(ApplicationCharm)
  File "/var/lib/juju/agents/unit-postgresql-test-app-0/charm/venv/ops/main.py", line 553, in main
    manager.run()
  File "/var/lib/juju/agents/unit-postgresql-test-app-0/charm/venv/ops/main.py", line 529, in run
    self._emit()
  File "/var/lib/juju/agents/unit-postgresql-test-app-0/charm/venv/ops/main.py", line 518, in _emit
    _emit_charm_event(self.charm, self.dispatcher.event_name, self._juju_context)
  File "/var/lib/juju/agents/unit-postgresql-test-app-0/charm/venv/ops/main.py", line 139, in _emit_charm_event
    event_to_emit.emit(*args, **kwargs)
  File "/var/lib/juju/agents/unit-postgresql-test-app-0/charm/venv/ops/framework.py", line 347, in emit
    framework._emit(event)
  File "/var/lib/juju/agents/unit-postgresql-test-app-0/charm/venv/ops/framework.py", line 853, in _emit
    self._reemit(event_path)
  File "/var/lib/juju/agents/unit-postgresql-test-app-0/charm/venv/ops/framework.py", line 943, in _reemit
    custom_handler(event)
  File "/var/lib/juju/agents/unit-postgresql-test-app-0/charm/./src/charm.py", line 289, in _on_clear_continuous_writes_action
    if self._connection_string is None:
  File "/var/lib/juju/agents/unit-postgresql-test-app-0/charm/./src/charm.py", line 259, in _connection_string
    data = list(self.first_database.fetch_relation_data().values())[0]
AttributeError: 'ApplicationCharm' object has no attribute 'first_database'
unit-postgresql-test-app-0: 01:47:51 ERROR unit.postgresql-test-app/0.juju-log Uncaught exception while in charm code:
Traceback (most recent call last):
  File "/var/lib/juju/agents/unit-postgresql-test-app-0/charm/./src/charm.py", line 538, in <module>
    main(ApplicationCharm)
  File "/var/lib/juju/agents/unit-postgresql-test-app-0/charm/venv/ops/main.py", line 553, in main
    manager.run()
  File "/var/lib/juju/agents/unit-postgresql-test-app-0/charm/venv/ops/main.py", line 529, in run
    self._emit()
  File "/var/lib/juju/agents/unit-postgresql-test-app-0/charm/venv/ops/main.py", line 518, in _emit
    _emit_charm_event(self.charm, self.dispatcher.event_name, self._juju_context)
  File "/var/lib/juju/agents/unit-postgresql-test-app-0/charm/venv/ops/main.py", line 139, in _emit_charm_event
    event_to_emit.emit(*args, **kwargs)
  File "/var/lib/juju/agents/unit-postgresql-test-app-0/charm/venv/ops/framework.py", line 347, in emit
    framework._emit(event)
  File "/var/lib/juju/agents/unit-postgresql-test-app-0/charm/venv/ops/framework.py", line 853, in _emit
    self._reemit(event_path)
  File "/var/lib/juju/agents/unit-postgresql-test-app-0/charm/venv/ops/framework.py", line 943, in _reemit
    custom_handler(event)
  File "/var/lib/juju/agents/unit-postgresql-test-app-0/charm/./src/charm.py", line 289, in _on_clear_continuous_writes_action
    if self._connection_string is None:
  File "/var/lib/juju/agents/unit-postgresql-test-app-0/charm/./src/charm.py", line 259, in _connection_string
    data = list(self.first_database.fetch_relation_data().values())[0]
AttributeError: 'ApplicationCharm' object has no attribute 'first_database'
unit-postgresql-test-app-0: 01:47:55 ERROR unit.postgresql-test-app/0.juju-log Uncaught exception while in charm code:
Traceback (most recent call last):
  File "/var/lib/juju/agents/unit-postgresql-test-app-0/charm/./src/charm.py", line 538, in <module>
    main(ApplicationCharm)
  File "/var/lib/juju/agents/unit-postgresql-test-app-0/charm/venv/ops/main.py", line 553, in main
    manager.run()
  File "/var/lib/juju/agents/unit-postgresql-test-app-0/charm/venv/ops/main.py", line 529, in run
    self._emit()
  File "/var/lib/juju/agents/unit-postgresql-test-app-0/charm/venv/ops/main.py", line 518, in _emit
    _emit_charm_event(self.charm, self.dispatcher.event_name, self._juju_context)
  File "/var/lib/juju/agents/unit-postgresql-test-app-0/charm/venv/ops/main.py", line 139, in _emit_charm_event
    event_to_emit.emit(*args, **kwargs)
  File "/var/lib/juju/agents/unit-postgresql-test-app-0/charm/venv/ops/framework.py", line 347, in emit
    framework._emit(event)
  File "/var/lib/juju/agents/unit-postgresql-test-app-0/charm/venv/ops/framework.py", line 853, in _emit
    self._reemit(event_path)
  File "/var/lib/juju/agents/unit-postgresql-test-app-0/charm/venv/ops/framework.py", line 943, in _reemit
    custom_handler(event)
  File "/var/lib/juju/agents/unit-postgresql-test-app-0/charm/./src/charm.py", line 289, in _on_clear_continuous_writes_action
    if self._connection_string is None:
  File "/var/lib/juju/agents/unit-postgresql-test-app-0/charm/./src/charm.py", line 259, in _connection_string
    data = list(self.first_database.fetch_relation_data().values())[0]
AttributeError: 'ApplicationCharm' object has no attribute 'first_database'
unit-postgresql-test-app-0: 01:47:59 ERROR unit.postgresql-test-app/0.juju-log Uncaught exception while in charm code:
Traceback (most recent call last):
  File "/var/lib/juju/agents/unit-postgresql-test-app-0/charm/./src/charm.py", line 538, in <module>
    main(ApplicationCharm)
  File "/var/lib/juju/agents/unit-postgresql-test-app-0/charm/venv/ops/main.py", line 553, in main
    manager.run()
  File "/var/lib/juju/agents/unit-postgresql-test-app-0/charm/venv/ops/main.py", line 529, in run
    self._emit()
  File "/var/lib/juju/agents/unit-postgresql-test-app-0/charm/venv/ops/main.py", line 518, in _emit
    _emit_charm_event(self.charm, self.dispatcher.event_name, self._juju_context)
  File "/var/lib/juju/agents/unit-postgresql-test-app-0/charm/venv/ops/main.py", line 139, in _emit_charm_event
    event_to_emit.emit(*args, **kwargs)
  File "/var/lib/juju/agents/unit-postgresql-test-app-0/charm/venv/ops/framework.py", line 347, in emit
    framework._emit(event)
  File "/var/lib/juju/agents/unit-postgresql-test-app-0/charm/venv/ops/framework.py", line 853, in _emit
    self._reemit(event_path)
  File "/var/lib/juju/agents/unit-postgresql-test-app-0/charm/venv/ops/framework.py", line 943, in _reemit
    custom_handler(event)
  File "/var/lib/juju/agents/unit-postgresql-test-app-0/charm/./src/charm.py", line 289, in _on_clear_continuous_writes_action
    if self._connection_string is None:
  File "/var/lib/juju/agents/unit-postgresql-test-app-0/charm/./src/charm.py", line 259, in _connection_string
    data = list(self.first_database.fetch_relation_data().values())[0]
AttributeError: 'ApplicationCharm' object has no attribute 'first_database'
unit-postgresql-test-app-0: 01:48:03 ERROR unit.postgresql-test-app/0.juju-log Uncaught exception while in charm code:
Traceback (most recent call last):
  File "/var/lib/juju/agents/unit-postgresql-test-app-0/charm/./src/charm.py", line 538, in <module>
    main(ApplicationCharm)
  File "/var/lib/juju/agents/unit-postgresql-test-app-0/charm/venv/ops/main.py", line 553, in main
    manager.run()
  File "/var/lib/juju/agents/unit-postgresql-test-app-0/charm/venv/ops/main.py", line 529, in run
    self._emit()
  File "/var/lib/juju/agents/unit-postgresql-test-app-0/charm/venv/ops/main.py", line 518, in _emit
    _emit_charm_event(self.charm, self.dispatcher.event_name, self._juju_context)
  File "/var/lib/juju/agents/unit-postgresql-test-app-0/charm/venv/ops/main.py", line 139, in _emit_charm_event
    event_to_emit.emit(*args, **kwargs)
  File "/var/lib/juju/agents/unit-postgresql-test-app-0/charm/venv/ops/framework.py", line 347, in emit
    framework._emit(event)
  File "/var/lib/juju/agents/unit-postgresql-test-app-0/charm/venv/ops/framework.py", line 853, in _emit
    self._reemit(event_path)
  File "/var/lib/juju/agents/unit-postgresql-test-app-0/charm/venv/ops/framework.py", line 943, in _reemit
    custom_handler(event)
  File "/var/lib/juju/agents/unit-postgresql-test-app-0/charm/./src/charm.py", line 289, in _on_clear_continuous_writes_action
    if self._connection_string is None:
  File "/var/lib/juju/agents/unit-postgresql-test-app-0/charm/./src/charm.py", line 259, in _connection_string
    data = list(self.first_database.fetch_relation_data().values())[0]
AttributeError: 'ApplicationCharm' object has no attribute 'first_database'
unit-postgresql-test-app-0: 01:48:07 ERROR unit.postgresql-test-app/0.juju-log Uncaught exception while in charm code:
Traceback (most recent call last):
  File "/var/lib/juju/agents/unit-postgresql-test-app-0/charm/./src/charm.py", line 538, in <module>
    main(ApplicationCharm)
  File "/var/lib/juju/agents/unit-postgresql-test-app-0/charm/venv/ops/main.py", line 553, in main
    manager.run()
  File "/var/lib/juju/agents/unit-postgresql-test-app-0/charm/venv/ops/main.py", line 529, in run
    self._emit()
  File "/var/lib/juju/agents/unit-postgresql-test-app-0/charm/venv/ops/main.py", line 518, in _emit
    _emit_charm_event(self.charm, self.dispatcher.event_name, self._juju_context)
  File "/var/lib/juju/agents/unit-postgresql-test-app-0/charm/venv/ops/main.py", line 139, in _emit_charm_event
    event_to_emit.emit(*args, **kwargs)
  File "/var/lib/juju/agents/unit-postgresql-test-app-0/charm/venv/ops/framework.py", line 347, in emit
    framework._emit(event)
  File "/var/lib/juju/agents/unit-postgresql-test-app-0/charm/venv/ops/framework.py", line 853, in _emit
    self._reemit(event_path)
  File "/var/lib/juju/agents/unit-postgresql-test-app-0/charm/venv/ops/framework.py", line 943, in _reemit
    custom_handler(event)
  File "/var/lib/juju/agents/unit-postgresql-test-app-0/charm/./src/charm.py", line 289, in _on_clear_continuous_writes_action
    if self._connection_string is None:
  File "/var/lib/juju/agents/unit-postgresql-test-app-0/charm/./src/charm.py", line 259, in _connection_string
    data = list(self.first_database.fetch_relation_data().values())[0]
AttributeError: 'ApplicationCharm' object has no attribute 'first_database'
unit-postgresql-test-app-0: 01:48:11 ERROR unit.postgresql-test-app/0.juju-log Uncaught exception while in charm code:
Traceback (most recent call last):
  File "/var/lib/juju/agents/unit-postgresql-test-app-0/charm/./src/charm.py", line 538, in <module>
    main(ApplicationCharm)
  File "/var/lib/juju/agents/unit-postgresql-test-app-0/charm/venv/ops/main.py", line 553, in main
    manager.run()
  File "/var/lib/juju/agents/unit-postgresql-test-app-0/charm/venv/ops/main.py", line 529, in run
    self._emit()
  File "/var/lib/juju/agents/unit-postgresql-test-app-0/charm/venv/ops/main.py", line 518, in _emit
    _emit_charm_event(self.charm, self.dispatcher.event_name, self._juju_context)
  File "/var/lib/juju/agents/unit-postgresql-test-app-0/charm/venv/ops/main.py", line 139, in _emit_charm_event
    event_to_emit.emit(*args, **kwargs)
  File "/var/lib/juju/agents/unit-postgresql-test-app-0/charm/venv/ops/framework.py", line 347, in emit
    framework._emit(event)
  File "/var/lib/juju/agents/unit-postgresql-test-app-0/charm/venv/ops/framework.py", line 853, in _emit
    self._reemit(event_path)
  File "/var/lib/juju/agents/unit-postgresql-test-app-0/charm/venv/ops/framework.py", line 943, in _reemit
    custom_handler(event)
  File "/var/lib/juju/agents/unit-postgresql-test-app-0/charm/./src/charm.py", line 289, in _on_clear_continuous_writes_action
    if self._connection_string is None:
  File "/var/lib/juju/agents/unit-postgresql-test-app-0/charm/./src/charm.py", line 259, in _connection_string
    data = list(self.first_database.fetch_relation_data().values())[0]
AttributeError: 'ApplicationCharm' object has no attribute 'first_database'
unit-postgresql-test-app-0: 01:48:15 ERROR unit.postgresql-test-app/0.juju-log Uncaught exception while in charm code:
Traceback (most recent call last):
  File "/var/lib/juju/agents/unit-postgresql-test-app-0/charm/./src/charm.py", line 538, in <module>
    main(ApplicationCharm)
  File "/var/lib/juju/agents/unit-postgresql-test-app-0/charm/venv/ops/main.py", line 553, in main
    manager.run()
  File "/var/lib/juju/agents/unit-postgresql-test-app-0/charm/venv/ops/main.py", line 529, in run
    self._emit()
  File "/var/lib/juju/agents/unit-postgresql-test-app-0/charm/venv/ops/main.py", line 518, in _emit
    _emit_charm_event(self.charm, self.dispatcher.event_name, self._juju_context)
  File "/var/lib/juju/agents/unit-postgresql-test-app-0/charm/venv/ops/main.py", line 139, in _emit_charm_event
    event_to_emit.emit(*args, **kwargs)
  File "/var/lib/juju/agents/unit-postgresql-test-app-0/charm/venv/ops/framework.py", line 347, in emit
    framework._emit(event)
  File "/var/lib/juju/agents/unit-postgresql-test-app-0/charm/venv/ops/framework.py", line 853, in _emit
    self._reemit(event_path)
  File "/var/lib/juju/agents/unit-postgresql-test-app-0/charm/venv/ops/framework.py", line 943, in _reemit
    custom_handler(event)
  File "/var/lib/juju/agents/unit-postgresql-test-app-0/charm/./src/charm.py", line 289, in _on_clear_continuous_writes_action
    if self._connection_string is None:
  File "/var/lib/juju/agents/unit-postgresql-test-app-0/charm/./src/charm.py", line 259, in _connection_string
    data = list(self.first_database.fetch_relation_data().values())[0]
AttributeError: 'ApplicationCharm' object has no attribute 'first_database'
unit-postgresql-test-app-0: 01:48:19 ERROR unit.postgresql-test-app/0.juju-log Uncaught exception while in charm code:
Traceback (most recent call last):
  File "/var/lib/juju/agents/unit-postgresql-test-app-0/charm/./src/charm.py", line 538, in <module>
    main(ApplicationCharm)
  File "/var/lib/juju/agents/unit-postgresql-test-app-0/charm/venv/ops/main.py", line 553, in main
    manager.run()
  File "/var/lib/juju/agents/unit-postgresql-test-app-0/charm/venv/ops/main.py", line 529, in run
    self._emit()
  File "/var/lib/juju/agents/unit-postgresql-test-app-0/charm/venv/ops/main.py", line 518, in _emit
    _emit_charm_event(self.charm, self.dispatcher.event_name, self._juju_context)
  File "/var/lib/juju/agents/unit-postgresql-test-app-0/charm/venv/ops/main.py", line 139, in _emit_charm_event
    event_to_emit.emit(*args, **kwargs)
  File "/var/lib/juju/agents/unit-postgresql-test-app-0/charm/venv/ops/framework.py", line 347, in emit
    framework._emit(event)
  File "/var/lib/juju/agents/unit-postgresql-test-app-0/charm/venv/ops/framework.py", line 853, in _emit
    self._reemit(event_path)
  File "/var/lib/juju/agents/unit-postgresql-test-app-0/charm/venv/ops/framework.py", line 943, in _reemit
    custom_handler(event)
  File "/var/lib/juju/agents/unit-postgresql-test-app-0/charm/./src/charm.py", line 289, in _on_clear_continuous_writes_action
    if self._connection_string is None:
  File "/var/lib/juju/agents/unit-postgresql-test-app-0/charm/./src/charm.py", line 259, in _connection_string
    data = list(self.first_database.fetch_relation_data().values())[0]
AttributeError: 'ApplicationCharm' object has no attribute 'first_database'
unit-postgresql-test-app-0: 01:48:23 ERROR unit.postgresql-test-app/0.juju-log Uncaught exception while in charm code:
Traceback (most recent call last):
  File "/var/lib/juju/agents/unit-postgresql-test-app-0/charm/./src/charm.py", line 538, in <module>
    main(ApplicationCharm)
  File "/var/lib/juju/agents/unit-postgresql-test-app-0/charm/venv/ops/main.py", line 553, in main
    manager.run()
  File "/var/lib/juju/agents/unit-postgresql-test-app-0/charm/venv/ops/main.py", line 529, in run
    self._emit()
  File "/var/lib/juju/agents/unit-postgresql-test-app-0/charm/venv/ops/main.py", line 518, in _emit
    _emit_charm_event(self.charm, self.dispatcher.event_name, self._juju_context)
  File "/var/lib/juju/agents/unit-postgresql-test-app-0/charm/venv/ops/main.py", line 139, in _emit_charm_event
    event_to_emit.emit(*args, **kwargs)
  File "/var/lib/juju/agents/unit-postgresql-test-app-0/charm/venv/ops/framework.py", line 347, in emit
    framework._emit(event)
  File "/var/lib/juju/agents/unit-postgresql-test-app-0/charm/venv/ops/framework.py", line 853, in _emit
    self._reemit(event_path)
  File "/var/lib/juju/agents/unit-postgresql-test-app-0/charm/venv/ops/framework.py", line 943, in _reemit
    custom_handler(event)
  File "/var/lib/juju/agents/unit-postgresql-test-app-0/charm/./src/charm.py", line 289, in _on_clear_continuous_writes_action
    if self._connection_string is None:
  File "/var/lib/juju/agents/unit-postgresql-test-app-0/charm/./src/charm.py", line 259, in _connection_string
    data = list(self.first_database.fetch_relation_data().values())[0]
AttributeError: 'ApplicationCharm' object has no attribute 'first_database'
unit-postgresql-test-app-0: 01:48:27 ERROR unit.postgresql-test-app/0.juju-log Uncaught exception while in charm code:
Traceback (most recent call last):
  File "/var/lib/juju/agents/unit-postgresql-test-app-0/charm/./src/charm.py", line 538, in <module>
    main(ApplicationCharm)
  File "/var/lib/juju/agents/unit-postgresql-test-app-0/charm/venv/ops/main.py", line 553, in main
    manager.run()
  File "/var/lib/juju/agents/unit-postgresql-test-app-0/charm/venv/ops/main.py", line 529, in run
    self._emit()
  File "/var/lib/juju/agents/unit-postgresql-test-app-0/charm/venv/ops/main.py", line 518, in _emit
    _emit_charm_event(self.charm, self.dispatcher.event_name, self._juju_context)
  File "/var/lib/juju/agents/unit-postgresql-test-app-0/charm/venv/ops/main.py", line 139, in _emit_charm_event
    event_to_emit.emit(*args, **kwargs)
  File "/var/lib/juju/agents/unit-postgresql-test-app-0/charm/venv/ops/framework.py", line 347, in emit
    framework._emit(event)
  File "/var/lib/juju/agents/unit-postgresql-test-app-0/charm/venv/ops/framework.py", line 853, in _emit
    self._reemit(event_path)
  File "/var/lib/juju/agents/unit-postgresql-test-app-0/charm/venv/ops/framework.py", line 943, in _reemit
    custom_handler(event)
  File "/var/lib/juju/agents/unit-postgresql-test-app-0/charm/./src/charm.py", line 289, in _on_clear_continuous_writes_action
    if self._connection_string is None:
  File "/var/lib/juju/agents/unit-postgresql-test-app-0/charm/./src/charm.py", line 259, in _connection_string
    data = list(self.first_database.fetch_relation_data().values())[0]
AttributeError: 'ApplicationCharm' object has no attribute 'first_database'

[32mINFO    [0m pytest_operator.plugin:plugin.py:947 Forgetting model main...