[32mINFO    [0m pytest_operator.plugin:plugin.py:734 Connecting to existing model microk8s-localhost:test on unspecified cloud
[32mINFO    [0m juju.model:model.py:2098 Deploying local:jammy/postgresql-k8s-0
[32mINFO    [0m juju.model:model.py:2098 Deploying ch:amd64/jammy/postgresql-test-app-215
[32mINFO    [0m juju.model:model.py:2972 Waiting for model:
  postgresql-k8s/0 [allocating] waiting: installing agent
  postgresql-k8s/1 [allocating] waiting: installing agent
  postgresql-k8s/2 [allocating] waiting: installing agent
  postgresql-test-app/0 [allocating] waiting: installing agent
[32mINFO    [0m juju.model:model.py:2972 Waiting for model:
  postgresql-k8s/0 [executing] maintenance: installing charm software
  postgresql-k8s/1 [executing] maintenance: installing charm software
  postgresql-k8s/2 [executing] maintenance: installing charm software
  postgresql-test-app/0 [idle] active: 
[32mINFO    [0m juju.model:model.py:2972 Waiting for model:
  postgresql-k8s/0 [executing] unknown: 
  postgresql-k8s/1 [executing] waiting: awaiting for cluster to start
  postgresql-k8s/2 [executing] unknown: 
[32mINFO    [0m juju.model:model.py:2972 Waiting for model:
  postgresql-k8s/0 [executing] unknown: 
  postgresql-k8s/1 [executing] waiting: awaiting for cluster to start
  postgresql-k8s/2 [executing] unknown: 
[32mINFO    [0m juju.model:model.py:2972 Waiting for model:
  postgresql-k8s/0 [idle] unknown: 
  postgresql-k8s/1 [executing] waiting: awaiting for cluster to start
  postgresql-k8s/2 [idle] unknown: 
[32mINFO    [0m juju.model:model.py:2972 Waiting for model:
  postgresql-k8s/0 [idle] unknown: 
  postgresql-k8s/1 [executing] waiting: awaiting for cluster to start
  postgresql-k8s/2 [idle] unknown: 
[32mINFO    [0m juju.model:model.py:2972 Waiting for model:
  postgresql-k8s/0 [idle] unknown: 
  postgresql-k8s/1 [executing] waiting: awaiting for cluster to start
  postgresql-k8s/2 [idle] unknown: 
[32mINFO    [0m juju.model:model.py:2972 Waiting for model:
  postgresql-k8s/0 [idle] unknown: 
  postgresql-k8s/1 [executing] waiting: awaiting for cluster to start
  postgresql-k8s/2 [idle] unknown: 
[32mINFO    [0m juju.model:model.py:2972 Waiting for model:
  postgresql-k8s/0 [idle] unknown: 
  postgresql-k8s/1 [executing] waiting: awaiting for primary endpoint to be ready
  postgresql-k8s/2 [idle] unknown: 
[32mINFO    [0m juju.model:model.py:2972 Waiting for model:
  postgresql-k8s/0 [idle] unknown: 
  postgresql-k8s/1 [executing] waiting: awaiting for primary endpoint to be ready
  postgresql-k8s/2 [idle] unknown: 
[32mINFO    [0m juju.model:model.py:2972 Waiting for model:
  postgresql-k8s/0 [idle] unknown: 
  postgresql-k8s/1 [executing] waiting: awaiting for primary endpoint to be ready
  postgresql-k8s/2 [idle] unknown: 
[32mINFO    [0m juju.model:model.py:2972 Waiting for model:
  postgresql-k8s/0 [idle] unknown: 
  postgresql-k8s/1 [executing] waiting: awaiting for primary endpoint to be ready
  postgresql-k8s/2 [idle] unknown: 
[32mINFO    [0m juju.model:model.py:2972 Waiting for model:
  postgresql-k8s/0 [idle] unknown: 
  postgresql-k8s/1 [executing] waiting: awaiting for primary endpoint to be ready
  postgresql-k8s/2 [idle] unknown: 
[32mINFO    [0m juju.model:model.py:2972 Waiting for model:
  postgresql-k8s/0 [idle] unknown: 
  postgresql-k8s/1 [executing] waiting: awaiting for primary endpoint to be ready
  postgresql-k8s/2 [idle] unknown: 
[32mINFO    [0m juju.model:model.py:2972 Waiting for model:
  postgresql-k8s/0 [idle] unknown: 
  postgresql-k8s/1 [executing] waiting: awaiting for primary endpoint to be ready
  postgresql-k8s/2 [idle] unknown: 
[32mINFO    [0m juju.model:model.py:2972 Waiting for model:
  postgresql-k8s/0 [idle] unknown: 
  postgresql-k8s/1 [executing] waiting: awaiting for primary endpoint to be ready
  postgresql-k8s/2 [idle] unknown: 
[32mINFO    [0m juju.model:model.py:2972 Waiting for model:
  postgresql-k8s/0 [idle] unknown: 
  postgresql-k8s/1 [executing] waiting: awaiting for primary endpoint to be ready
  postgresql-k8s/2 [idle] unknown: 
[32mINFO    [0m juju.model:model.py:2972 Waiting for model:
  postgresql-k8s/0 [idle] unknown: 
  postgresql-k8s/1 [executing] waiting: awaiting for primary endpoint to be ready
  postgresql-k8s/2 [idle] unknown: 
[32mINFO    [0m juju.model:model.py:2972 Waiting for model:
  postgresql-k8s/0 [idle] unknown: 
  postgresql-k8s/1 [executing] waiting: awaiting for primary endpoint to be ready
  postgresql-k8s/2 [idle] unknown: 
[32mINFO    [0m juju.model:model.py:2972 Waiting for model:
  postgresql-k8s/0 [idle] unknown: 
  postgresql-k8s/1 [executing] waiting: awaiting for primary endpoint to be ready
  postgresql-k8s/2 [idle] unknown: 
[32mINFO    [0m juju.model:model.py:2972 Waiting for model:
  postgresql-k8s/0 [idle] unknown: 
  postgresql-k8s/1 [executing] waiting: awaiting for primary endpoint to be ready
  postgresql-k8s/2 [idle] unknown: 
[32mINFO    [0m juju.model:model.py:2972 Waiting for model:
  postgresql-k8s/0 [idle] unknown: 
  postgresql-k8s/1 [idle] active: Primary
  postgresql-k8s/2 [idle] unknown: 
[32mINFO    [0m juju.model:model.py:2972 Waiting for model:
  postgresql-k8s/0 [idle] waiting: awaiting for cluster to start
  postgresql-k8s/1 [idle] active: Primary
  postgresql-k8s/2 [idle] waiting: awaiting for cluster to start
[32mINFO    [0m juju.model:model.py:2972 Waiting for model:
  postgresql-k8s/0 [idle] waiting: awaiting for cluster to start
  postgresql-k8s/1 [idle] active: Primary
  postgresql-k8s/2 [idle] waiting: awaiting for cluster to start
[32mINFO    [0m juju.model:model.py:2972 Waiting for model:
  postgresql-k8s/0 [idle] waiting: awaiting for cluster to start
  postgresql-k8s/1 [idle] active: Primary
  postgresql-k8s/2 [idle] waiting: awaiting for cluster to start
[32mINFO    [0m juju.model:model.py:2972 Waiting for model:
  postgresql-k8s/0 [idle] waiting: awaiting for cluster to start
  postgresql-k8s/1 [idle] active: Primary
  postgresql-k8s/2 [idle] waiting: awaiting for cluster to start
[32mINFO    [0m juju.model:model.py:2972 Waiting for model:
  postgresql-k8s/0 [idle] active: 
  postgresql-k8s/1 [idle] active: Primary
  postgresql-k8s/2 [idle] waiting: awaiting for cluster to start
[33mWARNING [0m juju.model:model.py:1564 relate is deprecated and will be removed. Use integrate instead.
[32mINFO    [0m pytest_operator.plugin:plugin.py:862 Model status:

Model  Controller          Cloud/Region        Version  SLA          Timestamp
test   microk8s-localhost  microk8s/localhost  3.4.4    unsupported  02:00:21Z

App                  Version  Status  Scale  Charm                Channel      Rev  Address         Exposed  Message
postgresql-k8s       14.12    active      3  postgresql-k8s                      0  10.152.183.212  no       
postgresql-test-app           active      1  postgresql-test-app  latest/edge  215  10.152.183.231  no       

Unit                    Workload  Agent  Address      Ports  Message
postgresql-k8s/0        active    idle   10.1.84.140         
postgresql-k8s/1*       active    idle   10.1.84.141         Primary
postgresql-k8s/2        active    idle   10.1.84.142         
postgresql-test-app/0*  active    idle   10.1.84.139         

[32mINFO    [0m pytest_operator.plugin:plugin.py:868 Juju error logs:

unit-postgresql-test-app-0: 01:55:19 ERROR unit.postgresql-test-app/0.juju-log Uncaught exception while in charm code:
Traceback (most recent call last):
  File "/var/lib/juju/agents/unit-postgresql-test-app-0/charm/./src/charm.py", line 538, in <module>
    main(ApplicationCharm)
  File "/var/lib/juju/agents/unit-postgresql-test-app-0/charm/venv/ops/main.py", line 551, in main
    manager.run()
  File "/var/lib/juju/agents/unit-postgresql-test-app-0/charm/venv/ops/main.py", line 530, in run
    self._emit()
  File "/var/lib/juju/agents/unit-postgresql-test-app-0/charm/venv/ops/main.py", line 519, in _emit
    _emit_charm_event(self.charm, self.dispatcher.event_name)
  File "/var/lib/juju/agents/unit-postgresql-test-app-0/charm/venv/ops/main.py", line 147, in _emit_charm_event
    event_to_emit.emit(*args, **kwargs)
  File "/var/lib/juju/agents/unit-postgresql-test-app-0/charm/venv/ops/framework.py", line 348, in emit
    framework._emit(event)
  File "/var/lib/juju/agents/unit-postgresql-test-app-0/charm/venv/ops/framework.py", line 860, in _emit
    self._reemit(event_path)
  File "/var/lib/juju/agents/unit-postgresql-test-app-0/charm/venv/ops/framework.py", line 950, in _reemit
    custom_handler(event)
  File "/var/lib/juju/agents/unit-postgresql-test-app-0/charm/./src/charm.py", line 289, in _on_clear_continuous_writes_action
    if self._connection_string is None:
  File "/var/lib/juju/agents/unit-postgresql-test-app-0/charm/./src/charm.py", line 259, in _connection_string
    data = list(self.first_database.fetch_relation_data().values())[0]
AttributeError: 'ApplicationCharm' object has no attribute 'first_database'
unit-postgresql-test-app-0: 01:55:23 ERROR unit.postgresql-test-app/0.juju-log Uncaught exception while in charm code:
Traceback (most recent call last):
  File "/var/lib/juju/agents/unit-postgresql-test-app-0/charm/./src/charm.py", line 538, in <module>
    main(ApplicationCharm)
  File "/var/lib/juju/agents/unit-postgresql-test-app-0/charm/venv/ops/main.py", line 551, in main
    manager.run()
  File "/var/lib/juju/agents/unit-postgresql-test-app-0/charm/venv/ops/main.py", line 530, in run
    self._emit()
  File "/var/lib/juju/agents/unit-postgresql-test-app-0/charm/venv/ops/main.py", line 519, in _emit
    _emit_charm_event(self.charm, self.dispatcher.event_name)
  File "/var/lib/juju/agents/unit-postgresql-test-app-0/charm/venv/ops/main.py", line 147, in _emit_charm_event
    event_to_emit.emit(*args, **kwargs)
  File "/var/lib/juju/agents/unit-postgresql-test-app-0/charm/venv/ops/framework.py", line 348, in emit
    framework._emit(event)
  File "/var/lib/juju/agents/unit-postgresql-test-app-0/charm/venv/ops/framework.py", line 860, in _emit
    self._reemit(event_path)
  File "/var/lib/juju/agents/unit-postgresql-test-app-0/charm/venv/ops/framework.py", line 950, in _reemit
    custom_handler(event)
  File "/var/lib/juju/agents/unit-postgresql-test-app-0/charm/./src/charm.py", line 289, in _on_clear_continuous_writes_action
    if self._connection_string is None:
  File "/var/lib/juju/agents/unit-postgresql-test-app-0/charm/./src/charm.py", line 259, in _connection_string
    data = list(self.first_database.fetch_relation_data().values())[0]
AttributeError: 'ApplicationCharm' object has no attribute 'first_database'
unit-postgresql-test-app-0: 01:55:27 ERROR unit.postgresql-test-app/0.juju-log Uncaught exception while in charm code:
Traceback (most recent call last):
  File "/var/lib/juju/agents/unit-postgresql-test-app-0/charm/./src/charm.py", line 538, in <module>
    main(ApplicationCharm)
  File "/var/lib/juju/agents/unit-postgresql-test-app-0/charm/venv/ops/main.py", line 551, in main
    manager.run()
  File "/var/lib/juju/agents/unit-postgresql-test-app-0/charm/venv/ops/main.py", line 530, in run
    self._emit()
  File "/var/lib/juju/agents/unit-postgresql-test-app-0/charm/venv/ops/main.py", line 519, in _emit
    _emit_charm_event(self.charm, self.dispatcher.event_name)
  File "/var/lib/juju/agents/unit-postgresql-test-app-0/charm/venv/ops/main.py", line 147, in _emit_charm_event
    event_to_emit.emit(*args, **kwargs)
  File "/var/lib/juju/agents/unit-postgresql-test-app-0/charm/venv/ops/framework.py", line 348, in emit
    framework._emit(event)
  File "/var/lib/juju/agents/unit-postgresql-test-app-0/charm/venv/ops/framework.py", line 860, in _emit
    self._reemit(event_path)
  File "/var/lib/juju/agents/unit-postgresql-test-app-0/charm/venv/ops/framework.py", line 950, in _reemit
    custom_handler(event)
  File "/var/lib/juju/agents/unit-postgresql-test-app-0/charm/./src/charm.py", line 289, in _on_clear_continuous_writes_action
    if self._connection_string is None:
  File "/var/lib/juju/agents/unit-postgresql-test-app-0/charm/./src/charm.py", line 259, in _connection_string
    data = list(self.first_database.fetch_relation_data().values())[0]
AttributeError: 'ApplicationCharm' object has no attribute 'first_database'
unit-postgresql-test-app-0: 01:55:31 ERROR unit.postgresql-test-app/0.juju-log Uncaught exception while in charm code:
Traceback (most recent call last):
  File "/var/lib/juju/agents/unit-postgresql-test-app-0/charm/./src/charm.py", line 538, in <module>
    main(ApplicationCharm)
  File "/var/lib/juju/agents/unit-postgresql-test-app-0/charm/venv/ops/main.py", line 551, in main
    manager.run()
  File "/var/lib/juju/agents/unit-postgresql-test-app-0/charm/venv/ops/main.py", line 530, in run
    self._emit()
  File "/var/lib/juju/agents/unit-postgresql-test-app-0/charm/venv/ops/main.py", line 519, in _emit
    _emit_charm_event(self.charm, self.dispatcher.event_name)
  File "/var/lib/juju/agents/unit-postgresql-test-app-0/charm/venv/ops/main.py", line 147, in _emit_charm_event
    event_to_emit.emit(*args, **kwargs)
  File "/var/lib/juju/agents/unit-postgresql-test-app-0/charm/venv/ops/framework.py", line 348, in emit
    framework._emit(event)
  File "/var/lib/juju/agents/unit-postgresql-test-app-0/charm/venv/ops/framework.py", line 860, in _emit
    self._reemit(event_path)
  File "/var/lib/juju/agents/unit-postgresql-test-app-0/charm/venv/ops/framework.py", line 950, in _reemit
    custom_handler(event)
  File "/var/lib/juju/agents/unit-postgresql-test-app-0/charm/./src/charm.py", line 289, in _on_clear_continuous_writes_action
    if self._connection_string is None:
  File "/var/lib/juju/agents/unit-postgresql-test-app-0/charm/./src/charm.py", line 259, in _connection_string
    data = list(self.first_database.fetch_relation_data().values())[0]
AttributeError: 'ApplicationCharm' object has no attribute 'first_database'
unit-postgresql-test-app-0: 01:55:35 ERROR unit.postgresql-test-app/0.juju-log Uncaught exception while in charm code:
Traceback (most recent call last):
  File "/var/lib/juju/agents/unit-postgresql-test-app-0/charm/./src/charm.py", line 538, in <module>
    main(ApplicationCharm)
  File "/var/lib/juju/agents/unit-postgresql-test-app-0/charm/venv/ops/main.py", line 551, in main
    manager.run()
  File "/var/lib/juju/agents/unit-postgresql-test-app-0/charm/venv/ops/main.py", line 530, in run
    self._emit()
  File "/var/lib/juju/agents/unit-postgresql-test-app-0/charm/venv/ops/main.py", line 519, in _emit
    _emit_charm_event(self.charm, self.dispatcher.event_name)
  File "/var/lib/juju/agents/unit-postgresql-test-app-0/charm/venv/ops/main.py", line 147, in _emit_charm_event
    event_to_emit.emit(*args, **kwargs)
  File "/var/lib/juju/agents/unit-postgresql-test-app-0/charm/venv/ops/framework.py", line 348, in emit
    framework._emit(event)
  File "/var/lib/juju/agents/unit-postgresql-test-app-0/charm/venv/ops/framework.py", line 860, in _emit
    self._reemit(event_path)
  File "/var/lib/juju/agents/unit-postgresql-test-app-0/charm/venv/ops/framework.py", line 950, in _reemit
    custom_handler(event)
  File "/var/lib/juju/agents/unit-postgresql-test-app-0/charm/./src/charm.py", line 289, in _on_clear_continuous_writes_action
    if self._connection_string is None:
  File "/var/lib/juju/agents/unit-postgresql-test-app-0/charm/./src/charm.py", line 259, in _connection_string
    data = list(self.first_database.fetch_relation_data().values())[0]
AttributeError: 'ApplicationCharm' object has no attribute 'first_database'
unit-postgresql-test-app-0: 01:55:39 ERROR unit.postgresql-test-app/0.juju-log Uncaught exception while in charm code:
Traceback (most recent call last):
  File "/var/lib/juju/agents/unit-postgresql-test-app-0/charm/./src/charm.py", line 538, in <module>
    main(ApplicationCharm)
  File "/var/lib/juju/agents/unit-postgresql-test-app-0/charm/venv/ops/main.py", line 551, in main
    manager.run()
  File "/var/lib/juju/agents/unit-postgresql-test-app-0/charm/venv/ops/main.py", line 530, in run
    self._emit()
  File "/var/lib/juju/agents/unit-postgresql-test-app-0/charm/venv/ops/main.py", line 519, in _emit
    _emit_charm_event(self.charm, self.dispatcher.event_name)
  File "/var/lib/juju/agents/unit-postgresql-test-app-0/charm/venv/ops/main.py", line 147, in _emit_charm_event
    event_to_emit.emit(*args, **kwargs)
  File "/var/lib/juju/agents/unit-postgresql-test-app-0/charm/venv/ops/framework.py", line 348, in emit
    framework._emit(event)
  File "/var/lib/juju/agents/unit-postgresql-test-app-0/charm/venv/ops/framework.py", line 860, in _emit
    self._reemit(event_path)
  File "/var/lib/juju/agents/unit-postgresql-test-app-0/charm/venv/ops/framework.py", line 950, in _reemit
    custom_handler(event)
  File "/var/lib/juju/agents/unit-postgresql-test-app-0/charm/./src/charm.py", line 289, in _on_clear_continuous_writes_action
    if self._connection_string is None:
  File "/var/lib/juju/agents/unit-postgresql-test-app-0/charm/./src/charm.py", line 259, in _connection_string
    data = list(self.first_database.fetch_relation_data().values())[0]
AttributeError: 'ApplicationCharm' object has no attribute 'first_database'
unit-postgresql-test-app-0: 01:55:43 ERROR unit.postgresql-test-app/0.juju-log Uncaught exception while in charm code:
Traceback (most recent call last):
  File "/var/lib/juju/agents/unit-postgresql-test-app-0/charm/./src/charm.py", line 538, in <module>
    main(ApplicationCharm)
  File "/var/lib/juju/agents/unit-postgresql-test-app-0/charm/venv/ops/main.py", line 551, in main
    manager.run()
  File "/var/lib/juju/agents/unit-postgresql-test-app-0/charm/venv/ops/main.py", line 530, in run
    self._emit()
  File "/var/lib/juju/agents/unit-postgresql-test-app-0/charm/venv/ops/main.py", line 519, in _emit
    _emit_charm_event(self.charm, self.dispatcher.event_name)
  File "/var/lib/juju/agents/unit-postgresql-test-app-0/charm/venv/ops/main.py", line 147, in _emit_charm_event
    event_to_emit.emit(*args, **kwargs)
  File "/var/lib/juju/agents/unit-postgresql-test-app-0/charm/venv/ops/framework.py", line 348, in emit
    framework._emit(event)
  File "/var/lib/juju/agents/unit-postgresql-test-app-0/charm/venv/ops/framework.py", line 860, in _emit
    self._reemit(event_path)
  File "/var/lib/juju/agents/unit-postgresql-test-app-0/charm/venv/ops/framework.py", line 950, in _reemit
    custom_handler(event)
  File "/var/lib/juju/agents/unit-postgresql-test-app-0/charm/./src/charm.py", line 289, in _on_clear_continuous_writes_action
    if self._connection_string is None:
  File "/var/lib/juju/agents/unit-postgresql-test-app-0/charm/./src/charm.py", line 259, in _connection_string
    data = list(self.first_database.fetch_relation_data().values())[0]
AttributeError: 'ApplicationCharm' object has no attribute 'first_database'
unit-postgresql-test-app-0: 01:55:47 ERROR unit.postgresql-test-app/0.juju-log Uncaught exception while in charm code:
Traceback (most recent call last):
  File "/var/lib/juju/agents/unit-postgresql-test-app-0/charm/./src/charm.py", line 538, in <module>
    main(ApplicationCharm)
  File "/var/lib/juju/agents/unit-postgresql-test-app-0/charm/venv/ops/main.py", line 551, in main
    manager.run()
  File "/var/lib/juju/agents/unit-postgresql-test-app-0/charm/venv/ops/main.py", line 530, in run
    self._emit()
  File "/var/lib/juju/agents/unit-postgresql-test-app-0/charm/venv/ops/main.py", line 519, in _emit
    _emit_charm_event(self.charm, self.dispatcher.event_name)
  File "/var/lib/juju/agents/unit-postgresql-test-app-0/charm/venv/ops/main.py", line 147, in _emit_charm_event
    event_to_emit.emit(*args, **kwargs)
  File "/var/lib/juju/agents/unit-postgresql-test-app-0/charm/venv/ops/framework.py", line 348, in emit
    framework._emit(event)
  File "/var/lib/juju/agents/unit-postgresql-test-app-0/charm/venv/ops/framework.py", line 860, in _emit
    self._reemit(event_path)
  File "/var/lib/juju/agents/unit-postgresql-test-app-0/charm/venv/ops/framework.py", line 950, in _reemit
    custom_handler(event)
  File "/var/lib/juju/agents/unit-postgresql-test-app-0/charm/./src/charm.py", line 289, in _on_clear_continuous_writes_action
    if self._connection_string is None:
  File "/var/lib/juju/agents/unit-postgresql-test-app-0/charm/./src/charm.py", line 259, in _connection_string
    data = list(self.first_database.fetch_relation_data().values())[0]
AttributeError: 'ApplicationCharm' object has no attribute 'first_database'
unit-postgresql-test-app-0: 01:55:51 ERROR unit.postgresql-test-app/0.juju-log Uncaught exception while in charm code:
Traceback (most recent call last):
  File "/var/lib/juju/agents/unit-postgresql-test-app-0/charm/./src/charm.py", line 538, in <module>
    main(ApplicationCharm)
  File "/var/lib/juju/agents/unit-postgresql-test-app-0/charm/venv/ops/main.py", line 551, in main
    manager.run()
  File "/var/lib/juju/agents/unit-postgresql-test-app-0/charm/venv/ops/main.py", line 530, in run
    self._emit()
  File "/var/lib/juju/agents/unit-postgresql-test-app-0/charm/venv/ops/main.py", line 519, in _emit
    _emit_charm_event(self.charm, self.dispatcher.event_name)
  File "/var/lib/juju/agents/unit-postgresql-test-app-0/charm/venv/ops/main.py", line 147, in _emit_charm_event
    event_to_emit.emit(*args, **kwargs)
  File "/var/lib/juju/agents/unit-postgresql-test-app-0/charm/venv/ops/framework.py", line 348, in emit
    framework._emit(event)
  File "/var/lib/juju/agents/unit-postgresql-test-app-0/charm/venv/ops/framework.py", line 860, in _emit
    self._reemit(event_path)
  File "/var/lib/juju/agents/unit-postgresql-test-app-0/charm/venv/ops/framework.py", line 950, in _reemit
    custom_handler(event)
  File "/var/lib/juju/agents/unit-postgresql-test-app-0/charm/./src/charm.py", line 289, in _on_clear_continuous_writes_action
    if self._connection_string is None:
  File "/var/lib/juju/agents/unit-postgresql-test-app-0/charm/./src/charm.py", line 259, in _connection_string
    data = list(self.first_database.fetch_relation_data().values())[0]
AttributeError: 'ApplicationCharm' object has no attribute 'first_database'
unit-postgresql-test-app-0: 01:55:55 ERROR unit.postgresql-test-app/0.juju-log Uncaught exception while in charm code:
Traceback (most recent call last):
  File "/var/lib/juju/agents/unit-postgresql-test-app-0/charm/./src/charm.py", line 538, in <module>
    main(ApplicationCharm)
  File "/var/lib/juju/agents/unit-postgresql-test-app-0/charm/venv/ops/main.py", line 551, in main
    manager.run()
  File "/var/lib/juju/agents/unit-postgresql-test-app-0/charm/venv/ops/main.py", line 530, in run
    self._emit()
  File "/var/lib/juju/agents/unit-postgresql-test-app-0/charm/venv/ops/main.py", line 519, in _emit
    _emit_charm_event(self.charm, self.dispatcher.event_name)
  File "/var/lib/juju/agents/unit-postgresql-test-app-0/charm/venv/ops/main.py", line 147, in _emit_charm_event
    event_to_emit.emit(*args, **kwargs)
  File "/var/lib/juju/agents/unit-postgresql-test-app-0/charm/venv/ops/framework.py", line 348, in emit
    framework._emit(event)
  File "/var/lib/juju/agents/unit-postgresql-test-app-0/charm/venv/ops/framework.py", line 860, in _emit
    self._reemit(event_path)
  File "/var/lib/juju/agents/unit-postgresql-test-app-0/charm/venv/ops/framework.py", line 950, in _reemit
    custom_handler(event)
  File "/var/lib/juju/agents/unit-postgresql-test-app-0/charm/./src/charm.py", line 289, in _on_clear_continuous_writes_action
    if self._connection_string is None:
  File "/var/lib/juju/agents/unit-postgresql-test-app-0/charm/./src/charm.py", line 259, in _connection_string
    data = list(self.first_database.fetch_relation_data().values())[0]
AttributeError: 'ApplicationCharm' object has no attribute 'first_database'
unit-postgresql-test-app-0: 01:55:59 ERROR unit.postgresql-test-app/0.juju-log Uncaught exception while in charm code:
Traceback (most recent call last):
  File "/var/lib/juju/agents/unit-postgresql-test-app-0/charm/./src/charm.py", line 538, in <module>
    main(ApplicationCharm)
  File "/var/lib/juju/agents/unit-postgresql-test-app-0/charm/venv/ops/main.py", line 551, in main
    manager.run()
  File "/var/lib/juju/agents/unit-postgresql-test-app-0/charm/venv/ops/main.py", line 530, in run
    self._emit()
  File "/var/lib/juju/agents/unit-postgresql-test-app-0/charm/venv/ops/main.py", line 519, in _emit
    _emit_charm_event(self.charm, self.dispatcher.event_name)
  File "/var/lib/juju/agents/unit-postgresql-test-app-0/charm/venv/ops/main.py", line 147, in _emit_charm_event
    event_to_emit.emit(*args, **kwargs)
  File "/var/lib/juju/agents/unit-postgresql-test-app-0/charm/venv/ops/framework.py", line 348, in emit
    framework._emit(event)
  File "/var/lib/juju/agents/unit-postgresql-test-app-0/charm/venv/ops/framework.py", line 860, in _emit
    self._reemit(event_path)
  File "/var/lib/juju/agents/unit-postgresql-test-app-0/charm/venv/ops/framework.py", line 950, in _reemit
    custom_handler(event)
  File "/var/lib/juju/agents/unit-postgresql-test-app-0/charm/./src/charm.py", line 289, in _on_clear_continuous_writes_action
    if self._connection_string is None:
  File "/var/lib/juju/agents/unit-postgresql-test-app-0/charm/./src/charm.py", line 259, in _connection_string
    data = list(self.first_database.fetch_relation_data().values())[0]
AttributeError: 'ApplicationCharm' object has no attribute 'first_database'
unit-postgresql-test-app-0: 01:56:03 ERROR unit.postgresql-test-app/0.juju-log Uncaught exception while in charm code:
Traceback (most recent call last):
  File "/var/lib/juju/agents/unit-postgresql-test-app-0/charm/./src/charm.py", line 538, in <module>
    main(ApplicationCharm)
  File "/var/lib/juju/agents/unit-postgresql-test-app-0/charm/venv/ops/main.py", line 551, in main
    manager.run()
  File "/var/lib/juju/agents/unit-postgresql-test-app-0/charm/venv/ops/main.py", line 530, in run
    self._emit()
  File "/var/lib/juju/agents/unit-postgresql-test-app-0/charm/venv/ops/main.py", line 519, in _emit
    _emit_charm_event(self.charm, self.dispatcher.event_name)
  File "/var/lib/juju/agents/unit-postgresql-test-app-0/charm/venv/ops/main.py", line 147, in _emit_charm_event
    event_to_emit.emit(*args, **kwargs)
  File "/var/lib/juju/agents/unit-postgresql-test-app-0/charm/venv/ops/framework.py", line 348, in emit
    framework._emit(event)
  File "/var/lib/juju/agents/unit-postgresql-test-app-0/charm/venv/ops/framework.py", line 860, in _emit
    self._reemit(event_path)
  File "/var/lib/juju/agents/unit-postgresql-test-app-0/charm/venv/ops/framework.py", line 950, in _reemit
    custom_handler(event)
  File "/var/lib/juju/agents/unit-postgresql-test-app-0/charm/./src/charm.py", line 289, in _on_clear_continuous_writes_action
    if self._connection_string is None:
  File "/var/lib/juju/agents/unit-postgresql-test-app-0/charm/./src/charm.py", line 259, in _connection_string
    data = list(self.first_database.fetch_relation_data().values())[0]
AttributeError: 'ApplicationCharm' object has no attribute 'first_database'
unit-postgresql-test-app-0: 01:56:07 ERROR unit.postgresql-test-app/0.juju-log Uncaught exception while in charm code:
Traceback (most recent call last):
  File "/var/lib/juju/agents/unit-postgresql-test-app-0/charm/./src/charm.py", line 538, in <module>
    main(ApplicationCharm)
  File "/var/lib/juju/agents/unit-postgresql-test-app-0/charm/venv/ops/main.py", line 551, in main
    manager.run()
  File "/var/lib/juju/agents/unit-postgresql-test-app-0/charm/venv/ops/main.py", line 530, in run
    self._emit()
  File "/var/lib/juju/agents/unit-postgresql-test-app-0/charm/venv/ops/main.py", line 519, in _emit
    _emit_charm_event(self.charm, self.dispatcher.event_name)
  File "/var/lib/juju/agents/unit-postgresql-test-app-0/charm/venv/ops/main.py", line 147, in _emit_charm_event
    event_to_emit.emit(*args, **kwargs)
  File "/var/lib/juju/agents/unit-postgresql-test-app-0/charm/venv/ops/framework.py", line 348, in emit
    framework._emit(event)
  File "/var/lib/juju/agents/unit-postgresql-test-app-0/charm/venv/ops/framework.py", line 860, in _emit
    self._reemit(event_path)
  File "/var/lib/juju/agents/unit-postgresql-test-app-0/charm/venv/ops/framework.py", line 950, in _reemit
    custom_handler(event)
  File "/var/lib/juju/agents/unit-postgresql-test-app-0/charm/./src/charm.py", line 289, in _on_clear_continuous_writes_action
    if self._connection_string is None:
  File "/var/lib/juju/agents/unit-postgresql-test-app-0/charm/./src/charm.py", line 259, in _connection_string
    data = list(self.first_database.fetch_relation_data().values())[0]
AttributeError: 'ApplicationCharm' object has no attribute 'first_database'
unit-postgresql-test-app-0: 01:56:11 ERROR unit.postgresql-test-app/0.juju-log Uncaught exception while in charm code:
Traceback (most recent call last):
  File "/var/lib/juju/agents/unit-postgresql-test-app-0/charm/./src/charm.py", line 538, in <module>
    main(ApplicationCharm)
  File "/var/lib/juju/agents/unit-postgresql-test-app-0/charm/venv/ops/main.py", line 551, in main
    manager.run()
  File "/var/lib/juju/agents/unit-postgresql-test-app-0/charm/venv/ops/main.py", line 530, in run
    self._emit()
  File "/var/lib/juju/agents/unit-postgresql-test-app-0/charm/venv/ops/main.py", line 519, in _emit
    _emit_charm_event(self.charm, self.dispatcher.event_name)
  File "/var/lib/juju/agents/unit-postgresql-test-app-0/charm/venv/ops/main.py", line 147, in _emit_charm_event
    event_to_emit.emit(*args, **kwargs)
  File "/var/lib/juju/agents/unit-postgresql-test-app-0/charm/venv/ops/framework.py", line 348, in emit
    framework._emit(event)
  File "/var/lib/juju/agents/unit-postgresql-test-app-0/charm/venv/ops/framework.py", line 860, in _emit
    self._reemit(event_path)
  File "/var/lib/juju/agents/unit-postgresql-test-app-0/charm/venv/ops/framework.py", line 950, in _reemit
    custom_handler(event)
  File "/var/lib/juju/agents/unit-postgresql-test-app-0/charm/./src/charm.py", line 289, in _on_clear_continuous_writes_action
    if self._connection_string is None:
  File "/var/lib/juju/agents/unit-postgresql-test-app-0/charm/./src/charm.py", line 259, in _connection_string
    data = list(self.first_database.fetch_relation_data().values())[0]
AttributeError: 'ApplicationCharm' object has no attribute 'first_database'
unit-postgresql-test-app-0: 01:56:15 ERROR unit.postgresql-test-app/0.juju-log Uncaught exception while in charm code:
Traceback (most recent call last):
  File "/var/lib/juju/agents/unit-postgresql-test-app-0/charm/./src/charm.py", line 538, in <module>
    main(ApplicationCharm)
  File "/var/lib/juju/agents/unit-postgresql-test-app-0/charm/venv/ops/main.py", line 551, in main
    manager.run()
  File "/var/lib/juju/agents/unit-postgresql-test-app-0/charm/venv/ops/main.py", line 530, in run
    self._emit()
  File "/var/lib/juju/agents/unit-postgresql-test-app-0/charm/venv/ops/main.py", line 519, in _emit
    _emit_charm_event(self.charm, self.dispatcher.event_name)
  File "/var/lib/juju/agents/unit-postgresql-test-app-0/charm/venv/ops/main.py", line 147, in _emit_charm_event
    event_to_emit.emit(*args, **kwargs)
  File "/var/lib/juju/agents/unit-postgresql-test-app-0/charm/venv/ops/framework.py", line 348, in emit
    framework._emit(event)
  File "/var/lib/juju/agents/unit-postgresql-test-app-0/charm/venv/ops/framework.py", line 860, in _emit
    self._reemit(event_path)
  File "/var/lib/juju/agents/unit-postgresql-test-app-0/charm/venv/ops/framework.py", line 950, in _reemit
    custom_handler(event)
  File "/var/lib/juju/agents/unit-postgresql-test-app-0/charm/./src/charm.py", line 289, in _on_clear_continuous_writes_action
    if self._connection_string is None:
  File "/var/lib/juju/agents/unit-postgresql-test-app-0/charm/./src/charm.py", line 259, in _connection_string
    data = list(self.first_database.fetch_relation_data().values())[0]
AttributeError: 'ApplicationCharm' object has no attribute 'first_database'
unit-postgresql-test-app-0: 01:56:19 ERROR unit.postgresql-test-app/0.juju-log Uncaught exception while in charm code:
Traceback (most recent call last):
  File "/var/lib/juju/agents/unit-postgresql-test-app-0/charm/./src/charm.py", line 538, in <module>
    main(ApplicationCharm)
  File "/var/lib/juju/agents/unit-postgresql-test-app-0/charm/venv/ops/main.py", line 551, in main
    manager.run()
  File "/var/lib/juju/agents/unit-postgresql-test-app-0/charm/venv/ops/main.py", line 530, in run
    self._emit()
  File "/var/lib/juju/agents/unit-postgresql-test-app-0/charm/venv/ops/main.py", line 519, in _emit
    _emit_charm_event(self.charm, self.dispatcher.event_name)
  File "/var/lib/juju/agents/unit-postgresql-test-app-0/charm/venv/ops/main.py", line 147, in _emit_charm_event
    event_to_emit.emit(*args, **kwargs)
  File "/var/lib/juju/agents/unit-postgresql-test-app-0/charm/venv/ops/framework.py", line 348, in emit
    framework._emit(event)
  File "/var/lib/juju/agents/unit-postgresql-test-app-0/charm/venv/ops/framework.py", line 860, in _emit
    self._reemit(event_path)
  File "/var/lib/juju/agents/unit-postgresql-test-app-0/charm/venv/ops/framework.py", line 950, in _reemit
    custom_handler(event)
  File "/var/lib/juju/agents/unit-postgresql-test-app-0/charm/./src/charm.py", line 289, in _on_clear_continuous_writes_action
    if self._connection_string is None:
  File "/var/lib/juju/agents/unit-postgresql-test-app-0/charm/./src/charm.py", line 259, in _connection_string
    data = list(self.first_database.fetch_relation_data().values())[0]
AttributeError: 'ApplicationCharm' object has no attribute 'first_database'
unit-postgresql-test-app-0: 01:56:23 ERROR unit.postgresql-test-app/0.juju-log Uncaught exception while in charm code:
Traceback (most recent call last):
  File "/var/lib/juju/agents/unit-postgresql-test-app-0/charm/./src/charm.py", line 538, in <module>
    main(ApplicationCharm)
  File "/var/lib/juju/agents/unit-postgresql-test-app-0/charm/venv/ops/main.py", line 551, in main
    manager.run()
  File "/var/lib/juju/agents/unit-postgresql-test-app-0/charm/venv/ops/main.py", line 530, in run
    self._emit()
  File "/var/lib/juju/agents/unit-postgresql-test-app-0/charm/venv/ops/main.py", line 519, in _emit
    _emit_charm_event(self.charm, self.dispatcher.event_name)
  File "/var/lib/juju/agents/unit-postgresql-test-app-0/charm/venv/ops/main.py", line 147, in _emit_charm_event
    event_to_emit.emit(*args, **kwargs)
  File "/var/lib/juju/agents/unit-postgresql-test-app-0/charm/venv/ops/framework.py", line 348, in emit
    framework._emit(event)
  File "/var/lib/juju/agents/unit-postgresql-test-app-0/charm/venv/ops/framework.py", line 860, in _emit
    self._reemit(event_path)
  File "/var/lib/juju/agents/unit-postgresql-test-app-0/charm/venv/ops/framework.py", line 950, in _reemit
    custom_handler(event)
  File "/var/lib/juju/agents/unit-postgresql-test-app-0/charm/./src/charm.py", line 289, in _on_clear_continuous_writes_action
    if self._connection_string is None:
  File "/var/lib/juju/agents/unit-postgresql-test-app-0/charm/./src/charm.py", line 259, in _connection_string
    data = list(self.first_database.fetch_relation_data().values())[0]
AttributeError: 'ApplicationCharm' object has no attribute 'first_database'
unit-postgresql-test-app-0: 01:56:27 ERROR unit.postgresql-test-app/0.juju-log Uncaught exception while in charm code:
Traceback (most recent call last):
  File "/var/lib/juju/agents/unit-postgresql-test-app-0/charm/./src/charm.py", line 538, in <module>
    main(ApplicationCharm)
  File "/var/lib/juju/agents/unit-postgresql-test-app-0/charm/venv/ops/main.py", line 551, in main
    manager.run()
  File "/var/lib/juju/agents/unit-postgresql-test-app-0/charm/venv/ops/main.py", line 530, in run
    self._emit()
  File "/var/lib/juju/agents/unit-postgresql-test-app-0/charm/venv/ops/main.py", line 519, in _emit
    _emit_charm_event(self.charm, self.dispatcher.event_name)
  File "/var/lib/juju/agents/unit-postgresql-test-app-0/charm/venv/ops/main.py", line 147, in _emit_charm_event
    event_to_emit.emit(*args, **kwargs)
  File "/var/lib/juju/agents/unit-postgresql-test-app-0/charm/venv/ops/framework.py", line 348, in emit
    framework._emit(event)
  File "/var/lib/juju/agents/unit-postgresql-test-app-0/charm/venv/ops/framework.py", line 860, in _emit
    self._reemit(event_path)
  File "/var/lib/juju/agents/unit-postgresql-test-app-0/charm/venv/ops/framework.py", line 950, in _reemit
    custom_handler(event)
  File "/var/lib/juju/agents/unit-postgresql-test-app-0/charm/./src/charm.py", line 289, in _on_clear_continuous_writes_action
    if self._connection_string is None:
  File "/var/lib/juju/agents/unit-postgresql-test-app-0/charm/./src/charm.py", line 259, in _connection_string
    data = list(self.first_database.fetch_relation_data().values())[0]
AttributeError: 'ApplicationCharm' object has no attribute 'first_database'
unit-postgresql-test-app-0: 01:56:31 ERROR unit.postgresql-test-app/0.juju-log Uncaught exception while in charm code:
Traceback (most recent call last):
  File "/var/lib/juju/agents/unit-postgresql-test-app-0/charm/./src/charm.py", line 538, in <module>
    main(ApplicationCharm)
  File "/var/lib/juju/agents/unit-postgresql-test-app-0/charm/venv/ops/main.py", line 551, in main
    manager.run()
  File "/var/lib/juju/agents/unit-postgresql-test-app-0/charm/venv/ops/main.py", line 530, in run
    self._emit()
  File "/var/lib/juju/agents/unit-postgresql-test-app-0/charm/venv/ops/main.py", line 519, in _emit
    _emit_charm_event(self.charm, self.dispatcher.event_name)
  File "/var/lib/juju/agents/unit-postgresql-test-app-0/charm/venv/ops/main.py", line 147, in _emit_charm_event
    event_to_emit.emit(*args, **kwargs)
  File "/var/lib/juju/agents/unit-postgresql-test-app-0/charm/venv/ops/framework.py", line 348, in emit
    framework._emit(event)
  File "/var/lib/juju/agents/unit-postgresql-test-app-0/charm/venv/ops/framework.py", line 860, in _emit
    self._reemit(event_path)
  File "/var/lib/juju/agents/unit-postgresql-test-app-0/charm/venv/ops/framework.py", line 950, in _reemit
    custom_handler(event)
  File "/var/lib/juju/agents/unit-postgresql-test-app-0/charm/./src/charm.py", line 289, in _on_clear_continuous_writes_action
    if self._connection_string is None:
  File "/var/lib/juju/agents/unit-postgresql-test-app-0/charm/./src/charm.py", line 259, in _connection_string
    data = list(self.first_database.fetch_relation_data().values())[0]
AttributeError: 'ApplicationCharm' object has no attribute 'first_database'
unit-postgresql-test-app-0: 01:56:35 ERROR unit.postgresql-test-app/0.juju-log Uncaught exception while in charm code:
Traceback (most recent call last):
  File "/var/lib/juju/agents/unit-postgresql-test-app-0/charm/./src/charm.py", line 538, in <module>
    main(ApplicationCharm)
  File "/var/lib/juju/agents/unit-postgresql-test-app-0/charm/venv/ops/main.py", line 551, in main
    manager.run()
  File "/var/lib/juju/agents/unit-postgresql-test-app-0/charm/venv/ops/main.py", line 530, in run
    self._emit()
  File "/var/lib/juju/agents/unit-postgresql-test-app-0/charm/venv/ops/main.py", line 519, in _emit
    _emit_charm_event(self.charm, self.dispatcher.event_name)
  File "/var/lib/juju/agents/unit-postgresql-test-app-0/charm/venv/ops/main.py", line 147, in _emit_charm_event
    event_to_emit.emit(*args, **kwargs)
  File "/var/lib/juju/agents/unit-postgresql-test-app-0/charm/venv/ops/framework.py", line 348, in emit
    framework._emit(event)
  File "/var/lib/juju/agents/unit-postgresql-test-app-0/charm/venv/ops/framework.py", line 860, in _emit
    self._reemit(event_path)
  File "/var/lib/juju/agents/unit-postgresql-test-app-0/charm/venv/ops/framework.py", line 950, in _reemit
    custom_handler(event)
  File "/var/lib/juju/agents/unit-postgresql-test-app-0/charm/./src/charm.py", line 289, in _on_clear_continuous_writes_action
    if self._connection_string is None:
  File "/var/lib/juju/agents/unit-postgresql-test-app-0/charm/./src/charm.py", line 259, in _connection_string
    data = list(self.first_database.fetch_relation_data().values())[0]
AttributeError: 'ApplicationCharm' object has no attribute 'first_database'
unit-postgresql-test-app-0: 01:56:39 ERROR unit.postgresql-test-app/0.juju-log Uncaught exception while in charm code:
Traceback (most recent call last):
  File "/var/lib/juju/agents/unit-postgresql-test-app-0/charm/./src/charm.py", line 538, in <module>
    main(ApplicationCharm)
  File "/var/lib/juju/agents/unit-postgresql-test-app-0/charm/venv/ops/main.py", line 551, in main
    manager.run()
  File "/var/lib/juju/agents/unit-postgresql-test-app-0/charm/venv/ops/main.py", line 530, in run
    self._emit()
  File "/var/lib/juju/agents/unit-postgresql-test-app-0/charm/venv/ops/main.py", line 519, in _emit
    _emit_charm_event(self.charm, self.dispatcher.event_name)
  File "/var/lib/juju/agents/unit-postgresql-test-app-0/charm/venv/ops/main.py", line 147, in _emit_charm_event
    event_to_emit.emit(*args, **kwargs)
  File "/var/lib/juju/agents/unit-postgresql-test-app-0/charm/venv/ops/framework.py", line 348, in emit
    framework._emit(event)
  File "/var/lib/juju/agents/unit-postgresql-test-app-0/charm/venv/ops/framework.py", line 860, in _emit
    self._reemit(event_path)
  File "/var/lib/juju/agents/unit-postgresql-test-app-0/charm/venv/ops/framework.py", line 950, in _reemit
    custom_handler(event)
  File "/var/lib/juju/agents/unit-postgresql-test-app-0/charm/./src/charm.py", line 289, in _on_clear_continuous_writes_action
    if self._connection_string is None:
  File "/var/lib/juju/agents/unit-postgresql-test-app-0/charm/./src/charm.py", line 259, in _connection_string
    data = list(self.first_database.fetch_relation_data().values())[0]
AttributeError: 'ApplicationCharm' object has no attribute 'first_database'
unit-postgresql-test-app-0: 01:56:43 ERROR unit.postgresql-test-app/0.juju-log Uncaught exception while in charm code:
Traceback (most recent call last):
  File "/var/lib/juju/agents/unit-postgresql-test-app-0/charm/./src/charm.py", line 538, in <module>
    main(ApplicationCharm)
  File "/var/lib/juju/agents/unit-postgresql-test-app-0/charm/venv/ops/main.py", line 551, in main
    manager.run()
  File "/var/lib/juju/agents/unit-postgresql-test-app-0/charm/venv/ops/main.py", line 530, in run
    self._emit()
  File "/var/lib/juju/agents/unit-postgresql-test-app-0/charm/venv/ops/main.py", line 519, in _emit
    _emit_charm_event(self.charm, self.dispatcher.event_name)
  File "/var/lib/juju/agents/unit-postgresql-test-app-0/charm/venv/ops/main.py", line 147, in _emit_charm_event
    event_to_emit.emit(*args, **kwargs)
  File "/var/lib/juju/agents/unit-postgresql-test-app-0/charm/venv/ops/framework.py", line 348, in emit
    framework._emit(event)
  File "/var/lib/juju/agents/unit-postgresql-test-app-0/charm/venv/ops/framework.py", line 860, in _emit
    self._reemit(event_path)
  File "/var/lib/juju/agents/unit-postgresql-test-app-0/charm/venv/ops/framework.py", line 950, in _reemit
    custom_handler(event)
  File "/var/lib/juju/agents/unit-postgresql-test-app-0/charm/./src/charm.py", line 289, in _on_clear_continuous_writes_action
    if self._connection_string is None:
  File "/var/lib/juju/agents/unit-postgresql-test-app-0/charm/./src/charm.py", line 259, in _connection_string
    data = list(self.first_database.fetch_relation_data().values())[0]
AttributeError: 'ApplicationCharm' object has no attribute 'first_database'
unit-postgresql-test-app-0: 01:56:47 ERROR unit.postgresql-test-app/0.juju-log Uncaught exception while in charm code:
Traceback (most recent call last):
  File "/var/lib/juju/agents/unit-postgresql-test-app-0/charm/./src/charm.py", line 538, in <module>
    main(ApplicationCharm)
  File "/var/lib/juju/agents/unit-postgresql-test-app-0/charm/venv/ops/main.py", line 551, in main
    manager.run()
  File "/var/lib/juju/agents/unit-postgresql-test-app-0/charm/venv/ops/main.py", line 530, in run
    self._emit()
  File "/var/lib/juju/agents/unit-postgresql-test-app-0/charm/venv/ops/main.py", line 519, in _emit
    _emit_charm_event(self.charm, self.dispatcher.event_name)
  File "/var/lib/juju/agents/unit-postgresql-test-app-0/charm/venv/ops/main.py", line 147, in _emit_charm_event
    event_to_emit.emit(*args, **kwargs)
  File "/var/lib/juju/agents/unit-postgresql-test-app-0/charm/venv/ops/framework.py", line 348, in emit
    framework._emit(event)
  File "/var/lib/juju/agents/unit-postgresql-test-app-0/charm/venv/ops/framework.py", line 860, in _emit
    self._reemit(event_path)
  File "/var/lib/juju/agents/unit-postgresql-test-app-0/charm/venv/ops/framework.py", line 950, in _reemit
    custom_handler(event)
  File "/var/lib/juju/agents/unit-postgresql-test-app-0/charm/./src/charm.py", line 289, in _on_clear_continuous_writes_action
    if self._connection_string is None:
  File "/var/lib/juju/agents/unit-postgresql-test-app-0/charm/./src/charm.py", line 259, in _connection_string
    data = list(self.first_database.fetch_relation_data().values())[0]
AttributeError: 'ApplicationCharm' object has no attribute 'first_database'
unit-postgresql-test-app-0: 01:56:51 ERROR unit.postgresql-test-app/0.juju-log Uncaught exception while in charm code:
Traceback (most recent call last):
  File "/var/lib/juju/agents/unit-postgresql-test-app-0/charm/./src/charm.py", line 538, in <module>
    main(ApplicationCharm)
  File "/var/lib/juju/agents/unit-postgresql-test-app-0/charm/venv/ops/main.py", line 551, in main
    manager.run()
  File "/var/lib/juju/agents/unit-postgresql-test-app-0/charm/venv/ops/main.py", line 530, in run
    self._emit()
  File "/var/lib/juju/agents/unit-postgresql-test-app-0/charm/venv/ops/main.py", line 519, in _emit
    _emit_charm_event(self.charm, self.dispatcher.event_name)
  File "/var/lib/juju/agents/unit-postgresql-test-app-0/charm/venv/ops/main.py", line 147, in _emit_charm_event
    event_to_emit.emit(*args, **kwargs)
  File "/var/lib/juju/agents/unit-postgresql-test-app-0/charm/venv/ops/framework.py", line 348, in emit
    framework._emit(event)
  File "/var/lib/juju/agents/unit-postgresql-test-app-0/charm/venv/ops/framework.py", line 860, in _emit
    self._reemit(event_path)
  File "/var/lib/juju/agents/unit-postgresql-test-app-0/charm/venv/ops/framework.py", line 950, in _reemit
    custom_handler(event)
  File "/var/lib/juju/agents/unit-postgresql-test-app-0/charm/./src/charm.py", line 289, in _on_clear_continuous_writes_action
    if self._connection_string is None:
  File "/var/lib/juju/agents/unit-postgresql-test-app-0/charm/./src/charm.py", line 259, in _connection_string
    data = list(self.first_database.fetch_relation_data().values())[0]
AttributeError: 'ApplicationCharm' object has no attribute 'first_database'
unit-postgresql-test-app-0: 01:56:55 ERROR unit.postgresql-test-app/0.juju-log Uncaught exception while in charm code:
Traceback (most recent call last):
  File "/var/lib/juju/agents/unit-postgresql-test-app-0/charm/./src/charm.py", line 538, in <module>
    main(ApplicationCharm)
  File "/var/lib/juju/agents/unit-postgresql-test-app-0/charm/venv/ops/main.py", line 551, in main
    manager.run()
  File "/var/lib/juju/agents/unit-postgresql-test-app-0/charm/venv/ops/main.py", line 530, in run
    self._emit()
  File "/var/lib/juju/agents/unit-postgresql-test-app-0/charm/venv/ops/main.py", line 519, in _emit
    _emit_charm_event(self.charm, self.dispatcher.event_name)
  File "/var/lib/juju/agents/unit-postgresql-test-app-0/charm/venv/ops/main.py", line 147, in _emit_charm_event
    event_to_emit.emit(*args, **kwargs)
  File "/var/lib/juju/agents/unit-postgresql-test-app-0/charm/venv/ops/framework.py", line 348, in emit
    framework._emit(event)
  File "/var/lib/juju/agents/unit-postgresql-test-app-0/charm/venv/ops/framework.py", line 860, in _emit
    self._reemit(event_path)
  File "/var/lib/juju/agents/unit-postgresql-test-app-0/charm/venv/ops/framework.py", line 950, in _reemit
    custom_handler(event)
  File "/var/lib/juju/agents/unit-postgresql-test-app-0/charm/./src/charm.py", line 289, in _on_clear_continuous_writes_action
    if self._connection_string is None:
  File "/var/lib/juju/agents/unit-postgresql-test-app-0/charm/./src/charm.py", line 259, in _connection_string
    data = list(self.first_database.fetch_relation_data().values())[0]
AttributeError: 'ApplicationCharm' object has no attribute 'first_database'
unit-postgresql-test-app-0: 01:56:59 ERROR unit.postgresql-test-app/0.juju-log Uncaught exception while in charm code:
Traceback (most recent call last):
  File "/var/lib/juju/agents/unit-postgresql-test-app-0/charm/./src/charm.py", line 538, in <module>
    main(ApplicationCharm)
  File "/var/lib/juju/agents/unit-postgresql-test-app-0/charm/venv/ops/main.py", line 551, in main
    manager.run()
  File "/var/lib/juju/agents/unit-postgresql-test-app-0/charm/venv/ops/main.py", line 530, in run
    self._emit()
  File "/var/lib/juju/agents/unit-postgresql-test-app-0/charm/venv/ops/main.py", line 519, in _emit
    _emit_charm_event(self.charm, self.dispatcher.event_name)
  File "/var/lib/juju/agents/unit-postgresql-test-app-0/charm/venv/ops/main.py", line 147, in _emit_charm_event
    event_to_emit.emit(*args, **kwargs)
  File "/var/lib/juju/agents/unit-postgresql-test-app-0/charm/venv/ops/framework.py", line 348, in emit
    framework._emit(event)
  File "/var/lib/juju/agents/unit-postgresql-test-app-0/charm/venv/ops/framework.py", line 860, in _emit
    self._reemit(event_path)
  File "/var/lib/juju/agents/unit-postgresql-test-app-0/charm/venv/ops/framework.py", line 950, in _reemit
    custom_handler(event)
  File "/var/lib/juju/agents/unit-postgresql-test-app-0/charm/./src/charm.py", line 289, in _on_clear_continuous_writes_action
    if self._connection_string is None:
  File "/var/lib/juju/agents/unit-postgresql-test-app-0/charm/./src/charm.py", line 259, in _connection_string
    data = list(self.first_database.fetch_relation_data().values())[0]
AttributeError: 'ApplicationCharm' object has no attribute 'first_database'
unit-postgresql-test-app-0: 01:57:03 ERROR unit.postgresql-test-app/0.juju-log Uncaught exception while in charm code:
Traceback (most recent call last):
  File "/var/lib/juju/agents/unit-postgresql-test-app-0/charm/./src/charm.py", line 538, in <module>
    main(ApplicationCharm)
  File "/var/lib/juju/agents/unit-postgresql-test-app-0/charm/venv/ops/main.py", line 551, in main
    manager.run()
  File "/var/lib/juju/agents/unit-postgresql-test-app-0/charm/venv/ops/main.py", line 530, in run
    self._emit()
  File "/var/lib/juju/agents/unit-postgresql-test-app-0/charm/venv/ops/main.py", line 519, in _emit
    _emit_charm_event(self.charm, self.dispatcher.event_name)
  File "/var/lib/juju/agents/unit-postgresql-test-app-0/charm/venv/ops/main.py", line 147, in _emit_charm_event
    event_to_emit.emit(*args, **kwargs)
  File "/var/lib/juju/agents/unit-postgresql-test-app-0/charm/venv/ops/framework.py", line 348, in emit
    framework._emit(event)
  File "/var/lib/juju/agents/unit-postgresql-test-app-0/charm/venv/ops/framework.py", line 860, in _emit
    self._reemit(event_path)
  File "/var/lib/juju/agents/unit-postgresql-test-app-0/charm/venv/ops/framework.py", line 950, in _reemit
    custom_handler(event)
  File "/var/lib/juju/agents/unit-postgresql-test-app-0/charm/./src/charm.py", line 289, in _on_clear_continuous_writes_action
    if self._connection_string is None:
  File "/var/lib/juju/agents/unit-postgresql-test-app-0/charm/./src/charm.py", line 259, in _connection_string
    data = list(self.first_database.fetch_relation_data().values())[0]
AttributeError: 'ApplicationCharm' object has no attribute 'first_database'
unit-postgresql-test-app-0: 01:57:07 ERROR unit.postgresql-test-app/0.juju-log Uncaught exception while in charm code:
Traceback (most recent call last):
  File "/var/lib/juju/agents/unit-postgresql-test-app-0/charm/./src/charm.py", line 538, in <module>
    main(ApplicationCharm)
  File "/var/lib/juju/agents/unit-postgresql-test-app-0/charm/venv/ops/main.py", line 551, in main
    manager.run()
  File "/var/lib/juju/agents/unit-postgresql-test-app-0/charm/venv/ops/main.py", line 530, in run
    self._emit()
  File "/var/lib/juju/agents/unit-postgresql-test-app-0/charm/venv/ops/main.py", line 519, in _emit
    _emit_charm_event(self.charm, self.dispatcher.event_name)
  File "/var/lib/juju/agents/unit-postgresql-test-app-0/charm/venv/ops/main.py", line 147, in _emit_charm_event
    event_to_emit.emit(*args, **kwargs)
  File "/var/lib/juju/agents/unit-postgresql-test-app-0/charm/venv/ops/framework.py", line 348, in emit
    framework._emit(event)
  File "/var/lib/juju/agents/unit-postgresql-test-app-0/charm/venv/ops/framework.py", line 860, in _emit
    self._reemit(event_path)
  File "/var/lib/juju/agents/unit-postgresql-test-app-0/charm/venv/ops/framework.py", line 950, in _reemit
    custom_handler(event)
  File "/var/lib/juju/agents/unit-postgresql-test-app-0/charm/./src/charm.py", line 289, in _on_clear_continuous_writes_action
    if self._connection_string is None:
  File "/var/lib/juju/agents/unit-postgresql-test-app-0/charm/./src/charm.py", line 259, in _connection_string
    data = list(self.first_database.fetch_relation_data().values())[0]
AttributeError: 'ApplicationCharm' object has no attribute 'first_database'
unit-postgresql-test-app-0: 01:57:11 ERROR unit.postgresql-test-app/0.juju-log Uncaught exception while in charm code:
Traceback (most recent call last):
  File "/var/lib/juju/agents/unit-postgresql-test-app-0/charm/./src/charm.py", line 538, in <module>
    main(ApplicationCharm)
  File "/var/lib/juju/agents/unit-postgresql-test-app-0/charm/venv/ops/main.py", line 551, in main
    manager.run()
  File "/var/lib/juju/agents/unit-postgresql-test-app-0/charm/venv/ops/main.py", line 530, in run
    self._emit()
  File "/var/lib/juju/agents/unit-postgresql-test-app-0/charm/venv/ops/main.py", line 519, in _emit
    _emit_charm_event(self.charm, self.dispatcher.event_name)
  File "/var/lib/juju/agents/unit-postgresql-test-app-0/charm/venv/ops/main.py", line 147, in _emit_charm_event
    event_to_emit.emit(*args, **kwargs)
  File "/var/lib/juju/agents/unit-postgresql-test-app-0/charm/venv/ops/framework.py", line 348, in emit
    framework._emit(event)
  File "/var/lib/juju/agents/unit-postgresql-test-app-0/charm/venv/ops/framework.py", line 860, in _emit
    self._reemit(event_path)
  File "/var/lib/juju/agents/unit-postgresql-test-app-0/charm/venv/ops/framework.py", line 950, in _reemit
    custom_handler(event)
  File "/var/lib/juju/agents/unit-postgresql-test-app-0/charm/./src/charm.py", line 289, in _on_clear_continuous_writes_action
    if self._connection_string is None:
  File "/var/lib/juju/agents/unit-postgresql-test-app-0/charm/./src/charm.py", line 259, in _connection_string
    data = list(self.first_database.fetch_relation_data().values())[0]
AttributeError: 'ApplicationCharm' object has no attribute 'first_database'
unit-postgresql-test-app-0: 01:57:15 ERROR unit.postgresql-test-app/0.juju-log Uncaught exception while in charm code:
Traceback (most recent call last):
  File "/var/lib/juju/agents/unit-postgresql-test-app-0/charm/./src/charm.py", line 538, in <module>
    main(ApplicationCharm)
  File "/var/lib/juju/agents/unit-postgresql-test-app-0/charm/venv/ops/main.py", line 551, in main
    manager.run()
  File "/var/lib/juju/agents/unit-postgresql-test-app-0/charm/venv/ops/main.py", line 530, in run
    self._emit()
  File "/var/lib/juju/agents/unit-postgresql-test-app-0/charm/venv/ops/main.py", line 519, in _emit
    _emit_charm_event(self.charm, self.dispatcher.event_name)
  File "/var/lib/juju/agents/unit-postgresql-test-app-0/charm/venv/ops/main.py", line 147, in _emit_charm_event
    event_to_emit.emit(*args, **kwargs)
  File "/var/lib/juju/agents/unit-postgresql-test-app-0/charm/venv/ops/framework.py", line 348, in emit
    framework._emit(event)
  File "/var/lib/juju/agents/unit-postgresql-test-app-0/charm/venv/ops/framework.py", line 860, in _emit
    self._reemit(event_path)
  File "/var/lib/juju/agents/unit-postgresql-test-app-0/charm/venv/ops/framework.py", line 950, in _reemit
    custom_handler(event)
  File "/var/lib/juju/agents/unit-postgresql-test-app-0/charm/./src/charm.py", line 289, in _on_clear_continuous_writes_action
    if self._connection_string is None:
  File "/var/lib/juju/agents/unit-postgresql-test-app-0/charm/./src/charm.py", line 259, in _connection_string
    data = list(self.first_database.fetch_relation_data().values())[0]
AttributeError: 'ApplicationCharm' object has no attribute 'first_database'
unit-postgresql-test-app-0: 01:57:19 ERROR unit.postgresql-test-app/0.juju-log Uncaught exception while in charm code:
Traceback (most recent call last):
  File "/var/lib/juju/agents/unit-postgresql-test-app-0/charm/./src/charm.py", line 538, in <module>
    main(ApplicationCharm)
  File "/var/lib/juju/agents/unit-postgresql-test-app-0/charm/venv/ops/main.py", line 551, in main
    manager.run()
  File "/var/lib/juju/agents/unit-postgresql-test-app-0/charm/venv/ops/main.py", line 530, in run
    self._emit()
  File "/var/lib/juju/agents/unit-postgresql-test-app-0/charm/venv/ops/main.py", line 519, in _emit
    _emit_charm_event(self.charm, self.dispatcher.event_name)
  File "/var/lib/juju/agents/unit-postgresql-test-app-0/charm/venv/ops/main.py", line 147, in _emit_charm_event
    event_to_emit.emit(*args, **kwargs)
  File "/var/lib/juju/agents/unit-postgresql-test-app-0/charm/venv/ops/framework.py", line 348, in emit
    framework._emit(event)
  File "/var/lib/juju/agents/unit-postgresql-test-app-0/charm/venv/ops/framework.py", line 860, in _emit
    self._reemit(event_path)
  File "/var/lib/juju/agents/unit-postgresql-test-app-0/charm/venv/ops/framework.py", line 950, in _reemit
    custom_handler(event)
  File "/var/lib/juju/agents/unit-postgresql-test-app-0/charm/./src/charm.py", line 289, in _on_clear_continuous_writes_action
    if self._connection_string is None:
  File "/var/lib/juju/agents/unit-postgresql-test-app-0/charm/./src/charm.py", line 259, in _connection_string
    data = list(self.first_database.fetch_relation_data().values())[0]
AttributeError: 'ApplicationCharm' object has no attribute 'first_database'
unit-postgresql-test-app-0: 01:57:23 ERROR unit.postgresql-test-app/0.juju-log Uncaught exception while in charm code:
Traceback (most recent call last):
  File "/var/lib/juju/agents/unit-postgresql-test-app-0/charm/./src/charm.py", line 538, in <module>
    main(ApplicationCharm)
  File "/var/lib/juju/agents/unit-postgresql-test-app-0/charm/venv/ops/main.py", line 551, in main
    manager.run()
  File "/var/lib/juju/agents/unit-postgresql-test-app-0/charm/venv/ops/main.py", line 530, in run
    self._emit()
  File "/var/lib/juju/agents/unit-postgresql-test-app-0/charm/venv/ops/main.py", line 519, in _emit
    _emit_charm_event(self.charm, self.dispatcher.event_name)
  File "/var/lib/juju/agents/unit-postgresql-test-app-0/charm/venv/ops/main.py", line 147, in _emit_charm_event
    event_to_emit.emit(*args, **kwargs)
  File "/var/lib/juju/agents/unit-postgresql-test-app-0/charm/venv/ops/framework.py", line 348, in emit
    framework._emit(event)
  File "/var/lib/juju/agents/unit-postgresql-test-app-0/charm/venv/ops/framework.py", line 860, in _emit
    self._reemit(event_path)
  File "/var/lib/juju/agents/unit-postgresql-test-app-0/charm/venv/ops/framework.py", line 950, in _reemit
    custom_handler(event)
  File "/var/lib/juju/agents/unit-postgresql-test-app-0/charm/./src/charm.py", line 289, in _on_clear_continuous_writes_action
    if self._connection_string is None:
  File "/var/lib/juju/agents/unit-postgresql-test-app-0/charm/./src/charm.py", line 259, in _connection_string
    data = list(self.first_database.fetch_relation_data().values())[0]
AttributeError: 'ApplicationCharm' object has no attribute 'first_database'
unit-postgresql-test-app-0: 01:57:27 ERROR unit.postgresql-test-app/0.juju-log Uncaught exception while in charm code:
Traceback (most recent call last):
  File "/var/lib/juju/agents/unit-postgresql-test-app-0/charm/./src/charm.py", line 538, in <module>
    main(ApplicationCharm)
  File "/var/lib/juju/agents/unit-postgresql-test-app-0/charm/venv/ops/main.py", line 551, in main
    manager.run()
  File "/var/lib/juju/agents/unit-postgresql-test-app-0/charm/venv/ops/main.py", line 530, in run
    self._emit()
  File "/var/lib/juju/agents/unit-postgresql-test-app-0/charm/venv/ops/main.py", line 519, in _emit
    _emit_charm_event(self.charm, self.dispatcher.event_name)
  File "/var/lib/juju/agents/unit-postgresql-test-app-0/charm/venv/ops/main.py", line 147, in _emit_charm_event
    event_to_emit.emit(*args, **kwargs)
  File "/var/lib/juju/agents/unit-postgresql-test-app-0/charm/venv/ops/framework.py", line 348, in emit
    framework._emit(event)
  File "/var/lib/juju/agents/unit-postgresql-test-app-0/charm/venv/ops/framework.py", line 860, in _emit
    self._reemit(event_path)
  File "/var/lib/juju/agents/unit-postgresql-test-app-0/charm/venv/ops/framework.py", line 950, in _reemit
    custom_handler(event)
  File "/var/lib/juju/agents/unit-postgresql-test-app-0/charm/./src/charm.py", line 289, in _on_clear_continuous_writes_action
    if self._connection_string is None:
  File "/var/lib/juju/agents/unit-postgresql-test-app-0/charm/./src/charm.py", line 259, in _connection_string
    data = list(self.first_database.fetch_relation_data().values())[0]
AttributeError: 'ApplicationCharm' object has no attribute 'first_database'
unit-postgresql-test-app-0: 01:57:31 ERROR unit.postgresql-test-app/0.juju-log Uncaught exception while in charm code:
Traceback (most recent call last):
  File "/var/lib/juju/agents/unit-postgresql-test-app-0/charm/./src/charm.py", line 538, in <module>
    main(ApplicationCharm)
  File "/var/lib/juju/agents/unit-postgresql-test-app-0/charm/venv/ops/main.py", line 551, in main
    manager.run()
  File "/var/lib/juju/agents/unit-postgresql-test-app-0/charm/venv/ops/main.py", line 530, in run
    self._emit()
  File "/var/lib/juju/agents/unit-postgresql-test-app-0/charm/venv/ops/main.py", line 519, in _emit
    _emit_charm_event(self.charm, self.dispatcher.event_name)
  File "/var/lib/juju/agents/unit-postgresql-test-app-0/charm/venv/ops/main.py", line 147, in _emit_charm_event
    event_to_emit.emit(*args, **kwargs)
  File "/var/lib/juju/agents/unit-postgresql-test-app-0/charm/venv/ops/framework.py", line 348, in emit
    framework._emit(event)
  File "/var/lib/juju/agents/unit-postgresql-test-app-0/charm/venv/ops/framework.py", line 860, in _emit
    self._reemit(event_path)
  File "/var/lib/juju/agents/unit-postgresql-test-app-0/charm/venv/ops/framework.py", line 950, in _reemit
    custom_handler(event)
  File "/var/lib/juju/agents/unit-postgresql-test-app-0/charm/./src/charm.py", line 289, in _on_clear_continuous_writes_action
    if self._connection_string is None:
  File "/var/lib/juju/agents/unit-postgresql-test-app-0/charm/./src/charm.py", line 259, in _connection_string
    data = list(self.first_database.fetch_relation_data().values())[0]
AttributeError: 'ApplicationCharm' object has no attribute 'first_database'
unit-postgresql-test-app-0: 01:57:35 ERROR unit.postgresql-test-app/0.juju-log Uncaught exception while in charm code:
Traceback (most recent call last):
  File "/var/lib/juju/agents/unit-postgresql-test-app-0/charm/./src/charm.py", line 538, in <module>
    main(ApplicationCharm)
  File "/var/lib/juju/agents/unit-postgresql-test-app-0/charm/venv/ops/main.py", line 551, in main
    manager.run()
  File "/var/lib/juju/agents/unit-postgresql-test-app-0/charm/venv/ops/main.py", line 530, in run
    self._emit()
  File "/var/lib/juju/agents/unit-postgresql-test-app-0/charm/venv/ops/main.py", line 519, in _emit
    _emit_charm_event(self.charm, self.dispatcher.event_name)
  File "/var/lib/juju/agents/unit-postgresql-test-app-0/charm/venv/ops/main.py", line 147, in _emit_charm_event
    event_to_emit.emit(*args, **kwargs)
  File "/var/lib/juju/agents/unit-postgresql-test-app-0/charm/venv/ops/framework.py", line 348, in emit
    framework._emit(event)
  File "/var/lib/juju/agents/unit-postgresql-test-app-0/charm/venv/ops/framework.py", line 860, in _emit
    self._reemit(event_path)
  File "/var/lib/juju/agents/unit-postgresql-test-app-0/charm/venv/ops/framework.py", line 950, in _reemit
    custom_handler(event)
  File "/var/lib/juju/agents/unit-postgresql-test-app-0/charm/./src/charm.py", line 289, in _on_clear_continuous_writes_action
    if self._connection_string is None:
  File "/var/lib/juju/agents/unit-postgresql-test-app-0/charm/./src/charm.py", line 259, in _connection_string
    data = list(self.first_database.fetch_relation_data().values())[0]
AttributeError: 'ApplicationCharm' object has no attribute 'first_database'
unit-postgresql-test-app-0: 01:57:39 ERROR unit.postgresql-test-app/0.juju-log Uncaught exception while in charm code:
Traceback (most recent call last):
  File "/var/lib/juju/agents/unit-postgresql-test-app-0/charm/./src/charm.py", line 538, in <module>
    main(ApplicationCharm)
  File "/var/lib/juju/agents/unit-postgresql-test-app-0/charm/venv/ops/main.py", line 551, in main
    manager.run()
  File "/var/lib/juju/agents/unit-postgresql-test-app-0/charm/venv/ops/main.py", line 530, in run
    self._emit()
  File "/var/lib/juju/agents/unit-postgresql-test-app-0/charm/venv/ops/main.py", line 519, in _emit
    _emit_charm_event(self.charm, self.dispatcher.event_name)
  File "/var/lib/juju/agents/unit-postgresql-test-app-0/charm/venv/ops/main.py", line 147, in _emit_charm_event
    event_to_emit.emit(*args, **kwargs)
  File "/var/lib/juju/agents/unit-postgresql-test-app-0/charm/venv/ops/framework.py", line 348, in emit
    framework._emit(event)
  File "/var/lib/juju/agents/unit-postgresql-test-app-0/charm/venv/ops/framework.py", line 860, in _emit
    self._reemit(event_path)
  File "/var/lib/juju/agents/unit-postgresql-test-app-0/charm/venv/ops/framework.py", line 950, in _reemit
    custom_handler(event)
  File "/var/lib/juju/agents/unit-postgresql-test-app-0/charm/./src/charm.py", line 289, in _on_clear_continuous_writes_action
    if self._connection_string is None:
  File "/var/lib/juju/agents/unit-postgresql-test-app-0/charm/./src/charm.py", line 259, in _connection_string
    data = list(self.first_database.fetch_relation_data().values())[0]
AttributeError: 'ApplicationCharm' object has no attribute 'first_database'
unit-postgresql-test-app-0: 01:57:43 ERROR unit.postgresql-test-app/0.juju-log Uncaught exception while in charm code:
Traceback (most recent call last):
  File "/var/lib/juju/agents/unit-postgresql-test-app-0/charm/./src/charm.py", line 538, in <module>
    main(ApplicationCharm)
  File "/var/lib/juju/agents/unit-postgresql-test-app-0/charm/venv/ops/main.py", line 551, in main
    manager.run()
  File "/var/lib/juju/agents/unit-postgresql-test-app-0/charm/venv/ops/main.py", line 530, in run
    self._emit()
  File "/var/lib/juju/agents/unit-postgresql-test-app-0/charm/venv/ops/main.py", line 519, in _emit
    _emit_charm_event(self.charm, self.dispatcher.event_name)
  File "/var/lib/juju/agents/unit-postgresql-test-app-0/charm/venv/ops/main.py", line 147, in _emit_charm_event
    event_to_emit.emit(*args, **kwargs)
  File "/var/lib/juju/agents/unit-postgresql-test-app-0/charm/venv/ops/framework.py", line 348, in emit
    framework._emit(event)
  File "/var/lib/juju/agents/unit-postgresql-test-app-0/charm/venv/ops/framework.py", line 860, in _emit
    self._reemit(event_path)
  File "/var/lib/juju/agents/unit-postgresql-test-app-0/charm/venv/ops/framework.py", line 950, in _reemit
    custom_handler(event)
  File "/var/lib/juju/agents/unit-postgresql-test-app-0/charm/./src/charm.py", line 289, in _on_clear_continuous_writes_action
    if self._connection_string is None:
  File "/var/lib/juju/agents/unit-postgresql-test-app-0/charm/./src/charm.py", line 259, in _connection_string
    data = list(self.first_database.fetch_relation_data().values())[0]
AttributeError: 'ApplicationCharm' object has no attribute 'first_database'
unit-postgresql-test-app-0: 01:57:47 ERROR unit.postgresql-test-app/0.juju-log Uncaught exception while in charm code:
Traceback (most recent call last):
  File "/var/lib/juju/agents/unit-postgresql-test-app-0/charm/./src/charm.py", line 538, in <module>
    main(ApplicationCharm)
  File "/var/lib/juju/agents/unit-postgresql-test-app-0/charm/venv/ops/main.py", line 551, in main
    manager.run()
  File "/var/lib/juju/agents/unit-postgresql-test-app-0/charm/venv/ops/main.py", line 530, in run
    self._emit()
  File "/var/lib/juju/agents/unit-postgresql-test-app-0/charm/venv/ops/main.py", line 519, in _emit
    _emit_charm_event(self.charm, self.dispatcher.event_name)
  File "/var/lib/juju/agents/unit-postgresql-test-app-0/charm/venv/ops/main.py", line 147, in _emit_charm_event
    event_to_emit.emit(*args, **kwargs)
  File "/var/lib/juju/agents/unit-postgresql-test-app-0/charm/venv/ops/framework.py", line 348, in emit
    framework._emit(event)
  File "/var/lib/juju/agents/unit-postgresql-test-app-0/charm/venv/ops/framework.py", line 860, in _emit
    self._reemit(event_path)
  File "/var/lib/juju/agents/unit-postgresql-test-app-0/charm/venv/ops/framework.py", line 950, in _reemit
    custom_handler(event)
  File "/var/lib/juju/agents/unit-postgresql-test-app-0/charm/./src/charm.py", line 289, in _on_clear_continuous_writes_action
    if self._connection_string is None:
  File "/var/lib/juju/agents/unit-postgresql-test-app-0/charm/./src/charm.py", line 259, in _connection_string
    data = list(self.first_database.fetch_relation_data().values())[0]
AttributeError: 'ApplicationCharm' object has no attribute 'first_database'
unit-postgresql-test-app-0: 01:57:51 ERROR unit.postgresql-test-app/0.juju-log Uncaught exception while in charm code:
Traceback (most recent call last):
  File "/var/lib/juju/agents/unit-postgresql-test-app-0/charm/./src/charm.py", line 538, in <module>
    main(ApplicationCharm)
  File "/var/lib/juju/agents/unit-postgresql-test-app-0/charm/venv/ops/main.py", line 551, in main
    manager.run()
  File "/var/lib/juju/agents/unit-postgresql-test-app-0/charm/venv/ops/main.py", line 530, in run
    self._emit()
  File "/var/lib/juju/agents/unit-postgresql-test-app-0/charm/venv/ops/main.py", line 519, in _emit
    _emit_charm_event(self.charm, self.dispatcher.event_name)
  File "/var/lib/juju/agents/unit-postgresql-test-app-0/charm/venv/ops/main.py", line 147, in _emit_charm_event
    event_to_emit.emit(*args, **kwargs)
  File "/var/lib/juju/agents/unit-postgresql-test-app-0/charm/venv/ops/framework.py", line 348, in emit
    framework._emit(event)
  File "/var/lib/juju/agents/unit-postgresql-test-app-0/charm/venv/ops/framework.py", line 860, in _emit
    self._reemit(event_path)
  File "/var/lib/juju/agents/unit-postgresql-test-app-0/charm/venv/ops/framework.py", line 950, in _reemit
    custom_handler(event)
  File "/var/lib/juju/agents/unit-postgresql-test-app-0/charm/./src/charm.py", line 289, in _on_clear_continuous_writes_action
    if self._connection_string is None:
  File "/var/lib/juju/agents/unit-postgresql-test-app-0/charm/./src/charm.py", line 259, in _connection_string
    data = list(self.first_database.fetch_relation_data().values())[0]
AttributeError: 'ApplicationCharm' object has no attribute 'first_database'
unit-postgresql-test-app-0: 01:57:55 ERROR unit.postgresql-test-app/0.juju-log Uncaught exception while in charm code:
Traceback (most recent call last):
  File "/var/lib/juju/agents/unit-postgresql-test-app-0/charm/./src/charm.py", line 538, in <module>
    main(ApplicationCharm)
  File "/var/lib/juju/agents/unit-postgresql-test-app-0/charm/venv/ops/main.py", line 551, in main
    manager.run()
  File "/var/lib/juju/agents/unit-postgresql-test-app-0/charm/venv/ops/main.py", line 530, in run
    self._emit()
  File "/var/lib/juju/agents/unit-postgresql-test-app-0/charm/venv/ops/main.py", line 519, in _emit
    _emit_charm_event(self.charm, self.dispatcher.event_name)
  File "/var/lib/juju/agents/unit-postgresql-test-app-0/charm/venv/ops/main.py", line 147, in _emit_charm_event
    event_to_emit.emit(*args, **kwargs)
  File "/var/lib/juju/agents/unit-postgresql-test-app-0/charm/venv/ops/framework.py", line 348, in emit
    framework._emit(event)
  File "/var/lib/juju/agents/unit-postgresql-test-app-0/charm/venv/ops/framework.py", line 860, in _emit
    self._reemit(event_path)
  File "/var/lib/juju/agents/unit-postgresql-test-app-0/charm/venv/ops/framework.py", line 950, in _reemit
    custom_handler(event)
  File "/var/lib/juju/agents/unit-postgresql-test-app-0/charm/./src/charm.py", line 289, in _on_clear_continuous_writes_action
    if self._connection_string is None:
  File "/var/lib/juju/agents/unit-postgresql-test-app-0/charm/./src/charm.py", line 259, in _connection_string
    data = list(self.first_database.fetch_relation_data().values())[0]
AttributeError: 'ApplicationCharm' object has no attribute 'first_database'
unit-postgresql-test-app-0: 01:57:59 ERROR unit.postgresql-test-app/0.juju-log Uncaught exception while in charm code:
Traceback (most recent call last):
  File "/var/lib/juju/agents/unit-postgresql-test-app-0/charm/./src/charm.py", line 538, in <module>
    main(ApplicationCharm)
  File "/var/lib/juju/agents/unit-postgresql-test-app-0/charm/venv/ops/main.py", line 551, in main
    manager.run()
  File "/var/lib/juju/agents/unit-postgresql-test-app-0/charm/venv/ops/main.py", line 530, in run
    self._emit()
  File "/var/lib/juju/agents/unit-postgresql-test-app-0/charm/venv/ops/main.py", line 519, in _emit
    _emit_charm_event(self.charm, self.dispatcher.event_name)
  File "/var/lib/juju/agents/unit-postgresql-test-app-0/charm/venv/ops/main.py", line 147, in _emit_charm_event
    event_to_emit.emit(*args, **kwargs)
  File "/var/lib/juju/agents/unit-postgresql-test-app-0/charm/venv/ops/framework.py", line 348, in emit
    framework._emit(event)
  File "/var/lib/juju/agents/unit-postgresql-test-app-0/charm/venv/ops/framework.py", line 860, in _emit
    self._reemit(event_path)
  File "/var/lib/juju/agents/unit-postgresql-test-app-0/charm/venv/ops/framework.py", line 950, in _reemit
    custom_handler(event)
  File "/var/lib/juju/agents/unit-postgresql-test-app-0/charm/./src/charm.py", line 289, in _on_clear_continuous_writes_action
    if self._connection_string is None:
  File "/var/lib/juju/agents/unit-postgresql-test-app-0/charm/./src/charm.py", line 259, in _connection_string
    data = list(self.first_database.fetch_relation_data().values())[0]
AttributeError: 'ApplicationCharm' object has no attribute 'first_database'
unit-postgresql-test-app-0: 01:58:03 ERROR unit.postgresql-test-app/0.juju-log Uncaught exception while in charm code:
Traceback (most recent call last):
  File "/var/lib/juju/agents/unit-postgresql-test-app-0/charm/./src/charm.py", line 538, in <module>
    main(ApplicationCharm)
  File "/var/lib/juju/agents/unit-postgresql-test-app-0/charm/venv/ops/main.py", line 551, in main
    manager.run()
  File "/var/lib/juju/agents/unit-postgresql-test-app-0/charm/venv/ops/main.py", line 530, in run
    self._emit()
  File "/var/lib/juju/agents/unit-postgresql-test-app-0/charm/venv/ops/main.py", line 519, in _emit
    _emit_charm_event(self.charm, self.dispatcher.event_name)
  File "/var/lib/juju/agents/unit-postgresql-test-app-0/charm/venv/ops/main.py", line 147, in _emit_charm_event
    event_to_emit.emit(*args, **kwargs)
  File "/var/lib/juju/agents/unit-postgresql-test-app-0/charm/venv/ops/framework.py", line 348, in emit
    framework._emit(event)
  File "/var/lib/juju/agents/unit-postgresql-test-app-0/charm/venv/ops/framework.py", line 860, in _emit
    self._reemit(event_path)
  File "/var/lib/juju/agents/unit-postgresql-test-app-0/charm/venv/ops/framework.py", line 950, in _reemit
    custom_handler(event)
  File "/var/lib/juju/agents/unit-postgresql-test-app-0/charm/./src/charm.py", line 289, in _on_clear_continuous_writes_action
    if self._connection_string is None:
  File "/var/lib/juju/agents/unit-postgresql-test-app-0/charm/./src/charm.py", line 259, in _connection_string
    data = list(self.first_database.fetch_relation_data().values())[0]
AttributeError: 'ApplicationCharm' object has no attribute 'first_database'
unit-postgresql-test-app-0: 01:58:07 ERROR unit.postgresql-test-app/0.juju-log Uncaught exception while in charm code:
Traceback (most recent call last):
  File "/var/lib/juju/agents/unit-postgresql-test-app-0/charm/./src/charm.py", line 538, in <module>
    main(ApplicationCharm)
  File "/var/lib/juju/agents/unit-postgresql-test-app-0/charm/venv/ops/main.py", line 551, in main
    manager.run()
  File "/var/lib/juju/agents/unit-postgresql-test-app-0/charm/venv/ops/main.py", line 530, in run
    self._emit()
  File "/var/lib/juju/agents/unit-postgresql-test-app-0/charm/venv/ops/main.py", line 519, in _emit
    _emit_charm_event(self.charm, self.dispatcher.event_name)
  File "/var/lib/juju/agents/unit-postgresql-test-app-0/charm/venv/ops/main.py", line 147, in _emit_charm_event
    event_to_emit.emit(*args, **kwargs)
  File "/var/lib/juju/agents/unit-postgresql-test-app-0/charm/venv/ops/framework.py", line 348, in emit
    framework._emit(event)
  File "/var/lib/juju/agents/unit-postgresql-test-app-0/charm/venv/ops/framework.py", line 860, in _emit
    self._reemit(event_path)
  File "/var/lib/juju/agents/unit-postgresql-test-app-0/charm/venv/ops/framework.py", line 950, in _reemit
    custom_handler(event)
  File "/var/lib/juju/agents/unit-postgresql-test-app-0/charm/./src/charm.py", line 289, in _on_clear_continuous_writes_action
    if self._connection_string is None:
  File "/var/lib/juju/agents/unit-postgresql-test-app-0/charm/./src/charm.py", line 259, in _connection_string
    data = list(self.first_database.fetch_relation_data().values())[0]
AttributeError: 'ApplicationCharm' object has no attribute 'first_database'
unit-postgresql-test-app-0: 01:58:11 ERROR unit.postgresql-test-app/0.juju-log Uncaught exception while in charm code:
Traceback (most recent call last):
  File "/var/lib/juju/agents/unit-postgresql-test-app-0/charm/./src/charm.py", line 538, in <module>
    main(ApplicationCharm)
  File "/var/lib/juju/agents/unit-postgresql-test-app-0/charm/venv/ops/main.py", line 551, in main
    manager.run()
  File "/var/lib/juju/agents/unit-postgresql-test-app-0/charm/venv/ops/main.py", line 530, in run
    self._emit()
  File "/var/lib/juju/agents/unit-postgresql-test-app-0/charm/venv/ops/main.py", line 519, in _emit
    _emit_charm_event(self.charm, self.dispatcher.event_name)
  File "/var/lib/juju/agents/unit-postgresql-test-app-0/charm/venv/ops/main.py", line 147, in _emit_charm_event
    event_to_emit.emit(*args, **kwargs)
  File "/var/lib/juju/agents/unit-postgresql-test-app-0/charm/venv/ops/framework.py", line 348, in emit
    framework._emit(event)
  File "/var/lib/juju/agents/unit-postgresql-test-app-0/charm/venv/ops/framework.py", line 860, in _emit
    self._reemit(event_path)
  File "/var/lib/juju/agents/unit-postgresql-test-app-0/charm/venv/ops/framework.py", line 950, in _reemit
    custom_handler(event)
  File "/var/lib/juju/agents/unit-postgresql-test-app-0/charm/./src/charm.py", line 289, in _on_clear_continuous_writes_action
    if self._connection_string is None:
  File "/var/lib/juju/agents/unit-postgresql-test-app-0/charm/./src/charm.py", line 259, in _connection_string
    data = list(self.first_database.fetch_relation_data().values())[0]
AttributeError: 'ApplicationCharm' object has no attribute 'first_database'
unit-postgresql-test-app-0: 01:58:15 ERROR unit.postgresql-test-app/0.juju-log Uncaught exception while in charm code:
Traceback (most recent call last):
  File "/var/lib/juju/agents/unit-postgresql-test-app-0/charm/./src/charm.py", line 538, in <module>
    main(ApplicationCharm)
  File "/var/lib/juju/agents/unit-postgresql-test-app-0/charm/venv/ops/main.py", line 551, in main
    manager.run()
  File "/var/lib/juju/agents/unit-postgresql-test-app-0/charm/venv/ops/main.py", line 530, in run
    self._emit()
  File "/var/lib/juju/agents/unit-postgresql-test-app-0/charm/venv/ops/main.py", line 519, in _emit
    _emit_charm_event(self.charm, self.dispatcher.event_name)
  File "/var/lib/juju/agents/unit-postgresql-test-app-0/charm/venv/ops/main.py", line 147, in _emit_charm_event
    event_to_emit.emit(*args, **kwargs)
  File "/var/lib/juju/agents/unit-postgresql-test-app-0/charm/venv/ops/framework.py", line 348, in emit
    framework._emit(event)
  File "/var/lib/juju/agents/unit-postgresql-test-app-0/charm/venv/ops/framework.py", line 860, in _emit
    self._reemit(event_path)
  File "/var/lib/juju/agents/unit-postgresql-test-app-0/charm/venv/ops/framework.py", line 950, in _reemit
    custom_handler(event)
  File "/var/lib/juju/agents/unit-postgresql-test-app-0/charm/./src/charm.py", line 289, in _on_clear_continuous_writes_action
    if self._connection_string is None:
  File "/var/lib/juju/agents/unit-postgresql-test-app-0/charm/./src/charm.py", line 259, in _connection_string
    data = list(self.first_database.fetch_relation_data().values())[0]
AttributeError: 'ApplicationCharm' object has no attribute 'first_database'
unit-postgresql-test-app-0: 01:58:20 ERROR unit.postgresql-test-app/0.juju-log Uncaught exception while in charm code:
Traceback (most recent call last):
  File "/var/lib/juju/agents/unit-postgresql-test-app-0/charm/./src/charm.py", line 538, in <module>
    main(ApplicationCharm)
  File "/var/lib/juju/agents/unit-postgresql-test-app-0/charm/venv/ops/main.py", line 551, in main
    manager.run()
  File "/var/lib/juju/agents/unit-postgresql-test-app-0/charm/venv/ops/main.py", line 530, in run
    self._emit()
  File "/var/lib/juju/agents/unit-postgresql-test-app-0/charm/venv/ops/main.py", line 519, in _emit
    _emit_charm_event(self.charm, self.dispatcher.event_name)
  File "/var/lib/juju/agents/unit-postgresql-test-app-0/charm/venv/ops/main.py", line 147, in _emit_charm_event
    event_to_emit.emit(*args, **kwargs)
  File "/var/lib/juju/agents/unit-postgresql-test-app-0/charm/venv/ops/framework.py", line 348, in emit
    framework._emit(event)
  File "/var/lib/juju/agents/unit-postgresql-test-app-0/charm/venv/ops/framework.py", line 860, in _emit
    self._reemit(event_path)
  File "/var/lib/juju/agents/unit-postgresql-test-app-0/charm/venv/ops/framework.py", line 950, in _reemit
    custom_handler(event)
  File "/var/lib/juju/agents/unit-postgresql-test-app-0/charm/./src/charm.py", line 289, in _on_clear_continuous_writes_action
    if self._connection_string is None:
  File "/var/lib/juju/agents/unit-postgresql-test-app-0/charm/./src/charm.py", line 259, in _connection_string
    data = list(self.first_database.fetch_relation_data().values())[0]
AttributeError: 'ApplicationCharm' object has no attribute 'first_database'
unit-postgresql-test-app-0: 01:58:24 ERROR unit.postgresql-test-app/0.juju-log Uncaught exception while in charm code:
Traceback (most recent call last):
  File "/var/lib/juju/agents/unit-postgresql-test-app-0/charm/./src/charm.py", line 538, in <module>
    main(ApplicationCharm)
  File "/var/lib/juju/agents/unit-postgresql-test-app-0/charm/venv/ops/main.py", line 551, in main
    manager.run()
  File "/var/lib/juju/agents/unit-postgresql-test-app-0/charm/venv/ops/main.py", line 530, in run
    self._emit()
  File "/var/lib/juju/agents/unit-postgresql-test-app-0/charm/venv/ops/main.py", line 519, in _emit
    _emit_charm_event(self.charm, self.dispatcher.event_name)
  File "/var/lib/juju/agents/unit-postgresql-test-app-0/charm/venv/ops/main.py", line 147, in _emit_charm_event
    event_to_emit.emit(*args, **kwargs)
  File "/var/lib/juju/agents/unit-postgresql-test-app-0/charm/venv/ops/framework.py", line 348, in emit
    framework._emit(event)
  File "/var/lib/juju/agents/unit-postgresql-test-app-0/charm/venv/ops/framework.py", line 860, in _emit
    self._reemit(event_path)
  File "/var/lib/juju/agents/unit-postgresql-test-app-0/charm/venv/ops/framework.py", line 950, in _reemit
    custom_handler(event)
  File "/var/lib/juju/agents/unit-postgresql-test-app-0/charm/./src/charm.py", line 289, in _on_clear_continuous_writes_action
    if self._connection_string is None:
  File "/var/lib/juju/agents/unit-postgresql-test-app-0/charm/./src/charm.py", line 259, in _connection_string
    data = list(self.first_database.fetch_relation_data().values())[0]
AttributeError: 'ApplicationCharm' object has no attribute 'first_database'
unit-postgresql-test-app-0: 01:58:28 ERROR unit.postgresql-test-app/0.juju-log Uncaught exception while in charm code:
Traceback (most recent call last):
  File "/var/lib/juju/agents/unit-postgresql-test-app-0/charm/./src/charm.py", line 538, in <module>
    main(ApplicationCharm)
  File "/var/lib/juju/agents/unit-postgresql-test-app-0/charm/venv/ops/main.py", line 551, in main
    manager.run()
  File "/var/lib/juju/agents/unit-postgresql-test-app-0/charm/venv/ops/main.py", line 530, in run
    self._emit()
  File "/var/lib/juju/agents/unit-postgresql-test-app-0/charm/venv/ops/main.py", line 519, in _emit
    _emit_charm_event(self.charm, self.dispatcher.event_name)
  File "/var/lib/juju/agents/unit-postgresql-test-app-0/charm/venv/ops/main.py", line 147, in _emit_charm_event
    event_to_emit.emit(*args, **kwargs)
  File "/var/lib/juju/agents/unit-postgresql-test-app-0/charm/venv/ops/framework.py", line 348, in emit
    framework._emit(event)
  File "/var/lib/juju/agents/unit-postgresql-test-app-0/charm/venv/ops/framework.py", line 860, in _emit
    self._reemit(event_path)
  File "/var/lib/juju/agents/unit-postgresql-test-app-0/charm/venv/ops/framework.py", line 950, in _reemit
    custom_handler(event)
  File "/var/lib/juju/agents/unit-postgresql-test-app-0/charm/./src/charm.py", line 289, in _on_clear_continuous_writes_action
    if self._connection_string is None:
  File "/var/lib/juju/agents/unit-postgresql-test-app-0/charm/./src/charm.py", line 259, in _connection_string
    data = list(self.first_database.fetch_relation_data().values())[0]
AttributeError: 'ApplicationCharm' object has no attribute 'first_database'
unit-postgresql-test-app-0: 01:58:32 ERROR unit.postgresql-test-app/0.juju-log Uncaught exception while in charm code:
Traceback (most recent call last):
  File "/var/lib/juju/agents/unit-postgresql-test-app-0/charm/./src/charm.py", line 538, in <module>
    main(ApplicationCharm)
  File "/var/lib/juju/agents/unit-postgresql-test-app-0/charm/venv/ops/main.py", line 551, in main
    manager.run()
  File "/var/lib/juju/agents/unit-postgresql-test-app-0/charm/venv/ops/main.py", line 530, in run
    self._emit()
  File "/var/lib/juju/agents/unit-postgresql-test-app-0/charm/venv/ops/main.py", line 519, in _emit
    _emit_charm_event(self.charm, self.dispatcher.event_name)
  File "/var/lib/juju/agents/unit-postgresql-test-app-0/charm/venv/ops/main.py", line 147, in _emit_charm_event
    event_to_emit.emit(*args, **kwargs)
  File "/var/lib/juju/agents/unit-postgresql-test-app-0/charm/venv/ops/framework.py", line 348, in emit
    framework._emit(event)
  File "/var/lib/juju/agents/unit-postgresql-test-app-0/charm/venv/ops/framework.py", line 860, in _emit
    self._reemit(event_path)
  File "/var/lib/juju/agents/unit-postgresql-test-app-0/charm/venv/ops/framework.py", line 950, in _reemit
    custom_handler(event)
  File "/var/lib/juju/agents/unit-postgresql-test-app-0/charm/./src/charm.py", line 289, in _on_clear_continuous_writes_action
    if self._connection_string is None:
  File "/var/lib/juju/agents/unit-postgresql-test-app-0/charm/./src/charm.py", line 259, in _connection_string
    data = list(self.first_database.fetch_relation_data().values())[0]
AttributeError: 'ApplicationCharm' object has no attribute 'first_database'
unit-postgresql-test-app-0: 01:58:36 ERROR unit.postgresql-test-app/0.juju-log Uncaught exception while in charm code:
Traceback (most recent call last):
  File "/var/lib/juju/agents/unit-postgresql-test-app-0/charm/./src/charm.py", line 538, in <module>
    main(ApplicationCharm)
  File "/var/lib/juju/agents/unit-postgresql-test-app-0/charm/venv/ops/main.py", line 551, in main
    manager.run()
  File "/var/lib/juju/agents/unit-postgresql-test-app-0/charm/venv/ops/main.py", line 530, in run
    self._emit()
  File "/var/lib/juju/agents/unit-postgresql-test-app-0/charm/venv/ops/main.py", line 519, in _emit
    _emit_charm_event(self.charm, self.dispatcher.event_name)
  File "/var/lib/juju/agents/unit-postgresql-test-app-0/charm/venv/ops/main.py", line 147, in _emit_charm_event
    event_to_emit.emit(*args, **kwargs)
  File "/var/lib/juju/agents/unit-postgresql-test-app-0/charm/venv/ops/framework.py", line 348, in emit
    framework._emit(event)
  File "/var/lib/juju/agents/unit-postgresql-test-app-0/charm/venv/ops/framework.py", line 860, in _emit
    self._reemit(event_path)
  File "/var/lib/juju/agents/unit-postgresql-test-app-0/charm/venv/ops/framework.py", line 950, in _reemit
    custom_handler(event)
  File "/var/lib/juju/agents/unit-postgresql-test-app-0/charm/./src/charm.py", line 289, in _on_clear_continuous_writes_action
    if self._connection_string is None:
  File "/var/lib/juju/agents/unit-postgresql-test-app-0/charm/./src/charm.py", line 259, in _connection_string
    data = list(self.first_database.fetch_relation_data().values())[0]
AttributeError: 'ApplicationCharm' object has no attribute 'first_database'
unit-postgresql-test-app-0: 01:58:40 ERROR unit.postgresql-test-app/0.juju-log Uncaught exception while in charm code:
Traceback (most recent call last):
  File "/var/lib/juju/agents/unit-postgresql-test-app-0/charm/./src/charm.py", line 538, in <module>
    main(ApplicationCharm)
  File "/var/lib/juju/agents/unit-postgresql-test-app-0/charm/venv/ops/main.py", line 551, in main
    manager.run()
  File "/var/lib/juju/agents/unit-postgresql-test-app-0/charm/venv/ops/main.py", line 530, in run
    self._emit()
  File "/var/lib/juju/agents/unit-postgresql-test-app-0/charm/venv/ops/main.py", line 519, in _emit
    _emit_charm_event(self.charm, self.dispatcher.event_name)
  File "/var/lib/juju/agents/unit-postgresql-test-app-0/charm/venv/ops/main.py", line 147, in _emit_charm_event
    event_to_emit.emit(*args, **kwargs)
  File "/var/lib/juju/agents/unit-postgresql-test-app-0/charm/venv/ops/framework.py", line 348, in emit
    framework._emit(event)
  File "/var/lib/juju/agents/unit-postgresql-test-app-0/charm/venv/ops/framework.py", line 860, in _emit
    self._reemit(event_path)
  File "/var/lib/juju/agents/unit-postgresql-test-app-0/charm/venv/ops/framework.py", line 950, in _reemit
    custom_handler(event)
  File "/var/lib/juju/agents/unit-postgresql-test-app-0/charm/./src/charm.py", line 289, in _on_clear_continuous_writes_action
    if self._connection_string is None:
  File "/var/lib/juju/agents/unit-postgresql-test-app-0/charm/./src/charm.py", line 259, in _connection_string
    data = list(self.first_database.fetch_relation_data().values())[0]
AttributeError: 'ApplicationCharm' object has no attribute 'first_database'
unit-postgresql-test-app-0: 01:58:44 ERROR unit.postgresql-test-app/0.juju-log Uncaught exception while in charm code:
Traceback (most recent call last):
  File "/var/lib/juju/agents/unit-postgresql-test-app-0/charm/./src/charm.py", line 538, in <module>
    main(ApplicationCharm)
  File "/var/lib/juju/agents/unit-postgresql-test-app-0/charm/venv/ops/main.py", line 551, in main
    manager.run()
  File "/var/lib/juju/agents/unit-postgresql-test-app-0/charm/venv/ops/main.py", line 530, in run
    self._emit()
  File "/var/lib/juju/agents/unit-postgresql-test-app-0/charm/venv/ops/main.py", line 519, in _emit
    _emit_charm_event(self.charm, self.dispatcher.event_name)
  File "/var/lib/juju/agents/unit-postgresql-test-app-0/charm/venv/ops/main.py", line 147, in _emit_charm_event
    event_to_emit.emit(*args, **kwargs)
  File "/var/lib/juju/agents/unit-postgresql-test-app-0/charm/venv/ops/framework.py", line 348, in emit
    framework._emit(event)
  File "/var/lib/juju/agents/unit-postgresql-test-app-0/charm/venv/ops/framework.py", line 860, in _emit
    self._reemit(event_path)
  File "/var/lib/juju/agents/unit-postgresql-test-app-0/charm/venv/ops/framework.py", line 950, in _reemit
    custom_handler(event)
  File "/var/lib/juju/agents/unit-postgresql-test-app-0/charm/./src/charm.py", line 289, in _on_clear_continuous_writes_action
    if self._connection_string is None:
  File "/var/lib/juju/agents/unit-postgresql-test-app-0/charm/./src/charm.py", line 259, in _connection_string
    data = list(self.first_database.fetch_relation_data().values())[0]
AttributeError: 'ApplicationCharm' object has no attribute 'first_database'
unit-postgresql-test-app-0: 01:58:48 ERROR unit.postgresql-test-app/0.juju-log Uncaught exception while in charm code:
Traceback (most recent call last):
  File "/var/lib/juju/agents/unit-postgresql-test-app-0/charm/./src/charm.py", line 538, in <module>
    main(ApplicationCharm)
  File "/var/lib/juju/agents/unit-postgresql-test-app-0/charm/venv/ops/main.py", line 551, in main
    manager.run()
  File "/var/lib/juju/agents/unit-postgresql-test-app-0/charm/venv/ops/main.py", line 530, in run
    self._emit()
  File "/var/lib/juju/agents/unit-postgresql-test-app-0/charm/venv/ops/main.py", line 519, in _emit
    _emit_charm_event(self.charm, self.dispatcher.event_name)
  File "/var/lib/juju/agents/unit-postgresql-test-app-0/charm/venv/ops/main.py", line 147, in _emit_charm_event
    event_to_emit.emit(*args, **kwargs)
  File "/var/lib/juju/agents/unit-postgresql-test-app-0/charm/venv/ops/framework.py", line 348, in emit
    framework._emit(event)
  File "/var/lib/juju/agents/unit-postgresql-test-app-0/charm/venv/ops/framework.py", line 860, in _emit
    self._reemit(event_path)
  File "/var/lib/juju/agents/unit-postgresql-test-app-0/charm/venv/ops/framework.py", line 950, in _reemit
    custom_handler(event)
  File "/var/lib/juju/agents/unit-postgresql-test-app-0/charm/./src/charm.py", line 289, in _on_clear_continuous_writes_action
    if self._connection_string is None:
  File "/var/lib/juju/agents/unit-postgresql-test-app-0/charm/./src/charm.py", line 259, in _connection_string
    data = list(self.first_database.fetch_relation_data().values())[0]
AttributeError: 'ApplicationCharm' object has no attribute 'first_database'
unit-postgresql-test-app-0: 01:58:52 ERROR unit.postgresql-test-app/0.juju-log Uncaught exception while in charm code:
Traceback (most recent call last):
  File "/var/lib/juju/agents/unit-postgresql-test-app-0/charm/./src/charm.py", line 538, in <module>
    main(ApplicationCharm)
  File "/var/lib/juju/agents/unit-postgresql-test-app-0/charm/venv/ops/main.py", line 551, in main
    manager.run()
  File "/var/lib/juju/agents/unit-postgresql-test-app-0/charm/venv/ops/main.py", line 530, in run
    self._emit()
  File "/var/lib/juju/agents/unit-postgresql-test-app-0/charm/venv/ops/main.py", line 519, in _emit
    _emit_charm_event(self.charm, self.dispatcher.event_name)
  File "/var/lib/juju/agents/unit-postgresql-test-app-0/charm/venv/ops/main.py", line 147, in _emit_charm_event
    event_to_emit.emit(*args, **kwargs)
  File "/var/lib/juju/agents/unit-postgresql-test-app-0/charm/venv/ops/framework.py", line 348, in emit
    framework._emit(event)
  File "/var/lib/juju/agents/unit-postgresql-test-app-0/charm/venv/ops/framework.py", line 860, in _emit
    self._reemit(event_path)
  File "/var/lib/juju/agents/unit-postgresql-test-app-0/charm/venv/ops/framework.py", line 950, in _reemit
    custom_handler(event)
  File "/var/lib/juju/agents/unit-postgresql-test-app-0/charm/./src/charm.py", line 289, in _on_clear_continuous_writes_action
    if self._connection_string is None:
  File "/var/lib/juju/agents/unit-postgresql-test-app-0/charm/./src/charm.py", line 259, in _connection_string
    data = list(self.first_database.fetch_relation_data().values())[0]
AttributeError: 'ApplicationCharm' object has no attribute 'first_database'
unit-postgresql-test-app-0: 01:58:56 ERROR unit.postgresql-test-app/0.juju-log Uncaught exception while in charm code:
Traceback (most recent call last):
  File "/var/lib/juju/agents/unit-postgresql-test-app-0/charm/./src/charm.py", line 538, in <module>
    main(ApplicationCharm)
  File "/var/lib/juju/agents/unit-postgresql-test-app-0/charm/venv/ops/main.py", line 551, in main
    manager.run()
  File "/var/lib/juju/agents/unit-postgresql-test-app-0/charm/venv/ops/main.py", line 530, in run
    self._emit()
  File "/var/lib/juju/agents/unit-postgresql-test-app-0/charm/venv/ops/main.py", line 519, in _emit
    _emit_charm_event(self.charm, self.dispatcher.event_name)
  File "/var/lib/juju/agents/unit-postgresql-test-app-0/charm/venv/ops/main.py", line 147, in _emit_charm_event
    event_to_emit.emit(*args, **kwargs)
  File "/var/lib/juju/agents/unit-postgresql-test-app-0/charm/venv/ops/framework.py", line 348, in emit
    framework._emit(event)
  File "/var/lib/juju/agents/unit-postgresql-test-app-0/charm/venv/ops/framework.py", line 860, in _emit
    self._reemit(event_path)
  File "/var/lib/juju/agents/unit-postgresql-test-app-0/charm/venv/ops/framework.py", line 950, in _reemit
    custom_handler(event)
  File "/var/lib/juju/agents/unit-postgresql-test-app-0/charm/./src/charm.py", line 289, in _on_clear_continuous_writes_action
    if self._connection_string is None:
  File "/var/lib/juju/agents/unit-postgresql-test-app-0/charm/./src/charm.py", line 259, in _connection_string
    data = list(self.first_database.fetch_relation_data().values())[0]
AttributeError: 'ApplicationCharm' object has no attribute 'first_database'
unit-postgresql-test-app-0: 01:59:00 ERROR unit.postgresql-test-app/0.juju-log Uncaught exception while in charm code:
Traceback (most recent call last):
  File "/var/lib/juju/agents/unit-postgresql-test-app-0/charm/./src/charm.py", line 538, in <module>
    main(ApplicationCharm)
  File "/var/lib/juju/agents/unit-postgresql-test-app-0/charm/venv/ops/main.py", line 551, in main
    manager.run()
  File "/var/lib/juju/agents/unit-postgresql-test-app-0/charm/venv/ops/main.py", line 530, in run
    self._emit()
  File "/var/lib/juju/agents/unit-postgresql-test-app-0/charm/venv/ops/main.py", line 519, in _emit
    _emit_charm_event(self.charm, self.dispatcher.event_name)
  File "/var/lib/juju/agents/unit-postgresql-test-app-0/charm/venv/ops/main.py", line 147, in _emit_charm_event
    event_to_emit.emit(*args, **kwargs)
  File "/var/lib/juju/agents/unit-postgresql-test-app-0/charm/venv/ops/framework.py", line 348, in emit
    framework._emit(event)
  File "/var/lib/juju/agents/unit-postgresql-test-app-0/charm/venv/ops/framework.py", line 860, in _emit
    self._reemit(event_path)
  File "/var/lib/juju/agents/unit-postgresql-test-app-0/charm/venv/ops/framework.py", line 950, in _reemit
    custom_handler(event)
  File "/var/lib/juju/agents/unit-postgresql-test-app-0/charm/./src/charm.py", line 289, in _on_clear_continuous_writes_action
    if self._connection_string is None:
  File "/var/lib/juju/agents/unit-postgresql-test-app-0/charm/./src/charm.py", line 259, in _connection_string
    data = list(self.first_database.fetch_relation_data().values())[0]
AttributeError: 'ApplicationCharm' object has no attribute 'first_database'
unit-postgresql-test-app-0: 01:59:04 ERROR unit.postgresql-test-app/0.juju-log Uncaught exception while in charm code:
Traceback (most recent call last):
  File "/var/lib/juju/agents/unit-postgresql-test-app-0/charm/./src/charm.py", line 538, in <module>
    main(ApplicationCharm)
  File "/var/lib/juju/agents/unit-postgresql-test-app-0/charm/venv/ops/main.py", line 551, in main
    manager.run()
  File "/var/lib/juju/agents/unit-postgresql-test-app-0/charm/venv/ops/main.py", line 530, in run
    self._emit()
  File "/var/lib/juju/agents/unit-postgresql-test-app-0/charm/venv/ops/main.py", line 519, in _emit
    _emit_charm_event(self.charm, self.dispatcher.event_name)
  File "/var/lib/juju/agents/unit-postgresql-test-app-0/charm/venv/ops/main.py", line 147, in _emit_charm_event
    event_to_emit.emit(*args, **kwargs)
  File "/var/lib/juju/agents/unit-postgresql-test-app-0/charm/venv/ops/framework.py", line 348, in emit
    framework._emit(event)
  File "/var/lib/juju/agents/unit-postgresql-test-app-0/charm/venv/ops/framework.py", line 860, in _emit
    self._reemit(event_path)
  File "/var/lib/juju/agents/unit-postgresql-test-app-0/charm/venv/ops/framework.py", line 950, in _reemit
    custom_handler(event)
  File "/var/lib/juju/agents/unit-postgresql-test-app-0/charm/./src/charm.py", line 289, in _on_clear_continuous_writes_action
    if self._connection_string is None:
  File "/var/lib/juju/agents/unit-postgresql-test-app-0/charm/./src/charm.py", line 259, in _connection_string
    data = list(self.first_database.fetch_relation_data().values())[0]
AttributeError: 'ApplicationCharm' object has no attribute 'first_database'
unit-postgresql-test-app-0: 01:59:08 ERROR unit.postgresql-test-app/0.juju-log Uncaught exception while in charm code:
Traceback (most recent call last):
  File "/var/lib/juju/agents/unit-postgresql-test-app-0/charm/./src/charm.py", line 538, in <module>
    main(ApplicationCharm)
  File "/var/lib/juju/agents/unit-postgresql-test-app-0/charm/venv/ops/main.py", line 551, in main
    manager.run()
  File "/var/lib/juju/agents/unit-postgresql-test-app-0/charm/venv/ops/main.py", line 530, in run
    self._emit()
  File "/var/lib/juju/agents/unit-postgresql-test-app-0/charm/venv/ops/main.py", line 519, in _emit
    _emit_charm_event(self.charm, self.dispatcher.event_name)
  File "/var/lib/juju/agents/unit-postgresql-test-app-0/charm/venv/ops/main.py", line 147, in _emit_charm_event
    event_to_emit.emit(*args, **kwargs)
  File "/var/lib/juju/agents/unit-postgresql-test-app-0/charm/venv/ops/framework.py", line 348, in emit
    framework._emit(event)
  File "/var/lib/juju/agents/unit-postgresql-test-app-0/charm/venv/ops/framework.py", line 860, in _emit
    self._reemit(event_path)
  File "/var/lib/juju/agents/unit-postgresql-test-app-0/charm/venv/ops/framework.py", line 950, in _reemit
    custom_handler(event)
  File "/var/lib/juju/agents/unit-postgresql-test-app-0/charm/./src/charm.py", line 289, in _on_clear_continuous_writes_action
    if self._connection_string is None:
  File "/var/lib/juju/agents/unit-postgresql-test-app-0/charm/./src/charm.py", line 259, in _connection_string
    data = list(self.first_database.fetch_relation_data().values())[0]
AttributeError: 'ApplicationCharm' object has no attribute 'first_database'
unit-postgresql-test-app-0: 01:59:12 ERROR unit.postgresql-test-app/0.juju-log Uncaught exception while in charm code:
Traceback (most recent call last):
  File "/var/lib/juju/agents/unit-postgresql-test-app-0/charm/./src/charm.py", line 538, in <module>
    main(ApplicationCharm)
  File "/var/lib/juju/agents/unit-postgresql-test-app-0/charm/venv/ops/main.py", line 551, in main
    manager.run()
  File "/var/lib/juju/agents/unit-postgresql-test-app-0/charm/venv/ops/main.py", line 530, in run
    self._emit()
  File "/var/lib/juju/agents/unit-postgresql-test-app-0/charm/venv/ops/main.py", line 519, in _emit
    _emit_charm_event(self.charm, self.dispatcher.event_name)
  File "/var/lib/juju/agents/unit-postgresql-test-app-0/charm/venv/ops/main.py", line 147, in _emit_charm_event
    event_to_emit.emit(*args, **kwargs)
  File "/var/lib/juju/agents/unit-postgresql-test-app-0/charm/venv/ops/framework.py", line 348, in emit
    framework._emit(event)
  File "/var/lib/juju/agents/unit-postgresql-test-app-0/charm/venv/ops/framework.py", line 860, in _emit
    self._reemit(event_path)
  File "/var/lib/juju/agents/unit-postgresql-test-app-0/charm/venv/ops/framework.py", line 950, in _reemit
    custom_handler(event)
  File "/var/lib/juju/agents/unit-postgresql-test-app-0/charm/./src/charm.py", line 289, in _on_clear_continuous_writes_action
    if self._connection_string is None:
  File "/var/lib/juju/agents/unit-postgresql-test-app-0/charm/./src/charm.py", line 259, in _connection_string
    data = list(self.first_database.fetch_relation_data().values())[0]
AttributeError: 'ApplicationCharm' object has no attribute 'first_database'
unit-postgresql-test-app-0: 01:59:16 ERROR unit.postgresql-test-app/0.juju-log Uncaught exception while in charm code:
Traceback (most recent call last):
  File "/var/lib/juju/agents/unit-postgresql-test-app-0/charm/./src/charm.py", line 538, in <module>
    main(ApplicationCharm)
  File "/var/lib/juju/agents/unit-postgresql-test-app-0/charm/venv/ops/main.py", line 551, in main
    manager.run()
  File "/var/lib/juju/agents/unit-postgresql-test-app-0/charm/venv/ops/main.py", line 530, in run
    self._emit()
  File "/var/lib/juju/agents/unit-postgresql-test-app-0/charm/venv/ops/main.py", line 519, in _emit
    _emit_charm_event(self.charm, self.dispatcher.event_name)
  File "/var/lib/juju/agents/unit-postgresql-test-app-0/charm/venv/ops/main.py", line 147, in _emit_charm_event
    event_to_emit.emit(*args, **kwargs)
  File "/var/lib/juju/agents/unit-postgresql-test-app-0/charm/venv/ops/framework.py", line 348, in emit
    framework._emit(event)
  File "/var/lib/juju/agents/unit-postgresql-test-app-0/charm/venv/ops/framework.py", line 860, in _emit
    self._reemit(event_path)
  File "/var/lib/juju/agents/unit-postgresql-test-app-0/charm/venv/ops/framework.py", line 950, in _reemit
    custom_handler(event)
  File "/var/lib/juju/agents/unit-postgresql-test-app-0/charm/./src/charm.py", line 289, in _on_clear_continuous_writes_action
    if self._connection_string is None:
  File "/var/lib/juju/agents/unit-postgresql-test-app-0/charm/./src/charm.py", line 259, in _connection_string
    data = list(self.first_database.fetch_relation_data().values())[0]
AttributeError: 'ApplicationCharm' object has no attribute 'first_database'
unit-postgresql-test-app-0: 01:59:20 ERROR unit.postgresql-test-app/0.juju-log Uncaught exception while in charm code:
Traceback (most recent call last):
  File "/var/lib/juju/agents/unit-postgresql-test-app-0/charm/./src/charm.py", line 538, in <module>
    main(ApplicationCharm)
  File "/var/lib/juju/agents/unit-postgresql-test-app-0/charm/venv/ops/main.py", line 551, in main
    manager.run()
  File "/var/lib/juju/agents/unit-postgresql-test-app-0/charm/venv/ops/main.py", line 530, in run
    self._emit()
  File "/var/lib/juju/agents/unit-postgresql-test-app-0/charm/venv/ops/main.py", line 519, in _emit
    _emit_charm_event(self.charm, self.dispatcher.event_name)
  File "/var/lib/juju/agents/unit-postgresql-test-app-0/charm/venv/ops/main.py", line 147, in _emit_charm_event
    event_to_emit.emit(*args, **kwargs)
  File "/var/lib/juju/agents/unit-postgresql-test-app-0/charm/venv/ops/framework.py", line 348, in emit
    framework._emit(event)
  File "/var/lib/juju/agents/unit-postgresql-test-app-0/charm/venv/ops/framework.py", line 860, in _emit
    self._reemit(event_path)
  File "/var/lib/juju/agents/unit-postgresql-test-app-0/charm/venv/ops/framework.py", line 950, in _reemit
    custom_handler(event)
  File "/var/lib/juju/agents/unit-postgresql-test-app-0/charm/./src/charm.py", line 289, in _on_clear_continuous_writes_action
    if self._connection_string is None:
  File "/var/lib/juju/agents/unit-postgresql-test-app-0/charm/./src/charm.py", line 259, in _connection_string
    data = list(self.first_database.fetch_relation_data().values())[0]
AttributeError: 'ApplicationCharm' object has no attribute 'first_database'
unit-postgresql-test-app-0: 01:59:24 ERROR unit.postgresql-test-app/0.juju-log Uncaught exception while in charm code:
Traceback (most recent call last):
  File "/var/lib/juju/agents/unit-postgresql-test-app-0/charm/./src/charm.py", line 538, in <module>
    main(ApplicationCharm)
  File "/var/lib/juju/agents/unit-postgresql-test-app-0/charm/venv/ops/main.py", line 551, in main
    manager.run()
  File "/var/lib/juju/agents/unit-postgresql-test-app-0/charm/venv/ops/main.py", line 530, in run
    self._emit()
  File "/var/lib/juju/agents/unit-postgresql-test-app-0/charm/venv/ops/main.py", line 519, in _emit
    _emit_charm_event(self.charm, self.dispatcher.event_name)
  File "/var/lib/juju/agents/unit-postgresql-test-app-0/charm/venv/ops/main.py", line 147, in _emit_charm_event
    event_to_emit.emit(*args, **kwargs)
  File "/var/lib/juju/agents/unit-postgresql-test-app-0/charm/venv/ops/framework.py", line 348, in emit
    framework._emit(event)
  File "/var/lib/juju/agents/unit-postgresql-test-app-0/charm/venv/ops/framework.py", line 860, in _emit
    self._reemit(event_path)
  File "/var/lib/juju/agents/unit-postgresql-test-app-0/charm/venv/ops/framework.py", line 950, in _reemit
    custom_handler(event)
  File "/var/lib/juju/agents/unit-postgresql-test-app-0/charm/./src/charm.py", line 289, in _on_clear_continuous_writes_action
    if self._connection_string is None:
  File "/var/lib/juju/agents/unit-postgresql-test-app-0/charm/./src/charm.py", line 259, in _connection_string
    data = list(self.first_database.fetch_relation_data().values())[0]
AttributeError: 'ApplicationCharm' object has no attribute 'first_database'
unit-postgresql-test-app-0: 01:59:28 ERROR unit.postgresql-test-app/0.juju-log Uncaught exception while in charm code:
Traceback (most recent call last):
  File "/var/lib/juju/agents/unit-postgresql-test-app-0/charm/./src/charm.py", line 538, in <module>
    main(ApplicationCharm)
  File "/var/lib/juju/agents/unit-postgresql-test-app-0/charm/venv/ops/main.py", line 551, in main
    manager.run()
  File "/var/lib/juju/agents/unit-postgresql-test-app-0/charm/venv/ops/main.py", line 530, in run
    self._emit()
  File "/var/lib/juju/agents/unit-postgresql-test-app-0/charm/venv/ops/main.py", line 519, in _emit
    _emit_charm_event(self.charm, self.dispatcher.event_name)
  File "/var/lib/juju/agents/unit-postgresql-test-app-0/charm/venv/ops/main.py", line 147, in _emit_charm_event
    event_to_emit.emit(*args, **kwargs)
  File "/var/lib/juju/agents/unit-postgresql-test-app-0/charm/venv/ops/framework.py", line 348, in emit
    framework._emit(event)
  File "/var/lib/juju/agents/unit-postgresql-test-app-0/charm/venv/ops/framework.py", line 860, in _emit
    self._reemit(event_path)
  File "/var/lib/juju/agents/unit-postgresql-test-app-0/charm/venv/ops/framework.py", line 950, in _reemit
    custom_handler(event)
  File "/var/lib/juju/agents/unit-postgresql-test-app-0/charm/./src/charm.py", line 289, in _on_clear_continuous_writes_action
    if self._connection_string is None:
  File "/var/lib/juju/agents/unit-postgresql-test-app-0/charm/./src/charm.py", line 259, in _connection_string
    data = list(self.first_database.fetch_relation_data().values())[0]
AttributeError: 'ApplicationCharm' object has no attribute 'first_database'
unit-postgresql-test-app-0: 01:59:32 ERROR unit.postgresql-test-app/0.juju-log Uncaught exception while in charm code:
Traceback (most recent call last):
  File "/var/lib/juju/agents/unit-postgresql-test-app-0/charm/./src/charm.py", line 538, in <module>
    main(ApplicationCharm)
  File "/var/lib/juju/agents/unit-postgresql-test-app-0/charm/venv/ops/main.py", line 551, in main
    manager.run()
  File "/var/lib/juju/agents/unit-postgresql-test-app-0/charm/venv/ops/main.py", line 530, in run
    self._emit()
  File "/var/lib/juju/agents/unit-postgresql-test-app-0/charm/venv/ops/main.py", line 519, in _emit
    _emit_charm_event(self.charm, self.dispatcher.event_name)
  File "/var/lib/juju/agents/unit-postgresql-test-app-0/charm/venv/ops/main.py", line 147, in _emit_charm_event
    event_to_emit.emit(*args, **kwargs)
  File "/var/lib/juju/agents/unit-postgresql-test-app-0/charm/venv/ops/framework.py", line 348, in emit
    framework._emit(event)
  File "/var/lib/juju/agents/unit-postgresql-test-app-0/charm/venv/ops/framework.py", line 860, in _emit
    self._reemit(event_path)
  File "/var/lib/juju/agents/unit-postgresql-test-app-0/charm/venv/ops/framework.py", line 950, in _reemit
    custom_handler(event)
  File "/var/lib/juju/agents/unit-postgresql-test-app-0/charm/./src/charm.py", line 289, in _on_clear_continuous_writes_action
    if self._connection_string is None:
  File "/var/lib/juju/agents/unit-postgresql-test-app-0/charm/./src/charm.py", line 259, in _connection_string
    data = list(self.first_database.fetch_relation_data().values())[0]
AttributeError: 'ApplicationCharm' object has no attribute 'first_database'
unit-postgresql-test-app-0: 01:59:36 ERROR unit.postgresql-test-app/0.juju-log Uncaught exception while in charm code:
Traceback (most recent call last):
  File "/var/lib/juju/agents/unit-postgresql-test-app-0/charm/./src/charm.py", line 538, in <module>
    main(ApplicationCharm)
  File "/var/lib/juju/agents/unit-postgresql-test-app-0/charm/venv/ops/main.py", line 551, in main
    manager.run()
  File "/var/lib/juju/agents/unit-postgresql-test-app-0/charm/venv/ops/main.py", line 530, in run
    self._emit()
  File "/var/lib/juju/agents/unit-postgresql-test-app-0/charm/venv/ops/main.py", line 519, in _emit
    _emit_charm_event(self.charm, self.dispatcher.event_name)
  File "/var/lib/juju/agents/unit-postgresql-test-app-0/charm/venv/ops/main.py", line 147, in _emit_charm_event
    event_to_emit.emit(*args, **kwargs)
  File "/var/lib/juju/agents/unit-postgresql-test-app-0/charm/venv/ops/framework.py", line 348, in emit
    framework._emit(event)
  File "/var/lib/juju/agents/unit-postgresql-test-app-0/charm/venv/ops/framework.py", line 860, in _emit
    self._reemit(event_path)
  File "/var/lib/juju/agents/unit-postgresql-test-app-0/charm/venv/ops/framework.py", line 950, in _reemit
    custom_handler(event)
  File "/var/lib/juju/agents/unit-postgresql-test-app-0/charm/./src/charm.py", line 289, in _on_clear_continuous_writes_action
    if self._connection_string is None:
  File "/var/lib/juju/agents/unit-postgresql-test-app-0/charm/./src/charm.py", line 259, in _connection_string
    data = list(self.first_database.fetch_relation_data().values())[0]
AttributeError: 'ApplicationCharm' object has no attribute 'first_database'
unit-postgresql-test-app-0: 01:59:40 ERROR unit.postgresql-test-app/0.juju-log Uncaught exception while in charm code:
Traceback (most recent call last):
  File "/var/lib/juju/agents/unit-postgresql-test-app-0/charm/./src/charm.py", line 538, in <module>
    main(ApplicationCharm)
  File "/var/lib/juju/agents/unit-postgresql-test-app-0/charm/venv/ops/main.py", line 551, in main
    manager.run()
  File "/var/lib/juju/agents/unit-postgresql-test-app-0/charm/venv/ops/main.py", line 530, in run
    self._emit()
  File "/var/lib/juju/agents/unit-postgresql-test-app-0/charm/venv/ops/main.py", line 519, in _emit
    _emit_charm_event(self.charm, self.dispatcher.event_name)
  File "/var/lib/juju/agents/unit-postgresql-test-app-0/charm/venv/ops/main.py", line 147, in _emit_charm_event
    event_to_emit.emit(*args, **kwargs)
  File "/var/lib/juju/agents/unit-postgresql-test-app-0/charm/venv/ops/framework.py", line 348, in emit
    framework._emit(event)
  File "/var/lib/juju/agents/unit-postgresql-test-app-0/charm/venv/ops/framework.py", line 860, in _emit
    self._reemit(event_path)
  File "/var/lib/juju/agents/unit-postgresql-test-app-0/charm/venv/ops/framework.py", line 950, in _reemit
    custom_handler(event)
  File "/var/lib/juju/agents/unit-postgresql-test-app-0/charm/./src/charm.py", line 289, in _on_clear_continuous_writes_action
    if self._connection_string is None:
  File "/var/lib/juju/agents/unit-postgresql-test-app-0/charm/./src/charm.py", line 259, in _connection_string
    data = list(self.first_database.fetch_relation_data().values())[0]
AttributeError: 'ApplicationCharm' object has no attribute 'first_database'
unit-postgresql-test-app-0: 01:59:44 ERROR unit.postgresql-test-app/0.juju-log Uncaught exception while in charm code:
Traceback (most recent call last):
  File "/var/lib/juju/agents/unit-postgresql-test-app-0/charm/./src/charm.py", line 538, in <module>
    main(ApplicationCharm)
  File "/var/lib/juju/agents/unit-postgresql-test-app-0/charm/venv/ops/main.py", line 551, in main
    manager.run()
  File "/var/lib/juju/agents/unit-postgresql-test-app-0/charm/venv/ops/main.py", line 530, in run
    self._emit()
  File "/var/lib/juju/agents/unit-postgresql-test-app-0/charm/venv/ops/main.py", line 519, in _emit
    _emit_charm_event(self.charm, self.dispatcher.event_name)
  File "/var/lib/juju/agents/unit-postgresql-test-app-0/charm/venv/ops/main.py", line 147, in _emit_charm_event
    event_to_emit.emit(*args, **kwargs)
  File "/var/lib/juju/agents/unit-postgresql-test-app-0/charm/venv/ops/framework.py", line 348, in emit
    framework._emit(event)
  File "/var/lib/juju/agents/unit-postgresql-test-app-0/charm/venv/ops/framework.py", line 860, in _emit
    self._reemit(event_path)
  File "/var/lib/juju/agents/unit-postgresql-test-app-0/charm/venv/ops/framework.py", line 950, in _reemit
    custom_handler(event)
  File "/var/lib/juju/agents/unit-postgresql-test-app-0/charm/./src/charm.py", line 289, in _on_clear_continuous_writes_action
    if self._connection_string is None:
  File "/var/lib/juju/agents/unit-postgresql-test-app-0/charm/./src/charm.py", line 259, in _connection_string
    data = list(self.first_database.fetch_relation_data().values())[0]
AttributeError: 'ApplicationCharm' object has no attribute 'first_database'
unit-postgresql-test-app-0: 01:59:48 ERROR unit.postgresql-test-app/0.juju-log Uncaught exception while in charm code:
Traceback (most recent call last):
  File "/var/lib/juju/agents/unit-postgresql-test-app-0/charm/./src/charm.py", line 538, in <module>
    main(ApplicationCharm)
  File "/var/lib/juju/agents/unit-postgresql-test-app-0/charm/venv/ops/main.py", line 551, in main
    manager.run()
  File "/var/lib/juju/agents/unit-postgresql-test-app-0/charm/venv/ops/main.py", line 530, in run
    self._emit()
  File "/var/lib/juju/agents/unit-postgresql-test-app-0/charm/venv/ops/main.py", line 519, in _emit
    _emit_charm_event(self.charm, self.dispatcher.event_name)
  File "/var/lib/juju/agents/unit-postgresql-test-app-0/charm/venv/ops/main.py", line 147, in _emit_charm_event
    event_to_emit.emit(*args, **kwargs)
  File "/var/lib/juju/agents/unit-postgresql-test-app-0/charm/venv/ops/framework.py", line 348, in emit
    framework._emit(event)
  File "/var/lib/juju/agents/unit-postgresql-test-app-0/charm/venv/ops/framework.py", line 860, in _emit
    self._reemit(event_path)
  File "/var/lib/juju/agents/unit-postgresql-test-app-0/charm/venv/ops/framework.py", line 950, in _reemit
    custom_handler(event)
  File "/var/lib/juju/agents/unit-postgresql-test-app-0/charm/./src/charm.py", line 289, in _on_clear_continuous_writes_action
    if self._connection_string is None:
  File "/var/lib/juju/agents/unit-postgresql-test-app-0/charm/./src/charm.py", line 259, in _connection_string
    data = list(self.first_database.fetch_relation_data().values())[0]
AttributeError: 'ApplicationCharm' object has no attribute 'first_database'
unit-postgresql-test-app-0: 01:59:52 ERROR unit.postgresql-test-app/0.juju-log Uncaught exception while in charm code:
Traceback (most recent call last):
  File "/var/lib/juju/agents/unit-postgresql-test-app-0/charm/./src/charm.py", line 538, in <module>
    main(ApplicationCharm)
  File "/var/lib/juju/agents/unit-postgresql-test-app-0/charm/venv/ops/main.py", line 551, in main
    manager.run()
  File "/var/lib/juju/agents/unit-postgresql-test-app-0/charm/venv/ops/main.py", line 530, in run
    self._emit()
  File "/var/lib/juju/agents/unit-postgresql-test-app-0/charm/venv/ops/main.py", line 519, in _emit
    _emit_charm_event(self.charm, self.dispatcher.event_name)
  File "/var/lib/juju/agents/unit-postgresql-test-app-0/charm/venv/ops/main.py", line 147, in _emit_charm_event
    event_to_emit.emit(*args, **kwargs)
  File "/var/lib/juju/agents/unit-postgresql-test-app-0/charm/venv/ops/framework.py", line 348, in emit
    framework._emit(event)
  File "/var/lib/juju/agents/unit-postgresql-test-app-0/charm/venv/ops/framework.py", line 860, in _emit
    self._reemit(event_path)
  File "/var/lib/juju/agents/unit-postgresql-test-app-0/charm/venv/ops/framework.py", line 950, in _reemit
    custom_handler(event)
  File "/var/lib/juju/agents/unit-postgresql-test-app-0/charm/./src/charm.py", line 289, in _on_clear_continuous_writes_action
    if self._connection_string is None:
  File "/var/lib/juju/agents/unit-postgresql-test-app-0/charm/./src/charm.py", line 259, in _connection_string
    data = list(self.first_database.fetch_relation_data().values())[0]
AttributeError: 'ApplicationCharm' object has no attribute 'first_database'
unit-postgresql-test-app-0: 01:59:56 ERROR unit.postgresql-test-app/0.juju-log Uncaught exception while in charm code:
Traceback (most recent call last):
  File "/var/lib/juju/agents/unit-postgresql-test-app-0/charm/./src/charm.py", line 538, in <module>
    main(ApplicationCharm)
  File "/var/lib/juju/agents/unit-postgresql-test-app-0/charm/venv/ops/main.py", line 551, in main
    manager.run()
  File "/var/lib/juju/agents/unit-postgresql-test-app-0/charm/venv/ops/main.py", line 530, in run
    self._emit()
  File "/var/lib/juju/agents/unit-postgresql-test-app-0/charm/venv/ops/main.py", line 519, in _emit
    _emit_charm_event(self.charm, self.dispatcher.event_name)
  File "/var/lib/juju/agents/unit-postgresql-test-app-0/charm/venv/ops/main.py", line 147, in _emit_charm_event
    event_to_emit.emit(*args, **kwargs)
  File "/var/lib/juju/agents/unit-postgresql-test-app-0/charm/venv/ops/framework.py", line 348, in emit
    framework._emit(event)
  File "/var/lib/juju/agents/unit-postgresql-test-app-0/charm/venv/ops/framework.py", line 860, in _emit
    self._reemit(event_path)
  File "/var/lib/juju/agents/unit-postgresql-test-app-0/charm/venv/ops/framework.py", line 950, in _reemit
    custom_handler(event)
  File "/var/lib/juju/agents/unit-postgresql-test-app-0/charm/./src/charm.py", line 289, in _on_clear_continuous_writes_action
    if self._connection_string is None:
  File "/var/lib/juju/agents/unit-postgresql-test-app-0/charm/./src/charm.py", line 259, in _connection_string
    data = list(self.first_database.fetch_relation_data().values())[0]
AttributeError: 'ApplicationCharm' object has no attribute 'first_database'
unit-postgresql-test-app-0: 02:00:00 ERROR unit.postgresql-test-app/0.juju-log Uncaught exception while in charm code:
Traceback (most recent call last):
  File "/var/lib/juju/agents/unit-postgresql-test-app-0/charm/./src/charm.py", line 538, in <module>
    main(ApplicationCharm)
  File "/var/lib/juju/agents/unit-postgresql-test-app-0/charm/venv/ops/main.py", line 551, in main
    manager.run()
  File "/var/lib/juju/agents/unit-postgresql-test-app-0/charm/venv/ops/main.py", line 530, in run
    self._emit()
  File "/var/lib/juju/agents/unit-postgresql-test-app-0/charm/venv/ops/main.py", line 519, in _emit
    _emit_charm_event(self.charm, self.dispatcher.event_name)
  File "/var/lib/juju/agents/unit-postgresql-test-app-0/charm/venv/ops/main.py", line 147, in _emit_charm_event
    event_to_emit.emit(*args, **kwargs)
  File "/var/lib/juju/agents/unit-postgresql-test-app-0/charm/venv/ops/framework.py", line 348, in emit
    framework._emit(event)
  File "/var/lib/juju/agents/unit-postgresql-test-app-0/charm/venv/ops/framework.py", line 860, in _emit
    self._reemit(event_path)
  File "/var/lib/juju/agents/unit-postgresql-test-app-0/charm/venv/ops/framework.py", line 950, in _reemit
    custom_handler(event)
  File "/var/lib/juju/agents/unit-postgresql-test-app-0/charm/./src/charm.py", line 289, in _on_clear_continuous_writes_action
    if self._connection_string is None:
  File "/var/lib/juju/agents/unit-postgresql-test-app-0/charm/./src/charm.py", line 259, in _connection_string
    data = list(self.first_database.fetch_relation_data().values())[0]
AttributeError: 'ApplicationCharm' object has no attribute 'first_database'
unit-postgresql-test-app-0: 02:00:04 ERROR unit.postgresql-test-app/0.juju-log Uncaught exception while in charm code:
Traceback (most recent call last):
  File "/var/lib/juju/agents/unit-postgresql-test-app-0/charm/./src/charm.py", line 538, in <module>
    main(ApplicationCharm)
  File "/var/lib/juju/agents/unit-postgresql-test-app-0/charm/venv/ops/main.py", line 551, in main
    manager.run()
  File "/var/lib/juju/agents/unit-postgresql-test-app-0/charm/venv/ops/main.py", line 530, in run
    self._emit()
  File "/var/lib/juju/agents/unit-postgresql-test-app-0/charm/venv/ops/main.py", line 519, in _emit
    _emit_charm_event(self.charm, self.dispatcher.event_name)
  File "/var/lib/juju/agents/unit-postgresql-test-app-0/charm/venv/ops/main.py", line 147, in _emit_charm_event
    event_to_emit.emit(*args, **kwargs)
  File "/var/lib/juju/agents/unit-postgresql-test-app-0/charm/venv/ops/framework.py", line 348, in emit
    framework._emit(event)
  File "/var/lib/juju/agents/unit-postgresql-test-app-0/charm/venv/ops/framework.py", line 860, in _emit
    self._reemit(event_path)
  File "/var/lib/juju/agents/unit-postgresql-test-app-0/charm/venv/ops/framework.py", line 950, in _reemit
    custom_handler(event)
  File "/var/lib/juju/agents/unit-postgresql-test-app-0/charm/./src/charm.py", line 289, in _on_clear_continuous_writes_action
    if self._connection_string is None:
  File "/var/lib/juju/agents/unit-postgresql-test-app-0/charm/./src/charm.py", line 259, in _connection_string
    data = list(self.first_database.fetch_relation_data().values())[0]
AttributeError: 'ApplicationCharm' object has no attribute 'first_database'
unit-postgresql-test-app-0: 02:00:08 ERROR unit.postgresql-test-app/0.juju-log Uncaught exception while in charm code:
Traceback (most recent call last):
  File "/var/lib/juju/agents/unit-postgresql-test-app-0/charm/./src/charm.py", line 538, in <module>
    main(ApplicationCharm)
  File "/var/lib/juju/agents/unit-postgresql-test-app-0/charm/venv/ops/main.py", line 551, in main
    manager.run()
  File "/var/lib/juju/agents/unit-postgresql-test-app-0/charm/venv/ops/main.py", line 530, in run
    self._emit()
  File "/var/lib/juju/agents/unit-postgresql-test-app-0/charm/venv/ops/main.py", line 519, in _emit
    _emit_charm_event(self.charm, self.dispatcher.event_name)
  File "/var/lib/juju/agents/unit-postgresql-test-app-0/charm/venv/ops/main.py", line 147, in _emit_charm_event
    event_to_emit.emit(*args, **kwargs)
  File "/var/lib/juju/agents/unit-postgresql-test-app-0/charm/venv/ops/framework.py", line 348, in emit
    framework._emit(event)
  File "/var/lib/juju/agents/unit-postgresql-test-app-0/charm/venv/ops/framework.py", line 860, in _emit
    self._reemit(event_path)
  File "/var/lib/juju/agents/unit-postgresql-test-app-0/charm/venv/ops/framework.py", line 950, in _reemit
    custom_handler(event)
  File "/var/lib/juju/agents/unit-postgresql-test-app-0/charm/./src/charm.py", line 289, in _on_clear_continuous_writes_action
    if self._connection_string is None:
  File "/var/lib/juju/agents/unit-postgresql-test-app-0/charm/./src/charm.py", line 259, in _connection_string
    data = list(self.first_database.fetch_relation_data().values())[0]
AttributeError: 'ApplicationCharm' object has no attribute 'first_database'
unit-postgresql-test-app-0: 02:00:12 ERROR unit.postgresql-test-app/0.juju-log Uncaught exception while in charm code:
Traceback (most recent call last):
  File "/var/lib/juju/agents/unit-postgresql-test-app-0/charm/./src/charm.py", line 538, in <module>
    main(ApplicationCharm)
  File "/var/lib/juju/agents/unit-postgresql-test-app-0/charm/venv/ops/main.py", line 551, in main
    manager.run()
  File "/var/lib/juju/agents/unit-postgresql-test-app-0/charm/venv/ops/main.py", line 530, in run
    self._emit()
  File "/var/lib/juju/agents/unit-postgresql-test-app-0/charm/venv/ops/main.py", line 519, in _emit
    _emit_charm_event(self.charm, self.dispatcher.event_name)
  File "/var/lib/juju/agents/unit-postgresql-test-app-0/charm/venv/ops/main.py", line 147, in _emit_charm_event
    event_to_emit.emit(*args, **kwargs)
  File "/var/lib/juju/agents/unit-postgresql-test-app-0/charm/venv/ops/framework.py", line 348, in emit
    framework._emit(event)
  File "/var/lib/juju/agents/unit-postgresql-test-app-0/charm/venv/ops/framework.py", line 860, in _emit
    self._reemit(event_path)
  File "/var/lib/juju/agents/unit-postgresql-test-app-0/charm/venv/ops/framework.py", line 950, in _reemit
    custom_handler(event)
  File "/var/lib/juju/agents/unit-postgresql-test-app-0/charm/./src/charm.py", line 289, in _on_clear_continuous_writes_action
    if self._connection_string is None:
  File "/var/lib/juju/agents/unit-postgresql-test-app-0/charm/./src/charm.py", line 259, in _connection_string
    data = list(self.first_database.fetch_relation_data().values())[0]
AttributeError: 'ApplicationCharm' object has no attribute 'first_database'
unit-postgresql-test-app-0: 02:00:16 ERROR unit.postgresql-test-app/0.juju-log Uncaught exception while in charm code:
Traceback (most recent call last):
  File "/var/lib/juju/agents/unit-postgresql-test-app-0/charm/./src/charm.py", line 538, in <module>
    main(ApplicationCharm)
  File "/var/lib/juju/agents/unit-postgresql-test-app-0/charm/venv/ops/main.py", line 551, in main
    manager.run()
  File "/var/lib/juju/agents/unit-postgresql-test-app-0/charm/venv/ops/main.py", line 530, in run
    self._emit()
  File "/var/lib/juju/agents/unit-postgresql-test-app-0/charm/venv/ops/main.py", line 519, in _emit
    _emit_charm_event(self.charm, self.dispatcher.event_name)
  File "/var/lib/juju/agents/unit-postgresql-test-app-0/charm/venv/ops/main.py", line 147, in _emit_charm_event
    event_to_emit.emit(*args, **kwargs)
  File "/var/lib/juju/agents/unit-postgresql-test-app-0/charm/venv/ops/framework.py", line 348, in emit
    framework._emit(event)
  File "/var/lib/juju/agents/unit-postgresql-test-app-0/charm/venv/ops/framework.py", line 860, in _emit
    self._reemit(event_path)
  File "/var/lib/juju/agents/unit-postgresql-test-app-0/charm/venv/ops/framework.py", line 950, in _reemit
    custom_handler(event)
  File "/var/lib/juju/agents/unit-postgresql-test-app-0/charm/./src/charm.py", line 289, in _on_clear_continuous_writes_action
    if self._connection_string is None:
  File "/var/lib/juju/agents/unit-postgresql-test-app-0/charm/./src/charm.py", line 259, in _connection_string
    data = list(self.first_database.fetch_relation_data().values())[0]
AttributeError: 'ApplicationCharm' object has no attribute 'first_database'

[32mINFO    [0m pytest_operator.plugin:plugin.py:947 Forgetting model main...